[2025-04-28 15:20:15,416] WARNING django.request Not Found: /
[2025-04-28 15:20:16,115] WARNING django.request Not Found: /apple-touch-icon-precomposed.png
[2025-04-28 15:20:16,127] WARNING django.request Not Found: /apple-touch-icon-precomposed.png
[2025-04-28 15:20:16,148] WARNING django.request Not Found: /apple-touch-icon.png
[2025-04-28 15:20:16,154] WARNING django.request Not Found: /favicon.ico
[2025-04-28 15:20:16,396] WARNING django.request Not Found: /apple-touch-icon.png
[2025-04-28 15:20:22,366] WARNING django.request Not Found: /api/v1/members/members/5/settings/
[2025-04-28 15:20:22,583] WARNING django.request Not Found: /api/v1/
[2025-04-28 15:20:30,116] WARNING django.request Unauthorized: /api/v1/comments/
[2025-04-28 15:21:42,291] WARNING django.request Unauthorized: /api/v1/comments/
[2025-04-28 15:22:18,645] ERROR django.request Internal Server Error: /api/v1/comments/comments/
Traceback (most recent call last):
  File "/Users/mutafvladimir/Documents/IT/dZENcode/.venv/lib/python3.12/site-packages/django/db/backends/utils.py", line 105, in _execute
    return self.cursor.execute(sql, params)
           ^^^^^^^^^^^^^^^^^^^^^^^^^^^^^^^^
  File "/Users/mutafvladimir/Documents/IT/dZENcode/.venv/lib/python3.12/site-packages/django/db/backends/sqlite3/base.py", line 360, in execute
    return super().execute(query, params)
           ^^^^^^^^^^^^^^^^^^^^^^^^^^^^^^
sqlite3.OperationalError: no such table: comments_comment

The above exception was the direct cause of the following exception:

Traceback (most recent call last):
  File "/Users/mutafvladimir/Documents/IT/dZENcode/.venv/lib/python3.12/site-packages/django/core/handlers/exception.py", line 55, in inner
    response = get_response(request)
               ^^^^^^^^^^^^^^^^^^^^^
  File "/Users/mutafvladimir/Documents/IT/dZENcode/.venv/lib/python3.12/site-packages/django/core/handlers/base.py", line 197, in _get_response
    response = wrapped_callback(request, *callback_args, **callback_kwargs)
               ^^^^^^^^^^^^^^^^^^^^^^^^^^^^^^^^^^^^^^^^^^^^^^^^^^^^^^^^^^^^
  File "/Users/mutafvladimir/Documents/IT/dZENcode/.venv/lib/python3.12/site-packages/django/views/decorators/csrf.py", line 65, in _view_wrapper
    return view_func(request, *args, **kwargs)
           ^^^^^^^^^^^^^^^^^^^^^^^^^^^^^^^^^^^
  File "/Users/mutafvladimir/Documents/IT/dZENcode/.venv/lib/python3.12/site-packages/rest_framework/viewsets.py", line 125, in view
    return self.dispatch(request, *args, **kwargs)
           ^^^^^^^^^^^^^^^^^^^^^^^^^^^^^^^^^^^^^^^
  File "/Users/mutafvladimir/Documents/IT/dZENcode/.venv/lib/python3.12/site-packages/rest_framework/views.py", line 515, in dispatch
    response = self.handle_exception(exc)
               ^^^^^^^^^^^^^^^^^^^^^^^^^^
  File "/Users/mutafvladimir/Documents/IT/dZENcode/.venv/lib/python3.12/site-packages/rest_framework/views.py", line 475, in handle_exception
    self.raise_uncaught_exception(exc)
  File "/Users/mutafvladimir/Documents/IT/dZENcode/.venv/lib/python3.12/site-packages/rest_framework/views.py", line 486, in raise_uncaught_exception
    raise exc
  File "/Users/mutafvladimir/Documents/IT/dZENcode/.venv/lib/python3.12/site-packages/rest_framework/views.py", line 512, in dispatch
    response = handler(request, *args, **kwargs)
               ^^^^^^^^^^^^^^^^^^^^^^^^^^^^^^^^^
  File "/Users/mutafvladimir/Documents/IT/dZENcode/.venv/lib/python3.12/site-packages/rest_framework/mixins.py", line 40, in list
    page = self.paginate_queryset(queryset)
           ^^^^^^^^^^^^^^^^^^^^^^^^^^^^^^^^
  File "/Users/mutafvladimir/Documents/IT/dZENcode/.venv/lib/python3.12/site-packages/rest_framework/generics.py", line 175, in paginate_queryset
    return self.paginator.paginate_queryset(queryset, self.request, view=self)
           ^^^^^^^^^^^^^^^^^^^^^^^^^^^^^^^^^^^^^^^^^^^^^^^^^^^^^^^^^^^^^^^^^^^
  File "/Users/mutafvladimir/Documents/IT/dZENcode/.venv/lib/python3.12/site-packages/rest_framework/pagination.py", line 211, in paginate_queryset
    self.page = paginator.page(page_number)
                ^^^^^^^^^^^^^^^^^^^^^^^^^^^
  File "/Users/mutafvladimir/Documents/IT/dZENcode/.venv/lib/python3.12/site-packages/django/core/paginator.py", line 89, in page
    number = self.validate_number(number)
             ^^^^^^^^^^^^^^^^^^^^^^^^^^^^
  File "/Users/mutafvladimir/Documents/IT/dZENcode/.venv/lib/python3.12/site-packages/django/core/paginator.py", line 70, in validate_number
    if number > self.num_pages:
                ^^^^^^^^^^^^^^
  File "/Users/mutafvladimir/Documents/IT/dZENcode/.venv/lib/python3.12/site-packages/django/utils/functional.py", line 47, in __get__
    res = instance.__dict__[self.name] = self.func(instance)
                                         ^^^^^^^^^^^^^^^^^^^
  File "/Users/mutafvladimir/Documents/IT/dZENcode/.venv/lib/python3.12/site-packages/django/core/paginator.py", line 116, in num_pages
    if self.count == 0 and not self.allow_empty_first_page:
       ^^^^^^^^^^
  File "/Users/mutafvladimir/Documents/IT/dZENcode/.venv/lib/python3.12/site-packages/django/utils/functional.py", line 47, in __get__
    res = instance.__dict__[self.name] = self.func(instance)
                                         ^^^^^^^^^^^^^^^^^^^
  File "/Users/mutafvladimir/Documents/IT/dZENcode/.venv/lib/python3.12/site-packages/django/core/paginator.py", line 110, in count
    return c()
           ^^^
  File "/Users/mutafvladimir/Documents/IT/dZENcode/.venv/lib/python3.12/site-packages/django/db/models/query.py", line 604, in count
    return self.query.get_count(using=self.db)
           ^^^^^^^^^^^^^^^^^^^^^^^^^^^^^^^^^^^
  File "/Users/mutafvladimir/Documents/IT/dZENcode/.venv/lib/python3.12/site-packages/django/db/models/sql/query.py", line 644, in get_count
    return obj.get_aggregation(using, {"__count": Count("*")})["__count"]
           ^^^^^^^^^^^^^^^^^^^^^^^^^^^^^^^^^^^^^^^^^^^^^^^^^^^
  File "/Users/mutafvladimir/Documents/IT/dZENcode/.venv/lib/python3.12/site-packages/django/db/models/sql/query.py", line 626, in get_aggregation
    result = compiler.execute_sql(SINGLE)
             ^^^^^^^^^^^^^^^^^^^^^^^^^^^^
  File "/Users/mutafvladimir/Documents/IT/dZENcode/.venv/lib/python3.12/site-packages/django/db/models/sql/compiler.py", line 1622, in execute_sql
    cursor.execute(sql, params)
  File "/Users/mutafvladimir/Documents/IT/dZENcode/.venv/lib/python3.12/site-packages/django/db/backends/utils.py", line 122, in execute
    return super().execute(sql, params)
           ^^^^^^^^^^^^^^^^^^^^^^^^^^^^
  File "/Users/mutafvladimir/Documents/IT/dZENcode/.venv/lib/python3.12/site-packages/django/db/backends/utils.py", line 79, in execute
    return self._execute_with_wrappers(
           ^^^^^^^^^^^^^^^^^^^^^^^^^^^^
  File "/Users/mutafvladimir/Documents/IT/dZENcode/.venv/lib/python3.12/site-packages/django/db/backends/utils.py", line 92, in _execute_with_wrappers
    return executor(sql, params, many, context)
           ^^^^^^^^^^^^^^^^^^^^^^^^^^^^^^^^^^^^
  File "/Users/mutafvladimir/Documents/IT/dZENcode/.venv/lib/python3.12/site-packages/django/db/backends/utils.py", line 100, in _execute
    with self.db.wrap_database_errors:
         ^^^^^^^^^^^^^^^^^^^^^^^^^^^^
  File "/Users/mutafvladimir/Documents/IT/dZENcode/.venv/lib/python3.12/site-packages/django/db/utils.py", line 91, in __exit__
    raise dj_exc_value.with_traceback(traceback) from exc_value
  File "/Users/mutafvladimir/Documents/IT/dZENcode/.venv/lib/python3.12/site-packages/django/db/backends/utils.py", line 105, in _execute
    return self.cursor.execute(sql, params)
           ^^^^^^^^^^^^^^^^^^^^^^^^^^^^^^^^
  File "/Users/mutafvladimir/Documents/IT/dZENcode/.venv/lib/python3.12/site-packages/django/db/backends/sqlite3/base.py", line 360, in execute
    return super().execute(query, params)
           ^^^^^^^^^^^^^^^^^^^^^^^^^^^^^^
django.db.utils.OperationalError: no such table: comments_comment
[2025-04-28 15:26:20,746] ERROR django.request Internal Server Error: /api/v1/comments/comments/
Traceback (most recent call last):
  File "/Users/mutafvladimir/Documents/IT/dZENcode/.venv/lib/python3.12/site-packages/django/core/handlers/exception.py", line 55, in inner
    response = get_response(request)
               ^^^^^^^^^^^^^^^^^^^^^
  File "/Users/mutafvladimir/Documents/IT/dZENcode/.venv/lib/python3.12/site-packages/django/core/handlers/base.py", line 197, in _get_response
    response = wrapped_callback(request, *callback_args, **callback_kwargs)
               ^^^^^^^^^^^^^^^^^^^^^^^^^^^^^^^^^^^^^^^^^^^^^^^^^^^^^^^^^^^^
  File "/Users/mutafvladimir/Documents/IT/dZENcode/.venv/lib/python3.12/site-packages/django/views/decorators/csrf.py", line 65, in _view_wrapper
    return view_func(request, *args, **kwargs)
           ^^^^^^^^^^^^^^^^^^^^^^^^^^^^^^^^^^^
  File "/Users/mutafvladimir/Documents/IT/dZENcode/.venv/lib/python3.12/site-packages/rest_framework/viewsets.py", line 125, in view
    return self.dispatch(request, *args, **kwargs)
           ^^^^^^^^^^^^^^^^^^^^^^^^^^^^^^^^^^^^^^^
  File "/Users/mutafvladimir/Documents/IT/dZENcode/.venv/lib/python3.12/site-packages/rest_framework/views.py", line 515, in dispatch
    response = self.handle_exception(exc)
               ^^^^^^^^^^^^^^^^^^^^^^^^^^
  File "/Users/mutafvladimir/Documents/IT/dZENcode/.venv/lib/python3.12/site-packages/rest_framework/views.py", line 475, in handle_exception
    self.raise_uncaught_exception(exc)
  File "/Users/mutafvladimir/Documents/IT/dZENcode/.venv/lib/python3.12/site-packages/rest_framework/views.py", line 486, in raise_uncaught_exception
    raise exc
  File "/Users/mutafvladimir/Documents/IT/dZENcode/.venv/lib/python3.12/site-packages/rest_framework/views.py", line 512, in dispatch
    response = handler(request, *args, **kwargs)
               ^^^^^^^^^^^^^^^^^^^^^^^^^^^^^^^^^
  File "/Users/mutafvladimir/Documents/IT/dZENcode/.venv/lib/python3.12/site-packages/rest_framework/mixins.py", line 19, in create
    self.perform_create(serializer)
  File "/Users/mutafvladimir/Documents/IT/dZENcode/.venv/lib/python3.12/site-packages/rest_framework/mixins.py", line 24, in perform_create
    serializer.save()
  File "/Users/mutafvladimir/Documents/IT/dZENcode/.venv/lib/python3.12/site-packages/rest_framework/serializers.py", line 210, in save
    self.instance = self.create(validated_data)
                    ^^^^^^^^^^^^^^^^^^^^^^^^^^^
  File "/Users/mutafvladimir/Documents/IT/dZENcode/.venv/lib/python3.12/site-packages/rest_framework/serializers.py", line 991, in create
    instance = ModelClass._default_manager.create(**validated_data)
               ^^^^^^^^^^^^^^^^^^^^^^^^^^^^^^^^^^^^^^^^^^^^^^^^^^^^
  File "/Users/mutafvladimir/Documents/IT/dZENcode/.venv/lib/python3.12/site-packages/django/db/models/manager.py", line 87, in manager_method
    return getattr(self.get_queryset(), name)(*args, **kwargs)
           ^^^^^^^^^^^^^^^^^^^^^^^^^^^^^^^^^^^^^^^^^^^^^^^^^^^
  File "/Users/mutafvladimir/Documents/IT/dZENcode/.venv/lib/python3.12/site-packages/django/db/models/query.py", line 661, in create
    obj = self.model(**kwargs)
          ^^^^^^^^^^^^^^^^^^^^
  File "/Users/mutafvladimir/Documents/IT/dZENcode/.venv/lib/python3.12/site-packages/django/db/models/base.py", line 545, in __init__
    _setattr(self, field.name, rel_obj)
  File "/Users/mutafvladimir/Documents/IT/dZENcode/.venv/lib/python3.12/site-packages/django/db/models/fields/related_descriptors.py", line 288, in __set__
    raise ValueError(
ValueError: Cannot assign "<django.contrib.auth.models.AnonymousUser object at 0x2d40d2960>": "Comment.user" must be a "User" instance.
[2025-04-28 15:26:40,086] WARNING django.request Not Found: /api/v1/members/members/5/settings/
[2025-04-28 15:26:41,749] WARNING django.request Not Found: /api/v1/members/members/5/settings/
[2025-04-28 15:26:48,475] WARNING django.request Not Found: /api/v1/applications/grader_name/
[2025-04-28 15:26:50,184] WARNING django.request Not Found: /api/v1/auth/register/email/
[2025-04-28 15:27:04,708] WARNING django.request Method Not Allowed: /api/v1/auth/registration/
[2025-04-28 15:28:34,949] WARNING django.request Bad Request: /api/v1/auth/registration/
[2025-04-28 15:28:39,458] WARNING django.request Method Not Allowed: /api/v1/auth/registration/
[2025-04-28 15:28:46,182] WARNING django.request Method Not Allowed: /api/v1/auth/login/
[2025-04-28 15:29:12,191] WARNING django.request Not Found: /api/v1/members/members/5/settings/
[2025-04-28 15:30:08,217] ERROR django.request Internal Server Error: /api/v1/comments/comments/
Traceback (most recent call last):
  File "/Users/mutafvladimir/Documents/IT/dZENcode/.venv/lib/python3.12/site-packages/django/core/handlers/exception.py", line 55, in inner
    response = get_response(request)
               ^^^^^^^^^^^^^^^^^^^^^
  File "/Users/mutafvladimir/Documents/IT/dZENcode/.venv/lib/python3.12/site-packages/django/core/handlers/base.py", line 197, in _get_response
    response = wrapped_callback(request, *callback_args, **callback_kwargs)
               ^^^^^^^^^^^^^^^^^^^^^^^^^^^^^^^^^^^^^^^^^^^^^^^^^^^^^^^^^^^^
  File "/Users/mutafvladimir/Documents/IT/dZENcode/.venv/lib/python3.12/site-packages/django/views/decorators/csrf.py", line 65, in _view_wrapper
    return view_func(request, *args, **kwargs)
           ^^^^^^^^^^^^^^^^^^^^^^^^^^^^^^^^^^^
  File "/Users/mutafvladimir/Documents/IT/dZENcode/.venv/lib/python3.12/site-packages/rest_framework/viewsets.py", line 125, in view
    return self.dispatch(request, *args, **kwargs)
           ^^^^^^^^^^^^^^^^^^^^^^^^^^^^^^^^^^^^^^^
  File "/Users/mutafvladimir/Documents/IT/dZENcode/.venv/lib/python3.12/site-packages/rest_framework/views.py", line 515, in dispatch
    response = self.handle_exception(exc)
               ^^^^^^^^^^^^^^^^^^^^^^^^^^
  File "/Users/mutafvladimir/Documents/IT/dZENcode/.venv/lib/python3.12/site-packages/rest_framework/views.py", line 475, in handle_exception
    self.raise_uncaught_exception(exc)
  File "/Users/mutafvladimir/Documents/IT/dZENcode/.venv/lib/python3.12/site-packages/rest_framework/views.py", line 486, in raise_uncaught_exception
    raise exc
  File "/Users/mutafvladimir/Documents/IT/dZENcode/.venv/lib/python3.12/site-packages/rest_framework/views.py", line 512, in dispatch
    response = handler(request, *args, **kwargs)
               ^^^^^^^^^^^^^^^^^^^^^^^^^^^^^^^^^
  File "/Users/mutafvladimir/Documents/IT/dZENcode/.venv/lib/python3.12/site-packages/rest_framework/mixins.py", line 43, in list
    return self.get_paginated_response(serializer.data)
                                       ^^^^^^^^^^^^^^^
  File "/Users/mutafvladimir/Documents/IT/dZENcode/.venv/lib/python3.12/site-packages/rest_framework/serializers.py", line 797, in data
    ret = super().data
          ^^^^^^^^^^^^
  File "/Users/mutafvladimir/Documents/IT/dZENcode/.venv/lib/python3.12/site-packages/rest_framework/serializers.py", line 251, in data
    self._data = self.to_representation(self.instance)
                 ^^^^^^^^^^^^^^^^^^^^^^^^^^^^^^^^^^^^^
  File "/Users/mutafvladimir/Documents/IT/dZENcode/.venv/lib/python3.12/site-packages/rest_framework/serializers.py", line 716, in to_representation
    self.child.to_representation(item) for item in iterable
    ^^^^^^^^^^^^^^^^^^^^^^^^^^^^^^^^^^
  File "/Users/mutafvladimir/Documents/IT/dZENcode/.venv/lib/python3.12/site-packages/rest_framework/serializers.py", line 540, in to_representation
    ret[field.field_name] = field.to_representation(attribute)
                            ^^^^^^^^^^^^^^^^^^^^^^^^^^^^^^^^^^
  File "/Users/mutafvladimir/Documents/IT/dZENcode/.venv/lib/python3.12/site-packages/rest_framework/serializers.py", line 525, in to_representation
    for field in fields:
                 ^^^^^^
  File "/Users/mutafvladimir/Documents/IT/dZENcode/.venv/lib/python3.12/site-packages/rest_framework/serializers.py", line 386, in _readable_fields
    for field in self.fields.values():
                 ^^^^^^^^^^^
  File "/Users/mutafvladimir/Documents/IT/dZENcode/.venv/lib/python3.12/site-packages/django/utils/functional.py", line 47, in __get__
    res = instance.__dict__[self.name] = self.func(instance)
                                         ^^^^^^^^^^^^^^^^^^^
  File "/Users/mutafvladimir/Documents/IT/dZENcode/.venv/lib/python3.12/site-packages/rest_framework/serializers.py", line 374, in fields
    for key, value in self.get_fields().items():
                      ^^^^^^^^^^^^^^^^^
  File "/Users/mutafvladimir/Documents/IT/dZENcode/.venv/lib/python3.12/site-packages/rest_framework/serializers.py", line 1085, in get_fields
    extra_kwargs = self.get_extra_kwargs()
                   ^^^^^^^^^^^^^^^^^^^^^^^
  File "/Users/mutafvladimir/Documents/IT/dZENcode/.venv/lib/python3.12/site-packages/rest_framework/serializers.py", line 1408, in get_extra_kwargs
    raise TypeError(
TypeError: The `read_only_fields` option must be a list or tuple. Got str.
[2025-04-28 15:32:41,494] ERROR django.request Internal Server Error: /api/v1/comments/comments/1/
Traceback (most recent call last):
  File "/Users/mutafvladimir/Documents/IT/dZENcode/.venv/lib/python3.12/site-packages/django/core/handlers/exception.py", line 55, in inner
    response = get_response(request)
               ^^^^^^^^^^^^^^^^^^^^^
  File "/Users/mutafvladimir/Documents/IT/dZENcode/.venv/lib/python3.12/site-packages/django/core/handlers/base.py", line 197, in _get_response
    response = wrapped_callback(request, *callback_args, **callback_kwargs)
               ^^^^^^^^^^^^^^^^^^^^^^^^^^^^^^^^^^^^^^^^^^^^^^^^^^^^^^^^^^^^
  File "/Users/mutafvladimir/Documents/IT/dZENcode/.venv/lib/python3.12/site-packages/django/views/decorators/csrf.py", line 65, in _view_wrapper
    return view_func(request, *args, **kwargs)
           ^^^^^^^^^^^^^^^^^^^^^^^^^^^^^^^^^^^
  File "/Users/mutafvladimir/Documents/IT/dZENcode/.venv/lib/python3.12/site-packages/rest_framework/viewsets.py", line 125, in view
    return self.dispatch(request, *args, **kwargs)
           ^^^^^^^^^^^^^^^^^^^^^^^^^^^^^^^^^^^^^^^
  File "/Users/mutafvladimir/Documents/IT/dZENcode/.venv/lib/python3.12/site-packages/rest_framework/views.py", line 515, in dispatch
    response = self.handle_exception(exc)
               ^^^^^^^^^^^^^^^^^^^^^^^^^^
  File "/Users/mutafvladimir/Documents/IT/dZENcode/.venv/lib/python3.12/site-packages/rest_framework/views.py", line 475, in handle_exception
    self.raise_uncaught_exception(exc)
  File "/Users/mutafvladimir/Documents/IT/dZENcode/.venv/lib/python3.12/site-packages/rest_framework/views.py", line 486, in raise_uncaught_exception
    raise exc
  File "/Users/mutafvladimir/Documents/IT/dZENcode/.venv/lib/python3.12/site-packages/rest_framework/views.py", line 512, in dispatch
    response = handler(request, *args, **kwargs)
               ^^^^^^^^^^^^^^^^^^^^^^^^^^^^^^^^^
  File "/Users/mutafvladimir/Documents/IT/dZENcode/.venv/lib/python3.12/site-packages/rest_framework/mixins.py", line 56, in retrieve
    return Response(serializer.data)
                    ^^^^^^^^^^^^^^^
  File "/Users/mutafvladimir/Documents/IT/dZENcode/.venv/lib/python3.12/site-packages/rest_framework/serializers.py", line 573, in data
    ret = super().data
          ^^^^^^^^^^^^
  File "/Users/mutafvladimir/Documents/IT/dZENcode/.venv/lib/python3.12/site-packages/rest_framework/serializers.py", line 251, in data
    self._data = self.to_representation(self.instance)
                 ^^^^^^^^^^^^^^^^^^^^^^^^^^^^^^^^^^^^^
  File "/Users/mutafvladimir/Documents/IT/dZENcode/.venv/lib/python3.12/site-packages/rest_framework/serializers.py", line 525, in to_representation
    for field in fields:
                 ^^^^^^
  File "/Users/mutafvladimir/Documents/IT/dZENcode/.venv/lib/python3.12/site-packages/rest_framework/serializers.py", line 386, in _readable_fields
    for field in self.fields.values():
                 ^^^^^^^^^^^
  File "/Users/mutafvladimir/Documents/IT/dZENcode/.venv/lib/python3.12/site-packages/django/utils/functional.py", line 47, in __get__
    res = instance.__dict__[self.name] = self.func(instance)
                                         ^^^^^^^^^^^^^^^^^^^
  File "/Users/mutafvladimir/Documents/IT/dZENcode/.venv/lib/python3.12/site-packages/rest_framework/serializers.py", line 374, in fields
    for key, value in self.get_fields().items():
                      ^^^^^^^^^^^^^^^^^
  File "/Users/mutafvladimir/Documents/IT/dZENcode/.venv/lib/python3.12/site-packages/rest_framework/serializers.py", line 1105, in get_fields
    field_class, field_kwargs = self.build_field(
                                ^^^^^^^^^^^^^^^^^
  File "/Users/mutafvladimir/Documents/IT/dZENcode/.venv/lib/python3.12/site-packages/rest_framework/serializers.py", line 1251, in build_field
    return self.build_unknown_field(field_name, model_class)
           ^^^^^^^^^^^^^^^^^^^^^^^^^^^^^^^^^^^^^^^^^^^^^^^^^
  File "/Users/mutafvladimir/Documents/IT/dZENcode/.venv/lib/python3.12/site-packages/rest_framework/serializers.py", line 1369, in build_unknown_field
    raise ImproperlyConfigured(
django.core.exceptions.ImproperlyConfigured: Field name `image` is not valid for model `Comment` in `comments.api.serializers.comments.CommentDetailUpdateSerializer`.
[2025-04-28 15:33:44,029] ERROR django.request Internal Server Error: /api/v1/comments/comments/1/
Traceback (most recent call last):
  File "/Users/mutafvladimir/Documents/IT/dZENcode/.venv/lib/python3.12/site-packages/django/core/handlers/exception.py", line 55, in inner
    response = get_response(request)
               ^^^^^^^^^^^^^^^^^^^^^
  File "/Users/mutafvladimir/Documents/IT/dZENcode/.venv/lib/python3.12/site-packages/django/core/handlers/base.py", line 197, in _get_response
    response = wrapped_callback(request, *callback_args, **callback_kwargs)
               ^^^^^^^^^^^^^^^^^^^^^^^^^^^^^^^^^^^^^^^^^^^^^^^^^^^^^^^^^^^^
  File "/Users/mutafvladimir/Documents/IT/dZENcode/.venv/lib/python3.12/site-packages/django/views/decorators/csrf.py", line 65, in _view_wrapper
    return view_func(request, *args, **kwargs)
           ^^^^^^^^^^^^^^^^^^^^^^^^^^^^^^^^^^^
  File "/Users/mutafvladimir/Documents/IT/dZENcode/.venv/lib/python3.12/site-packages/rest_framework/viewsets.py", line 125, in view
    return self.dispatch(request, *args, **kwargs)
           ^^^^^^^^^^^^^^^^^^^^^^^^^^^^^^^^^^^^^^^
  File "/Users/mutafvladimir/Documents/IT/dZENcode/.venv/lib/python3.12/site-packages/rest_framework/views.py", line 515, in dispatch
    response = self.handle_exception(exc)
               ^^^^^^^^^^^^^^^^^^^^^^^^^^
  File "/Users/mutafvladimir/Documents/IT/dZENcode/.venv/lib/python3.12/site-packages/rest_framework/views.py", line 475, in handle_exception
    self.raise_uncaught_exception(exc)
  File "/Users/mutafvladimir/Documents/IT/dZENcode/.venv/lib/python3.12/site-packages/rest_framework/views.py", line 486, in raise_uncaught_exception
    raise exc
  File "/Users/mutafvladimir/Documents/IT/dZENcode/.venv/lib/python3.12/site-packages/rest_framework/views.py", line 512, in dispatch
    response = handler(request, *args, **kwargs)
               ^^^^^^^^^^^^^^^^^^^^^^^^^^^^^^^^^
  File "/Users/mutafvladimir/Documents/IT/dZENcode/.venv/lib/python3.12/site-packages/rest_framework/mixins.py", line 68, in update
    self.perform_update(serializer)
  File "/Users/mutafvladimir/Documents/IT/dZENcode/.venv/lib/python3.12/site-packages/rest_framework/mixins.py", line 78, in perform_update
    serializer.save()
  File "/Users/mutafvladimir/Documents/IT/dZENcode/.venv/lib/python3.12/site-packages/rest_framework/serializers.py", line 205, in save
    self.instance = self.update(self.instance, validated_data)
                    ^^^^^^^^^^^^^^^^^^^^^^^^^^^^^^^^^^^^^^^^^^
  File "/Users/mutafvladimir/Documents/IT/dZENcode/.venv/lib/python3.12/site-packages/rest_framework/serializers.py", line 1021, in update
    raise_errors_on_nested_writes('update', self, validated_data)
  File "/Users/mutafvladimir/Documents/IT/dZENcode/.venv/lib/python3.12/site-packages/rest_framework/serializers.py", line 873, in raise_errors_on_nested_writes
    assert not any(
           ^^^^^^^^
AssertionError: The `.update()` method does not support writable dotted-source fields by default.
Write an explicit `.update()` method for serializer `comments.api.serializers.comments.CommentDetailUpdateSerializer`, or set `read_only=True` on dotted-source serializer fields.
[2025-04-28 15:37:53,979] ERROR django.request Internal Server Error: /api/v1/comments/comments/1/
Traceback (most recent call last):
  File "/Users/mutafvladimir/Documents/IT/dZENcode/.venv/lib/python3.12/site-packages/django/core/handlers/exception.py", line 55, in inner
    response = get_response(request)
               ^^^^^^^^^^^^^^^^^^^^^
  File "/Users/mutafvladimir/Documents/IT/dZENcode/.venv/lib/python3.12/site-packages/django/core/handlers/base.py", line 197, in _get_response
    response = wrapped_callback(request, *callback_args, **callback_kwargs)
               ^^^^^^^^^^^^^^^^^^^^^^^^^^^^^^^^^^^^^^^^^^^^^^^^^^^^^^^^^^^^
  File "/Users/mutafvladimir/Documents/IT/dZENcode/.venv/lib/python3.12/site-packages/django/views/decorators/csrf.py", line 65, in _view_wrapper
    return view_func(request, *args, **kwargs)
           ^^^^^^^^^^^^^^^^^^^^^^^^^^^^^^^^^^^
  File "/Users/mutafvladimir/Documents/IT/dZENcode/.venv/lib/python3.12/site-packages/rest_framework/viewsets.py", line 125, in view
    return self.dispatch(request, *args, **kwargs)
           ^^^^^^^^^^^^^^^^^^^^^^^^^^^^^^^^^^^^^^^
  File "/Users/mutafvladimir/Documents/IT/dZENcode/.venv/lib/python3.12/site-packages/rest_framework/views.py", line 515, in dispatch
    response = self.handle_exception(exc)
               ^^^^^^^^^^^^^^^^^^^^^^^^^^
  File "/Users/mutafvladimir/Documents/IT/dZENcode/.venv/lib/python3.12/site-packages/rest_framework/views.py", line 475, in handle_exception
    self.raise_uncaught_exception(exc)
  File "/Users/mutafvladimir/Documents/IT/dZENcode/.venv/lib/python3.12/site-packages/rest_framework/views.py", line 486, in raise_uncaught_exception
    raise exc
  File "/Users/mutafvladimir/Documents/IT/dZENcode/.venv/lib/python3.12/site-packages/rest_framework/views.py", line 512, in dispatch
    response = handler(request, *args, **kwargs)
               ^^^^^^^^^^^^^^^^^^^^^^^^^^^^^^^^^
  File "/Users/mutafvladimir/Documents/IT/dZENcode/.venv/lib/python3.12/site-packages/rest_framework/mixins.py", line 68, in update
    self.perform_update(serializer)
  File "/Users/mutafvladimir/Documents/IT/dZENcode/.venv/lib/python3.12/site-packages/rest_framework/mixins.py", line 78, in perform_update
    serializer.save()
  File "/Users/mutafvladimir/Documents/IT/dZENcode/.venv/lib/python3.12/site-packages/rest_framework/serializers.py", line 205, in save
    self.instance = self.update(self.instance, validated_data)
                    ^^^^^^^^^^^^^^^^^^^^^^^^^^^^^^^^^^^^^^^^^^
  File "/Users/mutafvladimir/Documents/IT/dZENcode/.venv/lib/python3.12/site-packages/rest_framework/serializers.py", line 1021, in update
    raise_errors_on_nested_writes('update', self, validated_data)
  File "/Users/mutafvladimir/Documents/IT/dZENcode/.venv/lib/python3.12/site-packages/rest_framework/serializers.py", line 873, in raise_errors_on_nested_writes
    assert not any(
           ^^^^^^^^
AssertionError: The `.update()` method does not support writable dotted-source fields by default.
Write an explicit `.update()` method for serializer `comments.api.serializers.comments.CommentDetailUpdateSerializer`, or set `read_only=True` on dotted-source serializer fields.
[2025-04-28 15:41:56,053] ERROR django.request Internal Server Error: /api/v1/comments/comments/
Traceback (most recent call last):
  File "/Users/mutafvladimir/Documents/IT/dZENcode/.venv/lib/python3.12/site-packages/django/core/handlers/exception.py", line 55, in inner
    response = get_response(request)
               ^^^^^^^^^^^^^^^^^^^^^
  File "/Users/mutafvladimir/Documents/IT/dZENcode/.venv/lib/python3.12/site-packages/django/core/handlers/base.py", line 220, in _get_response
    response = response.render()
               ^^^^^^^^^^^^^^^^^
  File "/Users/mutafvladimir/Documents/IT/dZENcode/.venv/lib/python3.12/site-packages/django/template/response.py", line 114, in render
    self.content = self.rendered_content
                   ^^^^^^^^^^^^^^^^^^^^^
  File "/Users/mutafvladimir/Documents/IT/dZENcode/.venv/lib/python3.12/site-packages/rest_framework/response.py", line 74, in rendered_content
    ret = renderer.render(self.data, accepted_media_type, context)
          ^^^^^^^^^^^^^^^^^^^^^^^^^^^^^^^^^^^^^^^^^^^^^^^^^^^^^^^^
  File "/Users/mutafvladimir/Documents/IT/dZENcode/.venv/lib/python3.12/site-packages/rest_framework/renderers.py", line 731, in render
    context = self.get_context(data, accepted_media_type, renderer_context)
              ^^^^^^^^^^^^^^^^^^^^^^^^^^^^^^^^^^^^^^^^^^^^^^^^^^^^^^^^^^^^^
  File "/Users/mutafvladimir/Documents/IT/dZENcode/.venv/lib/python3.12/site-packages/rest_framework/renderers.py", line 687, in get_context
    'content': self.get_content(renderer, data, accepted_media_type, renderer_context),
               ^^^^^^^^^^^^^^^^^^^^^^^^^^^^^^^^^^^^^^^^^^^^^^^^^^^^^^^^^^^^^^^^^^^^^^^
  File "/Users/mutafvladimir/Documents/IT/dZENcode/.venv/lib/python3.12/site-packages/rest_framework/renderers.py", line 417, in get_content
    content = renderer.render(data, accepted_media_type, renderer_context)
              ^^^^^^^^^^^^^^^^^^^^^^^^^^^^^^^^^^^^^^^^^^^^^^^^^^^^^^^^^^^^
  File "/Users/mutafvladimir/Documents/IT/dZENcode/.venv/lib/python3.12/site-packages/rest_framework/renderers.py", line 100, in render
    ret = json.dumps(
          ^^^^^^^^^^^
  File "/Users/mutafvladimir/Documents/IT/dZENcode/.venv/lib/python3.12/site-packages/rest_framework/utils/json.py", line 25, in dumps
    return json.dumps(*args, **kwargs)
           ^^^^^^^^^^^^^^^^^^^^^^^^^^^
  File "/Library/Frameworks/Python.framework/Versions/3.12/lib/python3.12/json/__init__.py", line 238, in dumps
    **kw).encode(obj)
          ^^^^^^^^^^^
  File "/Library/Frameworks/Python.framework/Versions/3.12/lib/python3.12/json/encoder.py", line 202, in encode
    chunks = list(chunks)
             ^^^^^^^^^^^^
  File "/Library/Frameworks/Python.framework/Versions/3.12/lib/python3.12/json/encoder.py", line 432, in _iterencode
    yield from _iterencode_dict(o, _current_indent_level)
  File "/Library/Frameworks/Python.framework/Versions/3.12/lib/python3.12/json/encoder.py", line 406, in _iterencode_dict
    yield from chunks
  File "/Library/Frameworks/Python.framework/Versions/3.12/lib/python3.12/json/encoder.py", line 326, in _iterencode_list
    yield from chunks
  File "/Library/Frameworks/Python.framework/Versions/3.12/lib/python3.12/json/encoder.py", line 406, in _iterencode_dict
    yield from chunks
  File "/Library/Frameworks/Python.framework/Versions/3.12/lib/python3.12/json/encoder.py", line 439, in _iterencode
    o = _default(o)
        ^^^^^^^^^^^
  File "/Users/mutafvladimir/Documents/IT/dZENcode/.venv/lib/python3.12/site-packages/rest_framework/utils/encoders.py", line 67, in default
    return super().default(obj)
           ^^^^^^^^^^^^^^^^^^^^
  File "/Library/Frameworks/Python.framework/Versions/3.12/lib/python3.12/json/encoder.py", line 180, in default
    raise TypeError(f'Object of type {o.__class__.__name__} '
TypeError: Object of type CommentListSerializer is not JSON serializable
[2025-04-28 15:56:55,717] WARNING django.request Not Found: /api/v1/comments/comments/2/
[2025-04-28 15:56:58,510] ERROR django.request Internal Server Error: /api/v1/comments/comments/
Traceback (most recent call last):
  File "/Users/mutafvladimir/Documents/IT/dZENcode/.venv/lib/python3.12/site-packages/django/core/handlers/exception.py", line 55, in inner
    response = get_response(request)
               ^^^^^^^^^^^^^^^^^^^^^
  File "/Users/mutafvladimir/Documents/IT/dZENcode/.venv/lib/python3.12/site-packages/django/core/handlers/base.py", line 197, in _get_response
    response = wrapped_callback(request, *callback_args, **callback_kwargs)
               ^^^^^^^^^^^^^^^^^^^^^^^^^^^^^^^^^^^^^^^^^^^^^^^^^^^^^^^^^^^^
  File "/Users/mutafvladimir/Documents/IT/dZENcode/.venv/lib/python3.12/site-packages/django/views/decorators/csrf.py", line 65, in _view_wrapper
    return view_func(request, *args, **kwargs)
           ^^^^^^^^^^^^^^^^^^^^^^^^^^^^^^^^^^^
  File "/Users/mutafvladimir/Documents/IT/dZENcode/.venv/lib/python3.12/site-packages/rest_framework/viewsets.py", line 125, in view
    return self.dispatch(request, *args, **kwargs)
           ^^^^^^^^^^^^^^^^^^^^^^^^^^^^^^^^^^^^^^^
  File "/Users/mutafvladimir/Documents/IT/dZENcode/.venv/lib/python3.12/site-packages/rest_framework/views.py", line 515, in dispatch
    response = self.handle_exception(exc)
               ^^^^^^^^^^^^^^^^^^^^^^^^^^
  File "/Users/mutafvladimir/Documents/IT/dZENcode/.venv/lib/python3.12/site-packages/rest_framework/views.py", line 475, in handle_exception
    self.raise_uncaught_exception(exc)
  File "/Users/mutafvladimir/Documents/IT/dZENcode/.venv/lib/python3.12/site-packages/rest_framework/views.py", line 486, in raise_uncaught_exception
    raise exc
  File "/Users/mutafvladimir/Documents/IT/dZENcode/.venv/lib/python3.12/site-packages/rest_framework/views.py", line 512, in dispatch
    response = handler(request, *args, **kwargs)
               ^^^^^^^^^^^^^^^^^^^^^^^^^^^^^^^^^
  File "/Users/mutafvladimir/Documents/IT/dZENcode/.venv/lib/python3.12/site-packages/rest_framework/mixins.py", line 43, in list
    return self.get_paginated_response(serializer.data)
                                       ^^^^^^^^^^^^^^^
  File "/Users/mutafvladimir/Documents/IT/dZENcode/.venv/lib/python3.12/site-packages/rest_framework/serializers.py", line 797, in data
    ret = super().data
          ^^^^^^^^^^^^
  File "/Users/mutafvladimir/Documents/IT/dZENcode/.venv/lib/python3.12/site-packages/rest_framework/serializers.py", line 251, in data
    self._data = self.to_representation(self.instance)
                 ^^^^^^^^^^^^^^^^^^^^^^^^^^^^^^^^^^^^^
  File "/Users/mutafvladimir/Documents/IT/dZENcode/.venv/lib/python3.12/site-packages/rest_framework/serializers.py", line 716, in to_representation
    self.child.to_representation(item) for item in iterable
    ^^^^^^^^^^^^^^^^^^^^^^^^^^^^^^^^^^
  File "/Users/mutafvladimir/Documents/IT/dZENcode/.venv/lib/python3.12/site-packages/rest_framework/serializers.py", line 525, in to_representation
    for field in fields:
                 ^^^^^^
  File "/Users/mutafvladimir/Documents/IT/dZENcode/.venv/lib/python3.12/site-packages/rest_framework/serializers.py", line 386, in _readable_fields
    for field in self.fields.values():
                 ^^^^^^^^^^^
  File "/Users/mutafvladimir/Documents/IT/dZENcode/.venv/lib/python3.12/site-packages/django/utils/functional.py", line 47, in __get__
    res = instance.__dict__[self.name] = self.func(instance)
                                         ^^^^^^^^^^^^^^^^^^^
  File "/Users/mutafvladimir/Documents/IT/dZENcode/.venv/lib/python3.12/site-packages/rest_framework/serializers.py", line 374, in fields
    for key, value in self.get_fields().items():
                      ^^^^^^^^^^^^^^^^^
  File "/Users/mutafvladimir/Documents/IT/dZENcode/.venv/lib/python3.12/site-packages/rest_framework/serializers.py", line 1085, in get_fields
    extra_kwargs = self.get_extra_kwargs()
                   ^^^^^^^^^^^^^^^^^^^^^^^
  File "/Users/mutafvladimir/Documents/IT/dZENcode/.venv/lib/python3.12/site-packages/rest_framework/serializers.py", line 1408, in get_extra_kwargs
    raise TypeError(
TypeError: The `read_only_fields` option must be a list or tuple. Got str.
[2025-04-28 16:48:52,514] WARNING django.request Method Not Allowed: /api/v1/comments/comments/1/like/
[2025-04-28 16:48:59,712] WARNING django.request Method Not Allowed: /api/v1/comments/comments/1/like/
[2025-04-28 16:49:33,768] WARNING django.request Method Not Allowed: /api/v1/comments/comments/1/like/
[2025-04-28 16:49:49,987] WARNING django.request Method Not Allowed: /api/v1/comments/comments/1/like/
[2025-04-28 16:49:56,684] WARNING django.request Method Not Allowed: /api/v1/comments/comments/1/dislike/
[2025-04-28 16:49:58,064] ERROR django.request Internal Server Error: /api/v1/comments/comments/1/dislike/
Traceback (most recent call last):
  File "/Users/mutafvladimir/Documents/IT/dZENcode/.venv/lib/python3.12/site-packages/django/core/handlers/exception.py", line 55, in inner
    response = get_response(request)
               ^^^^^^^^^^^^^^^^^^^^^
  File "/Users/mutafvladimir/Documents/IT/dZENcode/.venv/lib/python3.12/site-packages/django/core/handlers/base.py", line 197, in _get_response
    response = wrapped_callback(request, *callback_args, **callback_kwargs)
               ^^^^^^^^^^^^^^^^^^^^^^^^^^^^^^^^^^^^^^^^^^^^^^^^^^^^^^^^^^^^
  File "/Users/mutafvladimir/Documents/IT/dZENcode/.venv/lib/python3.12/site-packages/django/views/decorators/csrf.py", line 65, in _view_wrapper
    return view_func(request, *args, **kwargs)
           ^^^^^^^^^^^^^^^^^^^^^^^^^^^^^^^^^^^
  File "/Users/mutafvladimir/Documents/IT/dZENcode/.venv/lib/python3.12/site-packages/rest_framework/viewsets.py", line 125, in view
    return self.dispatch(request, *args, **kwargs)
           ^^^^^^^^^^^^^^^^^^^^^^^^^^^^^^^^^^^^^^^
  File "/Users/mutafvladimir/Documents/IT/dZENcode/.venv/lib/python3.12/site-packages/rest_framework/views.py", line 515, in dispatch
    response = self.handle_exception(exc)
               ^^^^^^^^^^^^^^^^^^^^^^^^^^
  File "/Users/mutafvladimir/Documents/IT/dZENcode/.venv/lib/python3.12/site-packages/rest_framework/views.py", line 475, in handle_exception
    self.raise_uncaught_exception(exc)
  File "/Users/mutafvladimir/Documents/IT/dZENcode/.venv/lib/python3.12/site-packages/rest_framework/views.py", line 486, in raise_uncaught_exception
    raise exc
  File "/Users/mutafvladimir/Documents/IT/dZENcode/.venv/lib/python3.12/site-packages/rest_framework/views.py", line 512, in dispatch
    response = handler(request, *args, **kwargs)
               ^^^^^^^^^^^^^^^^^^^^^^^^^^^^^^^^^
  File "/Users/mutafvladimir/Documents/IT/dZENcode/comments/api/viewsets/comments.py", line 57, in dislike
    return self._set_reaction(request.user, Reaction.ReactionTypes.DISLIKE)
           ^^^^^^^^^^^^^^^^^^^^^^^^^^^^^^^^^^^^^^^^^^^^^^^^^^^^^^^^^^^^^^^^
  File "/Users/mutafvladimir/Documents/IT/dZENcode/comments/api/viewsets/comments.py", line 45, in _set_reaction
    reaction.save(update_fields=['reaction'])
  File "/Users/mutafvladimir/Documents/IT/dZENcode/.venv/lib/python3.12/site-packages/django/db/models/base.py", line 902, in save
    self.save_base(
  File "/Users/mutafvladimir/Documents/IT/dZENcode/.venv/lib/python3.12/site-packages/django/db/models/base.py", line 1008, in save_base
    updated = self._save_table(
              ^^^^^^^^^^^^^^^^^
  File "/Users/mutafvladimir/Documents/IT/dZENcode/.venv/lib/python3.12/site-packages/django/db/models/base.py", line 1138, in _save_table
    updated = self._do_update(
              ^^^^^^^^^^^^^^^^
  File "/Users/mutafvladimir/Documents/IT/dZENcode/.venv/lib/python3.12/site-packages/django/db/models/base.py", line 1203, in _do_update
    return filtered._update(values) > 0
           ^^^^^^^^^^^^^^^^^^^^^^^^
  File "/Users/mutafvladimir/Documents/IT/dZENcode/.venv/lib/python3.12/site-packages/django/db/models/query.py", line 1283, in _update
    return query.get_compiler(self.db).execute_sql(ROW_COUNT)
           ^^^^^^^^^^^^^^^^^^^^^^^^^^^^^^^^^^^^^^^^^^^^^^^^^^
  File "/Users/mutafvladimir/Documents/IT/dZENcode/.venv/lib/python3.12/site-packages/django/db/models/sql/compiler.py", line 2059, in execute_sql
    row_count = super().execute_sql(result_type)
                ^^^^^^^^^^^^^^^^^^^^^^^^^^^^^^^^
  File "/Users/mutafvladimir/Documents/IT/dZENcode/.venv/lib/python3.12/site-packages/django/db/models/sql/compiler.py", line 1609, in execute_sql
    sql, params = self.as_sql()
                  ^^^^^^^^^^^^^
  File "/Users/mutafvladimir/Documents/IT/dZENcode/.venv/lib/python3.12/site-packages/django/db/models/sql/compiler.py", line 2022, in as_sql
    val = field.get_db_prep_save(val, connection=self.connection)
          ^^^^^^^^^^^^^^^^^^^^^^^^^^^^^^^^^^^^^^^^^^^^^^^^^^^^^^^
  File "/Users/mutafvladimir/Documents/IT/dZENcode/.venv/lib/python3.12/site-packages/django/db/models/fields/__init__.py", line 1012, in get_db_prep_save
    return self.get_db_prep_value(value, connection=connection, prepared=False)
           ^^^^^^^^^^^^^^^^^^^^^^^^^^^^^^^^^^^^^^^^^^^^^^^^^^^^^^^^^^^^^^^^^^^^
  File "/Users/mutafvladimir/Documents/IT/dZENcode/.venv/lib/python3.12/site-packages/django/db/models/fields/__init__.py", line 1005, in get_db_prep_value
    value = self.get_prep_value(value)
            ^^^^^^^^^^^^^^^^^^^^^^^^^^
  File "/Users/mutafvladimir/Documents/IT/dZENcode/.venv/lib/python3.12/site-packages/django/db/models/fields/__init__.py", line 1190, in get_prep_value
    return self.to_python(value)
           ^^^^^^^^^^^^^^^^^^^^^
  File "/Users/mutafvladimir/Documents/IT/dZENcode/.venv/lib/python3.12/site-packages/django/db/models/fields/__init__.py", line 1180, in to_python
    raise exceptions.ValidationError(
django.core.exceptions.ValidationError: ['“-1” value must be either True or False.']
[2025-04-28 16:51:41,826] WARNING django.request Method Not Allowed: /api/v1/comments/comments/1/dislike/
[2025-04-28 16:51:48,362] WARNING django.request Method Not Allowed: /api/v1/comments/comments/1/dislike/
[2025-04-28 16:52:24,800] WARNING django.request Method Not Allowed: /api/v1/comments/comments/1/like/
[2025-04-28 16:59:25,061] WARNING django.request Method Not Allowed: /api/v1/comments/comments/1/remove_reaction/
[2025-04-28 16:59:28,298] ERROR django.request Internal Server Error: /api/v1/comments/comments/1/remove_reaction/
Traceback (most recent call last):
  File "/Users/mutafvladimir/Documents/IT/dZENcode/.venv/lib/python3.12/site-packages/django/core/handlers/exception.py", line 55, in inner
    response = get_response(request)
               ^^^^^^^^^^^^^^^^^^^^^
  File "/Users/mutafvladimir/Documents/IT/dZENcode/.venv/lib/python3.12/site-packages/django/core/handlers/base.py", line 197, in _get_response
    response = wrapped_callback(request, *callback_args, **callback_kwargs)
               ^^^^^^^^^^^^^^^^^^^^^^^^^^^^^^^^^^^^^^^^^^^^^^^^^^^^^^^^^^^^
  File "/Users/mutafvladimir/Documents/IT/dZENcode/.venv/lib/python3.12/site-packages/django/views/decorators/csrf.py", line 65, in _view_wrapper
    return view_func(request, *args, **kwargs)
           ^^^^^^^^^^^^^^^^^^^^^^^^^^^^^^^^^^^
  File "/Users/mutafvladimir/Documents/IT/dZENcode/.venv/lib/python3.12/site-packages/rest_framework/viewsets.py", line 125, in view
    return self.dispatch(request, *args, **kwargs)
           ^^^^^^^^^^^^^^^^^^^^^^^^^^^^^^^^^^^^^^^
  File "/Users/mutafvladimir/Documents/IT/dZENcode/.venv/lib/python3.12/site-packages/rest_framework/views.py", line 515, in dispatch
    response = self.handle_exception(exc)
               ^^^^^^^^^^^^^^^^^^^^^^^^^^
  File "/Users/mutafvladimir/Documents/IT/dZENcode/.venv/lib/python3.12/site-packages/rest_framework/views.py", line 475, in handle_exception
    self.raise_uncaught_exception(exc)
  File "/Users/mutafvladimir/Documents/IT/dZENcode/.venv/lib/python3.12/site-packages/rest_framework/views.py", line 486, in raise_uncaught_exception
    raise exc
  File "/Users/mutafvladimir/Documents/IT/dZENcode/.venv/lib/python3.12/site-packages/rest_framework/views.py", line 512, in dispatch
    response = handler(request, *args, **kwargs)
               ^^^^^^^^^^^^^^^^^^^^^^^^^^^^^^^^^
  File "/Users/mutafvladimir/Documents/IT/dZENcode/comments/api/viewsets/comments.py", line 65, in remove_reaction
    reaction = Reaction.objects.get(user=user, comment=comment)
               ^^^^^^^^^^^^^^^^^^^^^^^^^^^^^^^^^^^^^^^^^^^^^^^^
  File "/Users/mutafvladimir/Documents/IT/dZENcode/.venv/lib/python3.12/site-packages/django/db/models/manager.py", line 87, in manager_method
    return getattr(self.get_queryset(), name)(*args, **kwargs)
           ^^^^^^^^^^^^^^^^^^^^^^^^^^^^^^^^^^^^^^^^^^^^^^^^^^^
  File "/Users/mutafvladimir/Documents/IT/dZENcode/.venv/lib/python3.12/site-packages/django/db/models/query.py", line 619, in get
    clone = self._chain() if self.query.combinator else self.filter(*args, **kwargs)
                                                        ^^^^^^^^^^^^^^^^^^^^^^^^^^^^
  File "/Users/mutafvladimir/Documents/IT/dZENcode/.venv/lib/python3.12/site-packages/django/db/models/query.py", line 1481, in filter
    return self._filter_or_exclude(False, args, kwargs)
           ^^^^^^^^^^^^^^^^^^^^^^^^^^^^^^^^^^^^^^^^^^^^
  File "/Users/mutafvladimir/Documents/IT/dZENcode/.venv/lib/python3.12/site-packages/django/db/models/query.py", line 1499, in _filter_or_exclude
    clone._filter_or_exclude_inplace(negate, args, kwargs)
  File "/Users/mutafvladimir/Documents/IT/dZENcode/.venv/lib/python3.12/site-packages/django/db/models/query.py", line 1506, in _filter_or_exclude_inplace
    self._query.add_q(Q(*args, **kwargs))
  File "/Users/mutafvladimir/Documents/IT/dZENcode/.venv/lib/python3.12/site-packages/django/db/models/sql/query.py", line 1643, in add_q
    clause, _ = self._add_q(q_object, can_reuse)
                ^^^^^^^^^^^^^^^^^^^^^^^^^^^^^^^^
  File "/Users/mutafvladimir/Documents/IT/dZENcode/.venv/lib/python3.12/site-packages/django/db/models/sql/query.py", line 1675, in _add_q
    child_clause, needed_inner = self.build_filter(
                                 ^^^^^^^^^^^^^^^^^^
  File "/Users/mutafvladimir/Documents/IT/dZENcode/.venv/lib/python3.12/site-packages/django/db/models/sql/query.py", line 1523, in build_filter
    lookups, parts, reffed_expression = self.solve_lookup_type(arg, summarize)
                                        ^^^^^^^^^^^^^^^^^^^^^^^^^^^^^^^^^^^^^^
  File "/Users/mutafvladimir/Documents/IT/dZENcode/.venv/lib/python3.12/site-packages/django/db/models/sql/query.py", line 1330, in solve_lookup_type
    _, field, _, lookup_parts = self.names_to_path(lookup_splitted, self.get_meta())
                                ^^^^^^^^^^^^^^^^^^^^^^^^^^^^^^^^^^^^^^^^^^^^^^^^^^^^
  File "/Users/mutafvladimir/Documents/IT/dZENcode/.venv/lib/python3.12/site-packages/django/db/models/sql/query.py", line 1802, in names_to_path
    raise FieldError(
django.core.exceptions.FieldError: Cannot resolve keyword 'comment' into field. Choices are: comments, comments_id, created_at, id, reaction, updated_at, user, user_id
[2025-04-28 16:59:54,267] WARNING django.request Method Not Allowed: /api/v1/comments/comments/1/remove_reaction/
[2025-04-28 16:59:56,359] ERROR django.request Internal Server Error: /api/v1/comments/comments/1/remove_reaction/
Traceback (most recent call last):
  File "/Users/mutafvladimir/Documents/IT/dZENcode/.venv/lib/python3.12/site-packages/django/core/handlers/exception.py", line 55, in inner
    response = get_response(request)
               ^^^^^^^^^^^^^^^^^^^^^
  File "/Users/mutafvladimir/Documents/IT/dZENcode/.venv/lib/python3.12/site-packages/django/core/handlers/base.py", line 197, in _get_response
    response = wrapped_callback(request, *callback_args, **callback_kwargs)
               ^^^^^^^^^^^^^^^^^^^^^^^^^^^^^^^^^^^^^^^^^^^^^^^^^^^^^^^^^^^^
  File "/Users/mutafvladimir/Documents/IT/dZENcode/.venv/lib/python3.12/site-packages/django/views/decorators/csrf.py", line 65, in _view_wrapper
    return view_func(request, *args, **kwargs)
           ^^^^^^^^^^^^^^^^^^^^^^^^^^^^^^^^^^^
  File "/Users/mutafvladimir/Documents/IT/dZENcode/.venv/lib/python3.12/site-packages/rest_framework/viewsets.py", line 125, in view
    return self.dispatch(request, *args, **kwargs)
           ^^^^^^^^^^^^^^^^^^^^^^^^^^^^^^^^^^^^^^^
  File "/Users/mutafvladimir/Documents/IT/dZENcode/.venv/lib/python3.12/site-packages/rest_framework/views.py", line 515, in dispatch
    response = self.handle_exception(exc)
               ^^^^^^^^^^^^^^^^^^^^^^^^^^
  File "/Users/mutafvladimir/Documents/IT/dZENcode/.venv/lib/python3.12/site-packages/rest_framework/views.py", line 475, in handle_exception
    self.raise_uncaught_exception(exc)
  File "/Users/mutafvladimir/Documents/IT/dZENcode/.venv/lib/python3.12/site-packages/rest_framework/views.py", line 486, in raise_uncaught_exception
    raise exc
  File "/Users/mutafvladimir/Documents/IT/dZENcode/.venv/lib/python3.12/site-packages/rest_framework/views.py", line 512, in dispatch
    response = handler(request, *args, **kwargs)
               ^^^^^^^^^^^^^^^^^^^^^^^^^^^^^^^^^
  File "/Users/mutafvladimir/Documents/IT/dZENcode/comments/api/viewsets/comments.py", line 65, in remove_reaction
    reaction = Reaction.objects.get(user=user, comment=comment)
               ^^^^^^^^^^^^^^^^^^^^^^^^^^^^^^^^^^^^^^^^^^^^^^^^
  File "/Users/mutafvladimir/Documents/IT/dZENcode/.venv/lib/python3.12/site-packages/django/db/models/manager.py", line 87, in manager_method
    return getattr(self.get_queryset(), name)(*args, **kwargs)
           ^^^^^^^^^^^^^^^^^^^^^^^^^^^^^^^^^^^^^^^^^^^^^^^^^^^
  File "/Users/mutafvladimir/Documents/IT/dZENcode/.venv/lib/python3.12/site-packages/django/db/models/query.py", line 619, in get
    clone = self._chain() if self.query.combinator else self.filter(*args, **kwargs)
                                                        ^^^^^^^^^^^^^^^^^^^^^^^^^^^^
  File "/Users/mutafvladimir/Documents/IT/dZENcode/.venv/lib/python3.12/site-packages/django/db/models/query.py", line 1481, in filter
    return self._filter_or_exclude(False, args, kwargs)
           ^^^^^^^^^^^^^^^^^^^^^^^^^^^^^^^^^^^^^^^^^^^^
  File "/Users/mutafvladimir/Documents/IT/dZENcode/.venv/lib/python3.12/site-packages/django/db/models/query.py", line 1499, in _filter_or_exclude
    clone._filter_or_exclude_inplace(negate, args, kwargs)
  File "/Users/mutafvladimir/Documents/IT/dZENcode/.venv/lib/python3.12/site-packages/django/db/models/query.py", line 1506, in _filter_or_exclude_inplace
    self._query.add_q(Q(*args, **kwargs))
  File "/Users/mutafvladimir/Documents/IT/dZENcode/.venv/lib/python3.12/site-packages/django/db/models/sql/query.py", line 1643, in add_q
    clause, _ = self._add_q(q_object, can_reuse)
                ^^^^^^^^^^^^^^^^^^^^^^^^^^^^^^^^
  File "/Users/mutafvladimir/Documents/IT/dZENcode/.venv/lib/python3.12/site-packages/django/db/models/sql/query.py", line 1675, in _add_q
    child_clause, needed_inner = self.build_filter(
                                 ^^^^^^^^^^^^^^^^^^
  File "/Users/mutafvladimir/Documents/IT/dZENcode/.venv/lib/python3.12/site-packages/django/db/models/sql/query.py", line 1523, in build_filter
    lookups, parts, reffed_expression = self.solve_lookup_type(arg, summarize)
                                        ^^^^^^^^^^^^^^^^^^^^^^^^^^^^^^^^^^^^^^
  File "/Users/mutafvladimir/Documents/IT/dZENcode/.venv/lib/python3.12/site-packages/django/db/models/sql/query.py", line 1330, in solve_lookup_type
    _, field, _, lookup_parts = self.names_to_path(lookup_splitted, self.get_meta())
                                ^^^^^^^^^^^^^^^^^^^^^^^^^^^^^^^^^^^^^^^^^^^^^^^^^^^^
  File "/Users/mutafvladimir/Documents/IT/dZENcode/.venv/lib/python3.12/site-packages/django/db/models/sql/query.py", line 1802, in names_to_path
    raise FieldError(
django.core.exceptions.FieldError: Cannot resolve keyword 'comment' into field. Choices are: comments, comments_id, created_at, id, reaction, updated_at, user, user_id
[2025-04-28 17:00:11,007] WARNING django.request Method Not Allowed: /api/v1/comments/comments/1/remove_reaction/
[2025-04-28 17:00:27,424] WARNING django.request Method Not Allowed: /api/v1/comments/comments/1/dislike/
[2025-04-28 17:02:05,904] WARNING django.request Method Not Allowed: /api/v1/comments/comments/1/remove_reaction/
[2025-04-28 17:02:08,352] ERROR django.request Internal Server Error: /api/v1/comments/comments/1/remove_reaction/
Traceback (most recent call last):
  File "/Users/mutafvladimir/Documents/IT/dZENcode/.venv/lib/python3.12/site-packages/django/core/handlers/exception.py", line 55, in inner
    response = get_response(request)
               ^^^^^^^^^^^^^^^^^^^^^
  File "/Users/mutafvladimir/Documents/IT/dZENcode/.venv/lib/python3.12/site-packages/django/core/handlers/base.py", line 197, in _get_response
    response = wrapped_callback(request, *callback_args, **callback_kwargs)
               ^^^^^^^^^^^^^^^^^^^^^^^^^^^^^^^^^^^^^^^^^^^^^^^^^^^^^^^^^^^^
  File "/Users/mutafvladimir/Documents/IT/dZENcode/.venv/lib/python3.12/site-packages/django/views/decorators/csrf.py", line 65, in _view_wrapper
    return view_func(request, *args, **kwargs)
           ^^^^^^^^^^^^^^^^^^^^^^^^^^^^^^^^^^^
  File "/Users/mutafvladimir/Documents/IT/dZENcode/.venv/lib/python3.12/site-packages/rest_framework/viewsets.py", line 125, in view
    return self.dispatch(request, *args, **kwargs)
           ^^^^^^^^^^^^^^^^^^^^^^^^^^^^^^^^^^^^^^^
  File "/Users/mutafvladimir/Documents/IT/dZENcode/.venv/lib/python3.12/site-packages/rest_framework/views.py", line 515, in dispatch
    response = self.handle_exception(exc)
               ^^^^^^^^^^^^^^^^^^^^^^^^^^
  File "/Users/mutafvladimir/Documents/IT/dZENcode/.venv/lib/python3.12/site-packages/rest_framework/views.py", line 475, in handle_exception
    self.raise_uncaught_exception(exc)
  File "/Users/mutafvladimir/Documents/IT/dZENcode/.venv/lib/python3.12/site-packages/rest_framework/views.py", line 486, in raise_uncaught_exception
    raise exc
  File "/Users/mutafvladimir/Documents/IT/dZENcode/.venv/lib/python3.12/site-packages/rest_framework/views.py", line 512, in dispatch
    response = handler(request, *args, **kwargs)
               ^^^^^^^^^^^^^^^^^^^^^^^^^^^^^^^^^
  File "/Users/mutafvladimir/Documents/IT/dZENcode/comments/api/viewsets/comments.py", line 64, in remove_reaction
    reaction = Reaction.objects.filter(user=user, comment=comment)
               ^^^^^^^^^^^^^^^^^^^^^^^^^^^^^^^^^^^^^^^^^^^^^^^^^^^
  File "/Users/mutafvladimir/Documents/IT/dZENcode/.venv/lib/python3.12/site-packages/django/db/models/manager.py", line 87, in manager_method
    return getattr(self.get_queryset(), name)(*args, **kwargs)
           ^^^^^^^^^^^^^^^^^^^^^^^^^^^^^^^^^^^^^^^^^^^^^^^^^^^
  File "/Users/mutafvladimir/Documents/IT/dZENcode/.venv/lib/python3.12/site-packages/django/db/models/query.py", line 1481, in filter
    return self._filter_or_exclude(False, args, kwargs)
           ^^^^^^^^^^^^^^^^^^^^^^^^^^^^^^^^^^^^^^^^^^^^
  File "/Users/mutafvladimir/Documents/IT/dZENcode/.venv/lib/python3.12/site-packages/django/db/models/query.py", line 1499, in _filter_or_exclude
    clone._filter_or_exclude_inplace(negate, args, kwargs)
  File "/Users/mutafvladimir/Documents/IT/dZENcode/.venv/lib/python3.12/site-packages/django/db/models/query.py", line 1506, in _filter_or_exclude_inplace
    self._query.add_q(Q(*args, **kwargs))
  File "/Users/mutafvladimir/Documents/IT/dZENcode/.venv/lib/python3.12/site-packages/django/db/models/sql/query.py", line 1643, in add_q
    clause, _ = self._add_q(q_object, can_reuse)
                ^^^^^^^^^^^^^^^^^^^^^^^^^^^^^^^^
  File "/Users/mutafvladimir/Documents/IT/dZENcode/.venv/lib/python3.12/site-packages/django/db/models/sql/query.py", line 1675, in _add_q
    child_clause, needed_inner = self.build_filter(
                                 ^^^^^^^^^^^^^^^^^^
  File "/Users/mutafvladimir/Documents/IT/dZENcode/.venv/lib/python3.12/site-packages/django/db/models/sql/query.py", line 1523, in build_filter
    lookups, parts, reffed_expression = self.solve_lookup_type(arg, summarize)
                                        ^^^^^^^^^^^^^^^^^^^^^^^^^^^^^^^^^^^^^^
  File "/Users/mutafvladimir/Documents/IT/dZENcode/.venv/lib/python3.12/site-packages/django/db/models/sql/query.py", line 1330, in solve_lookup_type
    _, field, _, lookup_parts = self.names_to_path(lookup_splitted, self.get_meta())
                                ^^^^^^^^^^^^^^^^^^^^^^^^^^^^^^^^^^^^^^^^^^^^^^^^^^^^
  File "/Users/mutafvladimir/Documents/IT/dZENcode/.venv/lib/python3.12/site-packages/django/db/models/sql/query.py", line 1802, in names_to_path
    raise FieldError(
django.core.exceptions.FieldError: Cannot resolve keyword 'comment' into field. Choices are: comments, comments_id, created_at, id, reaction, updated_at, user, user_id
[2025-04-28 17:03:39,112] WARNING django.request Method Not Allowed: /api/v1/comments/comments/1/remove_reaction/
[2025-04-28 17:06:14,434] WARNING django.request Method Not Allowed: /api/v1/comments/comments/1/neutral/
[2025-04-28 17:06:29,169] WARNING django.request Method Not Allowed: /api/v1/comments/comments/1/neutral/
[2025-04-28 17:06:31,108] ERROR django.request Internal Server Error: /api/v1/comments/comments/1/neutral/
Traceback (most recent call last):
  File "/Users/mutafvladimir/Documents/IT/dZENcode/.venv/lib/python3.12/site-packages/django/core/handlers/exception.py", line 55, in inner
    response = get_response(request)
               ^^^^^^^^^^^^^^^^^^^^^
  File "/Users/mutafvladimir/Documents/IT/dZENcode/.venv/lib/python3.12/site-packages/django/core/handlers/base.py", line 197, in _get_response
    response = wrapped_callback(request, *callback_args, **callback_kwargs)
               ^^^^^^^^^^^^^^^^^^^^^^^^^^^^^^^^^^^^^^^^^^^^^^^^^^^^^^^^^^^^
  File "/Users/mutafvladimir/Documents/IT/dZENcode/.venv/lib/python3.12/site-packages/django/views/decorators/csrf.py", line 65, in _view_wrapper
    return view_func(request, *args, **kwargs)
           ^^^^^^^^^^^^^^^^^^^^^^^^^^^^^^^^^^^
  File "/Users/mutafvladimir/Documents/IT/dZENcode/.venv/lib/python3.12/site-packages/rest_framework/viewsets.py", line 125, in view
    return self.dispatch(request, *args, **kwargs)
           ^^^^^^^^^^^^^^^^^^^^^^^^^^^^^^^^^^^^^^^
  File "/Users/mutafvladimir/Documents/IT/dZENcode/.venv/lib/python3.12/site-packages/rest_framework/views.py", line 515, in dispatch
    response = self.handle_exception(exc)
               ^^^^^^^^^^^^^^^^^^^^^^^^^^
  File "/Users/mutafvladimir/Documents/IT/dZENcode/.venv/lib/python3.12/site-packages/rest_framework/views.py", line 475, in handle_exception
    self.raise_uncaught_exception(exc)
  File "/Users/mutafvladimir/Documents/IT/dZENcode/.venv/lib/python3.12/site-packages/rest_framework/views.py", line 486, in raise_uncaught_exception
    raise exc
  File "/Users/mutafvladimir/Documents/IT/dZENcode/.venv/lib/python3.12/site-packages/rest_framework/views.py", line 512, in dispatch
    response = handler(request, *args, **kwargs)
               ^^^^^^^^^^^^^^^^^^^^^^^^^^^^^^^^^
  File "/Users/mutafvladimir/Documents/IT/dZENcode/comments/api/viewsets/comments.py", line 61, in neutral
    return self._set_reaction(request.user, Reaction.ReactionTypes.NEUTRAL)
           ^^^^^^^^^^^^^^^^^^^^^^^^^^^^^^^^^^^^^^^^^^^^^^^^^^^^^^^^^^^^^^^^
  File "/Users/mutafvladimir/Documents/IT/dZENcode/comments/api/viewsets/comments.py", line 47, in _set_reaction
    self._update_rating(comment)
  File "/Users/mutafvladimir/Documents/IT/dZENcode/comments/api/viewsets/comments.py", line 30, in _update_rating
    reactions = Reaction.objects.filter(comments=comment)
                ^^^^^^^^^^^^^^^^^^^^^^^^^^^^^^^^^^^^^^^^^
  File "/Users/mutafvladimir/Documents/IT/dZENcode/.venv/lib/python3.12/site-packages/django/db/models/manager.py", line 87, in manager_method
    return getattr(self.get_queryset(), name)(*args, **kwargs)
           ^^^^^^^^^^^^^^^^^^^^^^^^^^^^^^^^^^^^^^^^^^^^^^^^^^^
  File "/Users/mutafvladimir/Documents/IT/dZENcode/.venv/lib/python3.12/site-packages/django/db/models/query.py", line 1481, in filter
    return self._filter_or_exclude(False, args, kwargs)
           ^^^^^^^^^^^^^^^^^^^^^^^^^^^^^^^^^^^^^^^^^^^^
  File "/Users/mutafvladimir/Documents/IT/dZENcode/.venv/lib/python3.12/site-packages/django/db/models/query.py", line 1499, in _filter_or_exclude
    clone._filter_or_exclude_inplace(negate, args, kwargs)
  File "/Users/mutafvladimir/Documents/IT/dZENcode/.venv/lib/python3.12/site-packages/django/db/models/query.py", line 1506, in _filter_or_exclude_inplace
    self._query.add_q(Q(*args, **kwargs))
  File "/Users/mutafvladimir/Documents/IT/dZENcode/.venv/lib/python3.12/site-packages/django/db/models/sql/query.py", line 1643, in add_q
    clause, _ = self._add_q(q_object, can_reuse)
                ^^^^^^^^^^^^^^^^^^^^^^^^^^^^^^^^
  File "/Users/mutafvladimir/Documents/IT/dZENcode/.venv/lib/python3.12/site-packages/django/db/models/sql/query.py", line 1675, in _add_q
    child_clause, needed_inner = self.build_filter(
                                 ^^^^^^^^^^^^^^^^^^
  File "/Users/mutafvladimir/Documents/IT/dZENcode/.venv/lib/python3.12/site-packages/django/db/models/sql/query.py", line 1523, in build_filter
    lookups, parts, reffed_expression = self.solve_lookup_type(arg, summarize)
                                        ^^^^^^^^^^^^^^^^^^^^^^^^^^^^^^^^^^^^^^
  File "/Users/mutafvladimir/Documents/IT/dZENcode/.venv/lib/python3.12/site-packages/django/db/models/sql/query.py", line 1330, in solve_lookup_type
    _, field, _, lookup_parts = self.names_to_path(lookup_splitted, self.get_meta())
                                ^^^^^^^^^^^^^^^^^^^^^^^^^^^^^^^^^^^^^^^^^^^^^^^^^^^^
  File "/Users/mutafvladimir/Documents/IT/dZENcode/.venv/lib/python3.12/site-packages/django/db/models/sql/query.py", line 1802, in names_to_path
    raise FieldError(
django.core.exceptions.FieldError: Cannot resolve keyword 'comments' into field. Choices are: comment, comment_id, created_at, id, reaction, updated_at, user, user_id
[2025-04-28 17:07:04,856] WARNING django.request Method Not Allowed: /api/v1/comments/comments/1/neutral/
[2025-04-28 17:07:08,225] WARNING django.request Method Not Allowed: /api/v1/comments/comments/1/neutral/
[2025-04-28 17:38:22,894] WARNING django.request Not Found: /
[2025-04-28 17:38:23,419] WARNING django.request Not Found: /apple-touch-icon-precomposed.png
[2025-04-28 17:38:23,432] WARNING django.request Not Found: /apple-touch-icon.png
[2025-04-28 17:38:23,437] WARNING django.request Not Found: /favicon.ico
[2025-04-28 18:45:18,987] WARNING django.request Not Found: /
[2025-04-28 18:45:19,079] WARNING django.request Not Found: /apple-touch-icon-precomposed.png
[2025-04-28 18:45:19,085] WARNING django.request Not Found: /favicon.ico
[2025-04-28 18:45:19,088] WARNING django.request Not Found: /apple-touch-icon.png
[2025-04-28 18:45:19,967] WARNING django.request Not Found: /api/v1/members/members/5/settings/
[2025-04-28 18:57:21,544] WARNING django.request Not Found: /
[2025-04-28 18:57:21,727] WARNING django.request Not Found: /apple-touch-icon-precomposed.png
[2025-04-28 18:57:21,734] WARNING django.request Not Found: /apple-touch-icon.png
[2025-04-28 18:57:21,737] WARNING django.request Not Found: /favicon.ico
[2025-04-28 18:57:26,540] WARNING django.request Not Found: /
[2025-04-28 18:57:26,573] WARNING django.request Not Found: /apple-touch-icon-precomposed.png
[2025-04-28 18:57:26,579] WARNING django.request Not Found: /apple-touch-icon.png
[2025-04-28 18:57:26,583] WARNING django.request Not Found: /favicon.ico
[2025-04-28 18:57:55,582] WARNING django.request Not Found: /ws/comments/
[2025-04-28 18:59:55,903] WARNING django.request Not Found: /ws/comments/
[2025-04-28 19:00:06,712] WARNING django.request Not Found: /ws/comments/
[2025-04-28 19:05:24,257] WARNING django.request Not Found: /
[2025-04-28 19:05:24,337] WARNING django.request Not Found: /apple-touch-icon-precomposed.png
[2025-04-28 19:05:24,342] WARNING django.request Not Found: /favicon.ico
[2025-04-28 19:05:24,346] WARNING django.request Not Found: /apple-touch-icon.png
[2025-04-28 19:11:34,605] WARNING django.request Not Found: /apple-touch-icon-precomposed.png
[2025-04-28 19:11:34,611] WARNING django.request Not Found: /apple-touch-icon.png
[2025-04-28 19:11:34,615] WARNING django.request Not Found: /favicon.ico
[2025-04-28 19:12:18,975] WARNING django.request Not Found: /apple-touch-icon-precomposed.png
[2025-04-28 19:12:18,987] WARNING django.request Not Found: /apple-touch-icon.png
[2025-04-28 19:12:18,996] WARNING django.request Not Found: /favicon.ico
[2025-04-28 19:14:01,600] WARNING django.request Not Found: /ws/comments/
[2025-04-28 19:14:01,616] WARNING django.request Not Found: /apple-touch-icon-precomposed.png
[2025-04-28 19:14:01,622] WARNING django.request Not Found: /apple-touch-icon.png
[2025-04-28 19:14:01,627] WARNING django.request Not Found: /favicon.ico
[2025-04-28 19:23:50,619] WARNING django.request Not Found: /ws/comments/
[2025-04-28 19:23:50,652] WARNING django.request Not Found: /apple-touch-icon-precomposed.png
[2025-04-28 19:23:50,660] WARNING django.request Not Found: /favicon.ico
[2025-04-28 19:23:50,665] WARNING django.request Not Found: /apple-touch-icon.png
[2025-04-28 19:25:34,777] WARNING django.request Not Found: /ws/comments/
[2025-04-28 19:25:34,819] WARNING django.request Not Found: /apple-touch-icon-precomposed.png
[2025-04-28 19:25:34,824] WARNING django.request Not Found: /apple-touch-icon.png
[2025-04-28 19:25:34,829] WARNING django.request Not Found: /favicon.ico
[2025-04-28 19:25:37,755] WARNING django.request Not Found: /ws/comments/
[2025-04-28 19:25:37,791] WARNING django.request Not Found: /apple-touch-icon-precomposed.png
[2025-04-28 19:25:37,797] WARNING django.request Not Found: /apple-touch-icon.png
[2025-04-28 19:25:37,800] WARNING django.request Not Found: /favicon.ico
[2025-04-28 19:26:59,831] WARNING django.request Not Found: /ws/comments/
[2025-04-28 19:26:59,855] WARNING django.request Not Found: /apple-touch-icon-precomposed.png
[2025-04-28 19:26:59,862] WARNING django.request Not Found: /apple-touch-icon.png
[2025-04-28 19:26:59,868] WARNING django.request Not Found: /favicon.ico
[2025-04-28 19:33:54,834] WARNING django.request Not Found: /ws/comments/
[2025-04-28 19:33:54,902] WARNING django.request Not Found: /apple-touch-icon-precomposed.png
[2025-04-28 19:33:54,909] WARNING django.request Not Found: /favicon.ico
[2025-04-28 19:33:54,913] WARNING django.request Not Found: /apple-touch-icon.png
[2025-04-28 19:34:16,825] WARNING django.request Not Found: /ws/comments/
[2025-04-28 19:34:37,666] WARNING django.request Not Found: /ws/comments/
[2025-04-28 19:34:37,702] WARNING django.request Not Found: /apple-touch-icon-precomposed.png
[2025-04-28 19:34:37,709] WARNING django.request Not Found: /apple-touch-icon.png
[2025-04-28 19:34:37,714] WARNING django.request Not Found: /favicon.ico
[2025-04-28 19:39:01,723] WARNING django.request Not Found: /ws/comments/
[2025-04-28 19:39:01,801] WARNING django.request Not Found: /apple-touch-icon-precomposed.png
[2025-04-28 19:39:01,806] WARNING django.request Not Found: /favicon.ico
[2025-04-28 19:39:01,810] WARNING django.request Not Found: /apple-touch-icon.png
[2025-04-28 19:39:09,950] WARNING django.request Not Found: /ws/comments/
[2025-04-28 19:39:09,978] WARNING django.request Not Found: /apple-touch-icon-precomposed.png
[2025-04-28 19:39:09,981] WARNING django.request Not Found: /favicon.ico
[2025-04-28 19:39:09,986] WARNING django.request Not Found: /apple-touch-icon.png
[2025-04-29 06:08:40,953] WARNING django.request Not Found: /ws/socket-server/
[2025-04-29 06:08:40,998] WARNING django.request Not Found: /apple-touch-icon-precomposed.png
[2025-04-29 06:08:41,004] WARNING django.request Not Found: /apple-touch-icon.png
[2025-04-29 06:08:41,008] WARNING django.request Not Found: /favicon.ico
[2025-04-29 06:08:48,893] WARNING django.request Not Found: /ws/socket-server/
[2025-04-29 06:08:48,920] WARNING django.request Not Found: /apple-touch-icon-precomposed.png
[2025-04-29 06:08:48,927] WARNING django.request Not Found: /favicon.ico
[2025-04-29 06:08:48,933] WARNING django.request Not Found: /apple-touch-icon.png
[2025-04-29 06:10:36,718] WARNING django.request Not Found: /ws/socket-server/
[2025-04-29 06:10:36,755] WARNING django.request Not Found: /apple-touch-icon-precomposed.png
[2025-04-29 06:10:36,763] WARNING django.request Not Found: /apple-touch-icon.png
[2025-04-29 06:10:36,773] WARNING django.request Not Found: /favicon.ico
[2025-04-29 06:12:36,973] WARNING django.request Not Found: /ws/socket-server/
[2025-04-29 06:12:36,986] WARNING django.request Not Found: /apple-touch-icon-precomposed.png
[2025-04-29 06:12:36,994] WARNING django.request Not Found: /apple-touch-icon.png
[2025-04-29 06:12:37,001] WARNING django.request Not Found: /favicon.ico
[2025-04-29 06:13:00,717] WARNING django.request Not Found: /ws/socket-server/
[2025-04-29 06:13:00,751] WARNING django.request Not Found: /apple-touch-icon-precomposed.png
[2025-04-29 06:13:00,757] WARNING django.request Not Found: /apple-touch-icon.png
[2025-04-29 06:13:00,764] WARNING django.request Not Found: /favicon.ico
[2025-04-29 06:21:29,305] WARNING django.request Not Found: /ws/socket-server/
[2025-04-29 06:21:29,354] WARNING django.request Not Found: /apple-touch-icon-precomposed.png
[2025-04-29 06:21:29,361] WARNING django.request Not Found: /favicon.ico
[2025-04-29 06:21:29,365] WARNING django.request Not Found: /apple-touch-icon.png
[2025-04-29 06:24:51,245] WARNING django.request Not Found: /ws/socket-server/
[2025-04-29 06:24:51,266] WARNING django.request Not Found: /apple-touch-icon-precomposed.png
[2025-04-29 06:24:51,270] WARNING django.request Not Found: /apple-touch-icon.png
[2025-04-29 06:24:51,276] WARNING django.request Not Found: /favicon.ico
[2025-04-29 06:25:00,452] WARNING django.request Not Found: /ws/socket-server/
[2025-04-29 06:25:00,470] WARNING django.request Not Found: /apple-touch-icon-precomposed.png
[2025-04-29 06:25:00,477] WARNING django.request Not Found: /apple-touch-icon.png
[2025-04-29 06:25:00,489] WARNING django.request Not Found: /favicon.ico
[2025-04-29 06:32:19,751] WARNING django.request Not Found: /ws/socket-server/
[2025-04-29 06:32:19,795] WARNING django.request Not Found: /apple-touch-icon-precomposed.png
[2025-04-29 06:32:19,800] WARNING django.request Not Found: /apple-touch-icon.png
[2025-04-29 06:32:19,806] WARNING django.request Not Found: /favicon.ico
[2025-04-29 06:33:37,067] WARNING django.request Not Found: /apple-touch-icon.png
[2025-04-29 06:33:37,075] WARNING django.request Not Found: /apple-touch-icon-precomposed.png
[2025-04-29 06:33:37,081] WARNING django.request Not Found: /favicon.ico
[2025-04-29 06:33:37,086] WARNING django.request Not Found: /ws/socket-server/
[2025-04-29 06:44:20,929] WARNING django.request Not Found: /ws/socket-server/
[2025-04-29 06:44:20,989] WARNING django.request Not Found: /apple-touch-icon-precomposed.png
[2025-04-29 06:44:20,995] WARNING django.request Not Found: /apple-touch-icon.png
[2025-04-29 06:44:20,999] WARNING django.request Not Found: /favicon.ico
[2025-04-29 07:18:55,280] WARNING django.request Not Found: /ws/socket-server/
[2025-04-29 07:18:55,370] WARNING django.request Not Found: /apple-touch-icon-precomposed.png
[2025-04-29 07:18:55,374] WARNING django.request Not Found: /favicon.ico
[2025-04-29 07:18:55,374] WARNING django.request Not Found: /apple-touch-icon.png
[2025-04-29 07:28:03,624] WARNING django.request Not Found: /api/v1
[2025-04-29 07:28:11,627] WARNING django.request Not Found: /apple-touch-icon.png
[2025-04-29 07:28:11,627] WARNING django.request Not Found: /favicon.ico
[2025-04-29 07:28:11,628] WARNING django.request Not Found: /apple-touch-icon-precomposed.png
[2025-04-29 07:58:46,386] WARNING django.request Method Not Allowed: /api/v1/comments/comments/1/like/
[2025-04-29 10:04:47,186] WARNING django.request Not Found: /api/v1/commitment/assessment/
[2025-04-29 10:04:47,263] WARNING django.request Not Found: /favicon.ico
[2025-04-29 10:04:47,264] WARNING django.request Not Found: /apple-touch-icon-precomposed.png
[2025-04-29 10:04:47,547] WARNING django.request Not Found: /apple-touch-icon.png
[2025-04-29 10:04:48,331] ERROR django.request Internal Server Error: /
Traceback (most recent call last):
  File "/Users/mutafvladimir/Documents/IT/dZENcode/.venv/lib/python3.12/site-packages/asgiref/sync.py", line 518, in thread_handler
    raise exc_info[1]
  File "/Users/mutafvladimir/Documents/IT/dZENcode/.venv/lib/python3.12/site-packages/django/core/handlers/exception.py", line 42, in inner
    response = await get_response(request)
               ^^^^^^^^^^^^^^^^^^^^^^^^^^^
  File "/Users/mutafvladimir/Documents/IT/dZENcode/.venv/lib/python3.12/site-packages/asgiref/sync.py", line 518, in thread_handler
    raise exc_info[1]
  File "/Users/mutafvladimir/Documents/IT/dZENcode/.venv/lib/python3.12/site-packages/django/core/handlers/base.py", line 253, in _get_response_async
    response = await wrapped_callback(
               ^^^^^^^^^^^^^^^^^^^^^^^
  File "/Users/mutafvladimir/Documents/IT/dZENcode/.venv/lib/python3.12/site-packages/asgiref/sync.py", line 468, in __call__
    ret = await asyncio.shield(exec_coro)
          ^^^^^^^^^^^^^^^^^^^^^^^^^^^^^^^
  File "/Library/Frameworks/Python.framework/Versions/3.12/lib/python3.12/concurrent/futures/thread.py", line 59, in run
    result = self.fn(*self.args, **self.kwargs)
             ^^^^^^^^^^^^^^^^^^^^^^^^^^^^^^^^^^
  File "/Users/mutafvladimir/Documents/IT/dZENcode/.venv/lib/python3.12/site-packages/asgiref/sync.py", line 522, in thread_handler
    return func(*args, **kwargs)
           ^^^^^^^^^^^^^^^^^^^^^
  File "/Users/mutafvladimir/Documents/IT/dZENcode/front/views.py", line 4, in comments
    return render(request, 'comments.html')
           ^^^^^^^^^^^^^^^^^^^^^^^^^^^^^^^^
  File "/Users/mutafvladimir/Documents/IT/dZENcode/.venv/lib/python3.12/site-packages/django/shortcuts.py", line 25, in render
    content = loader.render_to_string(template_name, context, request, using=using)
              ^^^^^^^^^^^^^^^^^^^^^^^^^^^^^^^^^^^^^^^^^^^^^^^^^^^^^^^^^^^^^^^^^^^^^
  File "/Users/mutafvladimir/Documents/IT/dZENcode/.venv/lib/python3.12/site-packages/django/template/loader.py", line 61, in render_to_string
    template = get_template(template_name, using=using)
               ^^^^^^^^^^^^^^^^^^^^^^^^^^^^^^^^^^^^^^^^
  File "/Users/mutafvladimir/Documents/IT/dZENcode/.venv/lib/python3.12/site-packages/django/template/loader.py", line 19, in get_template
    raise TemplateDoesNotExist(template_name, chain=chain)
django.template.exceptions.TemplateDoesNotExist: comments.html
[2025-04-29 10:59:13,326] WARNING django.request Not Found: /apple-touch-icon.png
[2025-04-29 10:59:13,326] WARNING django.request Not Found: /favicon.ico
[2025-04-29 10:59:13,326] WARNING django.request Not Found: /apple-touch-icon-precomposed.png
[2025-04-29 11:02:14,189] WARNING django.request Not Found: /static/rest_framework/js/ajax-form.js
[2025-04-29 11:02:14,227] WARNING django.request Not Found: /static/rest_framework/js/default.js
[2025-04-29 11:02:14,232] WARNING django.request Not Found: /static/rest_framework/css/bootstrap.min.css
[2025-04-29 11:02:14,235] WARNING django.request Not Found: /static/rest_framework/css/bootstrap-tweaks.css
[2025-04-29 11:02:14,237] WARNING django.request Not Found: /static/rest_framework/js/load-ajax-form.js
[2025-04-29 11:02:14,243] WARNING django.request Not Found: /static/rest_framework/js/jquery-3.7.1.min.js
[2025-04-29 11:02:14,250] WARNING django.request Not Found: /static/rest_framework/js/csrf.js
[2025-04-29 11:02:14,276] WARNING django.request Not Found: /static/rest_framework/css/prettify.css
[2025-04-29 11:02:14,277] WARNING django.request Not Found: /static/rest_framework/css/default.css
[2025-04-29 11:02:14,279] WARNING django.request Not Found: /static/rest_framework/js/prettify-min.js
[2025-04-29 11:02:14,279] WARNING django.request Not Found: /static/rest_framework/js/bootstrap.min.js
[2025-04-29 11:03:11,605] WARNING django.request Not Found: /static/rest_framework/js/ajax-form.js
[2025-04-29 11:03:11,636] WARNING django.request Not Found: /static/rest_framework/js/load-ajax-form.js
[2025-04-29 11:03:11,637] WARNING django.request Not Found: /static/rest_framework/js/jquery-3.7.1.min.js
[2025-04-29 11:03:11,637] WARNING django.request Not Found: /static/rest_framework/js/csrf.js
[2025-04-29 11:03:11,637] WARNING django.request Not Found: /static/rest_framework/css/default.css
[2025-04-29 11:03:11,638] WARNING django.request Not Found: /static/rest_framework/js/default.js
[2025-04-29 11:03:11,657] WARNING django.request Not Found: /static/rest_framework/css/bootstrap.min.css
[2025-04-29 11:03:11,678] WARNING django.request Not Found: /static/rest_framework/css/prettify.css
[2025-04-29 11:03:11,679] WARNING django.request Not Found: /static/rest_framework/js/bootstrap.min.js
[2025-04-29 11:03:11,682] WARNING django.request Not Found: /static/rest_framework/css/bootstrap-tweaks.css
[2025-04-29 11:03:11,683] WARNING django.request Not Found: /static/rest_framework/js/prettify-min.js
[2025-04-29 11:04:01,823] WARNING django.request Not Found: /apple-touch-icon-precomposed.png
[2025-04-29 11:04:01,825] WARNING django.request Not Found: /apple-touch-icon.png
[2025-04-29 11:04:01,826] WARNING django.request Not Found: /favicon.ico
[2025-04-29 11:06:05,539] WARNING django.request Not Found: /apple-touch-icon.png
[2025-04-29 11:06:05,540] WARNING django.request Not Found: /apple-touch-icon-precomposed.png
[2025-04-29 11:06:05,541] WARNING django.request Not Found: /favicon.ico
[2025-04-29 11:07:57,070] WARNING django.request Not Found: /static/rest_framework/fonts/glyphicons-halflings-regular.woff2
[2025-04-29 11:07:57,085] WARNING django.request Not Found: /static/rest_framework/js/ajax-form.js
[2025-04-29 11:07:57,117] WARNING django.request Not Found: /static/rest_framework/js/default.js
[2025-04-29 11:07:57,118] WARNING django.request Not Found: /static/rest_framework/css/bootstrap.min.css
[2025-04-29 11:07:57,118] WARNING django.request Not Found: /static/rest_framework/css/default.css
[2025-04-29 11:07:57,118] WARNING django.request Not Found: /static/rest_framework/js/load-ajax-form.js
[2025-04-29 11:07:57,124] WARNING django.request Not Found: /static/rest_framework/css/bootstrap-tweaks.css
[2025-04-29 11:07:57,135] WARNING django.request Not Found: /static/rest_framework/css/prettify.css
[2025-04-29 11:07:57,160] WARNING django.request Not Found: /static/rest_framework/js/jquery-3.7.1.min.js
[2025-04-29 11:07:57,160] WARNING django.request Not Found: /static/rest_framework/js/csrf.js
[2025-04-29 11:07:57,160] WARNING django.request Not Found: /static/rest_framework/js/bootstrap.min.js
[2025-04-29 11:07:57,160] WARNING django.request Not Found: /static/rest_framework/js/prettify-min.js
[2025-04-29 11:11:07,992] DEBUG django.request Asynchronous handler adapted for middleware whitenoise.middleware.WhiteNoiseMiddleware.
[2025-04-29 11:11:25,241] WARNING django.request Not Found: /apple-touch-icon-precomposed.png
[2025-04-29 11:11:25,241] WARNING django.request Not Found: /favicon.ico
[2025-04-29 11:11:25,242] WARNING django.request Not Found: /apple-touch-icon.png
[2025-04-29 11:17:47,353] DEBUG django.request Asynchronous handler adapted for middleware whitenoise.middleware.WhiteNoiseMiddleware.
[2025-04-29 11:17:53,379] WARNING django.request Not Found: /apple-touch-icon-precomposed.png
[2025-04-29 11:17:53,379] WARNING django.request Not Found: /favicon.ico
[2025-04-29 11:17:53,379] WARNING django.request Not Found: /apple-touch-icon.png
[2025-04-29 11:37:53,733] DEBUG django.request Asynchronous handler adapted for middleware whitenoise.middleware.WhiteNoiseMiddleware.
[2025-04-29 11:38:00,824] WARNING django.request Not Found: /apple-touch-icon-precomposed.png
[2025-04-29 11:38:00,824] WARNING django.request Not Found: /apple-touch-icon.png
[2025-04-29 11:38:00,828] WARNING django.request Not Found: /favicon.ico
[2025-04-29 11:42:05,946] DEBUG django.request Asynchronous handler adapted for middleware whitenoise.middleware.WhiteNoiseMiddleware.
[2025-04-29 11:42:10,465] WARNING django.request Not Found: /apple-touch-icon-precomposed.png
[2025-04-29 11:42:10,465] WARNING django.request Not Found: /favicon.ico
[2025-04-29 11:42:10,465] WARNING django.request Not Found: /apple-touch-icon.png
[2025-04-29 12:19:34,717] DEBUG django.request Asynchronous handler adapted for middleware whitenoise.middleware.WhiteNoiseMiddleware.
[2025-04-29 12:20:00,430] WARNING django.request Not Found: /favicon.ico
[2025-04-29 12:20:34,389] WARNING django.request Not Found: /api/v1/auth/regisrtation
[2025-04-29 12:20:40,233] WARNING django.request Method Not Allowed: /api/v1/auth/registration/
[2025-04-29 12:21:12,867] WARNING django.request Bad Request: /api/v1/auth/registration/
[2025-04-29 12:21:42,594] WARNING django.request Method Not Allowed: /api/v1/auth/login/
[2025-04-29 12:22:15,455] WARNING django.request Not Found: /api/v1/doc/swagger
[2025-04-29 12:22:54,902] ERROR django.request Internal Server Error: /api/v1/comments/comments/
Traceback (most recent call last):
  File "/usr/local/lib/python3.11/site-packages/kombu/utils/functional.py", line 32, in __call__
    return self.__value__
           ^^^^^^^^^^^^^^
AttributeError: 'ChannelPromise' object has no attribute '__value__'

During handling of the above exception, another exception occurred:

Traceback (most recent call last):
  File "/usr/local/lib/python3.11/site-packages/kombu/transport/virtual/base.py", line 951, in create_channel
    return self._avail_channels.pop()
           ^^^^^^^^^^^^^^^^^^^^^^^^^^
IndexError: pop from empty list

During handling of the above exception, another exception occurred:

Traceback (most recent call last):
  File "/usr/local/lib/python3.11/site-packages/redis/connection.py", line 357, in connect
    sock = self.retry.call_with_retry(
           ^^^^^^^^^^^^^^^^^^^^^^^^^^^
  File "/usr/local/lib/python3.11/site-packages/redis/retry.py", line 62, in call_with_retry
    return do()
           ^^^^
  File "/usr/local/lib/python3.11/site-packages/redis/connection.py", line 358, in <lambda>
    lambda: self._connect(), lambda error: self.disconnect(error)
            ^^^^^^^^^^^^^^^
  File "/usr/local/lib/python3.11/site-packages/redis/connection.py", line 730, in _connect
    raise err
  File "/usr/local/lib/python3.11/site-packages/redis/connection.py", line 718, in _connect
    sock.connect(socket_address)
ConnectionRefusedError: [Errno 111] Connection refused

During handling of the above exception, another exception occurred:

Traceback (most recent call last):
  File "/usr/local/lib/python3.11/site-packages/kombu/connection.py", line 472, in _reraise_as_library_errors
    yield
  File "/usr/local/lib/python3.11/site-packages/kombu/connection.py", line 459, in _ensure_connection
    return retry_over_time(
           ^^^^^^^^^^^^^^^^
  File "/usr/local/lib/python3.11/site-packages/kombu/utils/functional.py", line 318, in retry_over_time
    return fun(*args, **kwargs)
           ^^^^^^^^^^^^^^^^^^^^
  File "/usr/local/lib/python3.11/site-packages/kombu/connection.py", line 938, in _connection_factory
    self._connection = self._establish_connection()
                       ^^^^^^^^^^^^^^^^^^^^^^^^^^^^
  File "/usr/local/lib/python3.11/site-packages/kombu/connection.py", line 860, in _establish_connection
    conn = self.transport.establish_connection()
           ^^^^^^^^^^^^^^^^^^^^^^^^^^^^^^^^^^^^^
  File "/usr/local/lib/python3.11/site-packages/kombu/transport/virtual/base.py", line 975, in establish_connection
    self._avail_channels.append(self.create_channel(self))
                                ^^^^^^^^^^^^^^^^^^^^^^^^^
  File "/usr/local/lib/python3.11/site-packages/kombu/transport/virtual/base.py", line 953, in create_channel
    channel = self.Channel(connection)
              ^^^^^^^^^^^^^^^^^^^^^^^^
  File "/usr/local/lib/python3.11/site-packages/kombu/transport/redis.py", line 744, in __init__
    self.client.ping()
  File "/usr/local/lib/python3.11/site-packages/redis/commands/core.py", line 1212, in ping
    return self.execute_command("PING", **kwargs)
           ^^^^^^^^^^^^^^^^^^^^^^^^^^^^^^^^^^^^^^
  File "/usr/local/lib/python3.11/site-packages/redis/client.py", line 559, in execute_command
    return self._execute_command(*args, **options)
           ^^^^^^^^^^^^^^^^^^^^^^^^^^^^^^^^^^^^^^^
  File "/usr/local/lib/python3.11/site-packages/redis/client.py", line 565, in _execute_command
    conn = self.connection or pool.get_connection(command_name, **options)
                              ^^^^^^^^^^^^^^^^^^^^^^^^^^^^^^^^^^^^^^^^^^^^
  File "/usr/local/lib/python3.11/site-packages/redis/connection.py", line 1422, in get_connection
    connection.connect()
  File "/usr/local/lib/python3.11/site-packages/redis/connection.py", line 363, in connect
    raise ConnectionError(self._error_message(e))
redis.exceptions.ConnectionError: Error 111 connecting to localhost:6379. Connection refused.

The above exception was the direct cause of the following exception:

Traceback (most recent call last):
  File "/usr/local/lib/python3.11/site-packages/asgiref/sync.py", line 518, in thread_handler
    raise exc_info[1]
  File "/usr/local/lib/python3.11/site-packages/django/core/handlers/exception.py", line 42, in inner
    response = await get_response(request)
               ^^^^^^^^^^^^^^^^^^^^^^^^^^^
  File "/usr/local/lib/python3.11/site-packages/asgiref/sync.py", line 518, in thread_handler
    raise exc_info[1]
  File "/usr/local/lib/python3.11/site-packages/django/core/handlers/base.py", line 253, in _get_response_async
    response = await wrapped_callback(
               ^^^^^^^^^^^^^^^^^^^^^^^
  File "/usr/local/lib/python3.11/site-packages/asgiref/sync.py", line 468, in __call__
    ret = await asyncio.shield(exec_coro)
          ^^^^^^^^^^^^^^^^^^^^^^^^^^^^^^^
  File "/usr/local/lib/python3.11/site-packages/asgiref/current_thread_executor.py", line 40, in run
    result = self.fn(*self.args, **self.kwargs)
             ^^^^^^^^^^^^^^^^^^^^^^^^^^^^^^^^^^
  File "/usr/local/lib/python3.11/site-packages/asgiref/sync.py", line 522, in thread_handler
    return func(*args, **kwargs)
           ^^^^^^^^^^^^^^^^^^^^^
  File "/usr/local/lib/python3.11/site-packages/django/views/decorators/csrf.py", line 65, in _view_wrapper
    return view_func(request, *args, **kwargs)
           ^^^^^^^^^^^^^^^^^^^^^^^^^^^^^^^^^^^
  File "/usr/local/lib/python3.11/site-packages/rest_framework/viewsets.py", line 125, in view
    return self.dispatch(request, *args, **kwargs)
           ^^^^^^^^^^^^^^^^^^^^^^^^^^^^^^^^^^^^^^^
  File "/usr/local/lib/python3.11/site-packages/rest_framework/views.py", line 515, in dispatch
    response = self.handle_exception(exc)
               ^^^^^^^^^^^^^^^^^^^^^^^^^^
  File "/usr/local/lib/python3.11/site-packages/rest_framework/views.py", line 475, in handle_exception
    self.raise_uncaught_exception(exc)
  File "/usr/local/lib/python3.11/site-packages/rest_framework/views.py", line 486, in raise_uncaught_exception
    raise exc
  File "/usr/local/lib/python3.11/site-packages/rest_framework/views.py", line 512, in dispatch
    response = handler(request, *args, **kwargs)
               ^^^^^^^^^^^^^^^^^^^^^^^^^^^^^^^^^
  File "/usr/local/lib/python3.11/site-packages/rest_framework/mixins.py", line 19, in create
    self.perform_create(serializer)
  File "/usr/local/lib/python3.11/site-packages/rest_framework/mixins.py", line 24, in perform_create
    serializer.save()
  File "/usr/local/lib/python3.11/site-packages/rest_framework/serializers.py", line 210, in save
    self.instance = self.create(validated_data)
                    ^^^^^^^^^^^^^^^^^^^^^^^^^^^
  File "/usr/local/lib/python3.11/site-packages/rest_framework/serializers.py", line 991, in create
    instance = ModelClass._default_manager.create(**validated_data)
               ^^^^^^^^^^^^^^^^^^^^^^^^^^^^^^^^^^^^^^^^^^^^^^^^^^^^
  File "/usr/local/lib/python3.11/site-packages/django/db/models/manager.py", line 87, in manager_method
    return getattr(self.get_queryset(), name)(*args, **kwargs)
           ^^^^^^^^^^^^^^^^^^^^^^^^^^^^^^^^^^^^^^^^^^^^^^^^^^^
  File "/usr/local/lib/python3.11/site-packages/django/db/models/query.py", line 663, in create
    obj.save(force_insert=True, using=self.db)
  File "/app/base/model.py", line 16, in save
    send_comment_updates.delay()
  File "/usr/local/lib/python3.11/site-packages/celery/app/task.py", line 444, in delay
    return self.apply_async(args, kwargs)
           ^^^^^^^^^^^^^^^^^^^^^^^^^^^^^^
  File "/usr/local/lib/python3.11/site-packages/celery/app/task.py", line 601, in apply_async
    return app.send_task(
           ^^^^^^^^^^^^^^
  File "/usr/local/lib/python3.11/site-packages/celery/app/base.py", line 922, in send_task
    amqp.send_task_message(P, name, message, **options)
  File "/usr/local/lib/python3.11/site-packages/celery/app/amqp.py", line 523, in send_task_message
    ret = producer.publish(
          ^^^^^^^^^^^^^^^^^
  File "/usr/local/lib/python3.11/site-packages/kombu/messaging.py", line 190, in publish
    return _publish(
           ^^^^^^^^^
  File "/usr/local/lib/python3.11/site-packages/kombu/connection.py", line 556, in _ensured
    return fun(*args, **kwargs)
           ^^^^^^^^^^^^^^^^^^^^
  File "/usr/local/lib/python3.11/site-packages/kombu/messaging.py", line 200, in _publish
    channel = self.channel
              ^^^^^^^^^^^^
  File "/usr/local/lib/python3.11/site-packages/kombu/messaging.py", line 224, in _get_channel
    channel = self._channel = channel()
                              ^^^^^^^^^
  File "/usr/local/lib/python3.11/site-packages/kombu/utils/functional.py", line 34, in __call__
    value = self.__value__ = self.__contract__()
                             ^^^^^^^^^^^^^^^^^^^
  File "/usr/local/lib/python3.11/site-packages/kombu/messaging.py", line 240, in <lambda>
    channel = ChannelPromise(lambda: connection.default_channel)
                                     ^^^^^^^^^^^^^^^^^^^^^^^^^^
  File "/usr/local/lib/python3.11/site-packages/kombu/connection.py", line 957, in default_channel
    self._ensure_connection(**conn_opts)
  File "/usr/local/lib/python3.11/site-packages/kombu/connection.py", line 458, in _ensure_connection
    with ctx():
  File "/usr/local/lib/python3.11/contextlib.py", line 158, in __exit__
    self.gen.throw(typ, value, traceback)
  File "/usr/local/lib/python3.11/site-packages/kombu/connection.py", line 476, in _reraise_as_library_errors
    raise ConnectionError(str(exc)) from exc
kombu.exceptions.OperationalError: Error 111 connecting to localhost:6379. Connection refused.
[2025-04-29 12:26:31,305] DEBUG django.request Asynchronous handler adapted for middleware whitenoise.middleware.WhiteNoiseMiddleware.
[2025-04-29 12:27:22,359] DEBUG django.request Asynchronous handler adapted for middleware whitenoise.middleware.WhiteNoiseMiddleware.
[2025-04-29 12:30:33,015] DEBUG django.request Asynchronous handler adapted for middleware whitenoise.middleware.WhiteNoiseMiddleware.
[2025-04-29 12:32:15,932] DEBUG django.request Asynchronous handler adapted for middleware whitenoise.middleware.WhiteNoiseMiddleware.
[2025-04-29 12:35:48,711] DEBUG django.request Asynchronous handler adapted for middleware whitenoise.middleware.WhiteNoiseMiddleware.
[2025-04-29 12:42:52,258] DEBUG django.request Asynchronous handler adapted for middleware whitenoise.middleware.WhiteNoiseMiddleware.
[2025-04-29 12:45:39,149] DEBUG django.request Asynchronous handler adapted for middleware whitenoise.middleware.WhiteNoiseMiddleware.
[2025-04-29 12:46:41,177] ERROR django.request Internal Server Error: /api/v1/comments/comments/
Traceback (most recent call last):
  File "/usr/local/lib/python3.11/site-packages/kombu/utils/functional.py", line 32, in __call__
    return self.__value__
           ^^^^^^^^^^^^^^
AttributeError: 'ChannelPromise' object has no attribute '__value__'

During handling of the above exception, another exception occurred:

Traceback (most recent call last):
  File "/usr/local/lib/python3.11/site-packages/kombu/transport/virtual/base.py", line 951, in create_channel
    return self._avail_channels.pop()
           ^^^^^^^^^^^^^^^^^^^^^^^^^^
IndexError: pop from empty list

During handling of the above exception, another exception occurred:

Traceback (most recent call last):
  File "/usr/local/lib/python3.11/site-packages/redis/connection.py", line 357, in connect
    sock = self.retry.call_with_retry(
           ^^^^^^^^^^^^^^^^^^^^^^^^^^^
  File "/usr/local/lib/python3.11/site-packages/redis/retry.py", line 62, in call_with_retry
    return do()
           ^^^^
  File "/usr/local/lib/python3.11/site-packages/redis/connection.py", line 358, in <lambda>
    lambda: self._connect(), lambda error: self.disconnect(error)
            ^^^^^^^^^^^^^^^
  File "/usr/local/lib/python3.11/site-packages/redis/connection.py", line 730, in _connect
    raise err
  File "/usr/local/lib/python3.11/site-packages/redis/connection.py", line 718, in _connect
    sock.connect(socket_address)
ConnectionRefusedError: [Errno 111] Connection refused

During handling of the above exception, another exception occurred:

Traceback (most recent call last):
  File "/usr/local/lib/python3.11/site-packages/kombu/connection.py", line 472, in _reraise_as_library_errors
    yield
  File "/usr/local/lib/python3.11/site-packages/kombu/connection.py", line 459, in _ensure_connection
    return retry_over_time(
           ^^^^^^^^^^^^^^^^
  File "/usr/local/lib/python3.11/site-packages/kombu/utils/functional.py", line 318, in retry_over_time
    return fun(*args, **kwargs)
           ^^^^^^^^^^^^^^^^^^^^
  File "/usr/local/lib/python3.11/site-packages/kombu/connection.py", line 938, in _connection_factory
    self._connection = self._establish_connection()
                       ^^^^^^^^^^^^^^^^^^^^^^^^^^^^
  File "/usr/local/lib/python3.11/site-packages/kombu/connection.py", line 860, in _establish_connection
    conn = self.transport.establish_connection()
           ^^^^^^^^^^^^^^^^^^^^^^^^^^^^^^^^^^^^^
  File "/usr/local/lib/python3.11/site-packages/kombu/transport/virtual/base.py", line 975, in establish_connection
    self._avail_channels.append(self.create_channel(self))
                                ^^^^^^^^^^^^^^^^^^^^^^^^^
  File "/usr/local/lib/python3.11/site-packages/kombu/transport/virtual/base.py", line 953, in create_channel
    channel = self.Channel(connection)
              ^^^^^^^^^^^^^^^^^^^^^^^^
  File "/usr/local/lib/python3.11/site-packages/kombu/transport/redis.py", line 744, in __init__
    self.client.ping()
  File "/usr/local/lib/python3.11/site-packages/redis/commands/core.py", line 1212, in ping
    return self.execute_command("PING", **kwargs)
           ^^^^^^^^^^^^^^^^^^^^^^^^^^^^^^^^^^^^^^
  File "/usr/local/lib/python3.11/site-packages/redis/client.py", line 559, in execute_command
    return self._execute_command(*args, **options)
           ^^^^^^^^^^^^^^^^^^^^^^^^^^^^^^^^^^^^^^^
  File "/usr/local/lib/python3.11/site-packages/redis/client.py", line 565, in _execute_command
    conn = self.connection or pool.get_connection(command_name, **options)
                              ^^^^^^^^^^^^^^^^^^^^^^^^^^^^^^^^^^^^^^^^^^^^
  File "/usr/local/lib/python3.11/site-packages/redis/connection.py", line 1422, in get_connection
    connection.connect()
  File "/usr/local/lib/python3.11/site-packages/redis/connection.py", line 363, in connect
    raise ConnectionError(self._error_message(e))
redis.exceptions.ConnectionError: Error 111 connecting to localhost:6379. Connection refused.

The above exception was the direct cause of the following exception:

Traceback (most recent call last):
  File "/usr/local/lib/python3.11/site-packages/asgiref/sync.py", line 518, in thread_handler
    raise exc_info[1]
  File "/usr/local/lib/python3.11/site-packages/django/core/handlers/exception.py", line 42, in inner
    response = await get_response(request)
               ^^^^^^^^^^^^^^^^^^^^^^^^^^^
  File "/usr/local/lib/python3.11/site-packages/asgiref/sync.py", line 518, in thread_handler
    raise exc_info[1]
  File "/usr/local/lib/python3.11/site-packages/django/core/handlers/base.py", line 253, in _get_response_async
    response = await wrapped_callback(
               ^^^^^^^^^^^^^^^^^^^^^^^
  File "/usr/local/lib/python3.11/site-packages/asgiref/sync.py", line 468, in __call__
    ret = await asyncio.shield(exec_coro)
          ^^^^^^^^^^^^^^^^^^^^^^^^^^^^^^^
  File "/usr/local/lib/python3.11/site-packages/asgiref/current_thread_executor.py", line 40, in run
    result = self.fn(*self.args, **self.kwargs)
             ^^^^^^^^^^^^^^^^^^^^^^^^^^^^^^^^^^
  File "/usr/local/lib/python3.11/site-packages/asgiref/sync.py", line 522, in thread_handler
    return func(*args, **kwargs)
           ^^^^^^^^^^^^^^^^^^^^^
  File "/usr/local/lib/python3.11/site-packages/django/views/decorators/csrf.py", line 65, in _view_wrapper
    return view_func(request, *args, **kwargs)
           ^^^^^^^^^^^^^^^^^^^^^^^^^^^^^^^^^^^
  File "/usr/local/lib/python3.11/site-packages/rest_framework/viewsets.py", line 125, in view
    return self.dispatch(request, *args, **kwargs)
           ^^^^^^^^^^^^^^^^^^^^^^^^^^^^^^^^^^^^^^^
  File "/usr/local/lib/python3.11/site-packages/rest_framework/views.py", line 515, in dispatch
    response = self.handle_exception(exc)
               ^^^^^^^^^^^^^^^^^^^^^^^^^^
  File "/usr/local/lib/python3.11/site-packages/rest_framework/views.py", line 475, in handle_exception
    self.raise_uncaught_exception(exc)
  File "/usr/local/lib/python3.11/site-packages/rest_framework/views.py", line 486, in raise_uncaught_exception
    raise exc
  File "/usr/local/lib/python3.11/site-packages/rest_framework/views.py", line 512, in dispatch
    response = handler(request, *args, **kwargs)
               ^^^^^^^^^^^^^^^^^^^^^^^^^^^^^^^^^
  File "/usr/local/lib/python3.11/site-packages/rest_framework/mixins.py", line 19, in create
    self.perform_create(serializer)
  File "/usr/local/lib/python3.11/site-packages/rest_framework/mixins.py", line 24, in perform_create
    serializer.save()
  File "/usr/local/lib/python3.11/site-packages/rest_framework/serializers.py", line 210, in save
    self.instance = self.create(validated_data)
                    ^^^^^^^^^^^^^^^^^^^^^^^^^^^
  File "/usr/local/lib/python3.11/site-packages/rest_framework/serializers.py", line 991, in create
    instance = ModelClass._default_manager.create(**validated_data)
               ^^^^^^^^^^^^^^^^^^^^^^^^^^^^^^^^^^^^^^^^^^^^^^^^^^^^
  File "/usr/local/lib/python3.11/site-packages/django/db/models/manager.py", line 87, in manager_method
    return getattr(self.get_queryset(), name)(*args, **kwargs)
           ^^^^^^^^^^^^^^^^^^^^^^^^^^^^^^^^^^^^^^^^^^^^^^^^^^^
  File "/usr/local/lib/python3.11/site-packages/django/db/models/query.py", line 663, in create
    obj.save(force_insert=True, using=self.db)
  File "/app/base/model.py", line 16, in save
    send_comment_updates.delay()
  File "/usr/local/lib/python3.11/site-packages/celery/app/task.py", line 444, in delay
    return self.apply_async(args, kwargs)
           ^^^^^^^^^^^^^^^^^^^^^^^^^^^^^^
  File "/usr/local/lib/python3.11/site-packages/celery/app/task.py", line 601, in apply_async
    return app.send_task(
           ^^^^^^^^^^^^^^
  File "/usr/local/lib/python3.11/site-packages/celery/app/base.py", line 922, in send_task
    amqp.send_task_message(P, name, message, **options)
  File "/usr/local/lib/python3.11/site-packages/celery/app/amqp.py", line 523, in send_task_message
    ret = producer.publish(
          ^^^^^^^^^^^^^^^^^
  File "/usr/local/lib/python3.11/site-packages/kombu/messaging.py", line 190, in publish
    return _publish(
           ^^^^^^^^^
  File "/usr/local/lib/python3.11/site-packages/kombu/connection.py", line 556, in _ensured
    return fun(*args, **kwargs)
           ^^^^^^^^^^^^^^^^^^^^
  File "/usr/local/lib/python3.11/site-packages/kombu/messaging.py", line 200, in _publish
    channel = self.channel
              ^^^^^^^^^^^^
  File "/usr/local/lib/python3.11/site-packages/kombu/messaging.py", line 224, in _get_channel
    channel = self._channel = channel()
                              ^^^^^^^^^
  File "/usr/local/lib/python3.11/site-packages/kombu/utils/functional.py", line 34, in __call__
    value = self.__value__ = self.__contract__()
                             ^^^^^^^^^^^^^^^^^^^
  File "/usr/local/lib/python3.11/site-packages/kombu/messaging.py", line 240, in <lambda>
    channel = ChannelPromise(lambda: connection.default_channel)
                                     ^^^^^^^^^^^^^^^^^^^^^^^^^^
  File "/usr/local/lib/python3.11/site-packages/kombu/connection.py", line 957, in default_channel
    self._ensure_connection(**conn_opts)
  File "/usr/local/lib/python3.11/site-packages/kombu/connection.py", line 458, in _ensure_connection
    with ctx():
  File "/usr/local/lib/python3.11/contextlib.py", line 158, in __exit__
    self.gen.throw(typ, value, traceback)
  File "/usr/local/lib/python3.11/site-packages/kombu/connection.py", line 476, in _reraise_as_library_errors
    raise ConnectionError(str(exc)) from exc
kombu.exceptions.OperationalError: Error 111 connecting to localhost:6379. Connection refused.
[2025-04-29 12:50:30,521] DEBUG django.request Asynchronous handler adapted for middleware whitenoise.middleware.WhiteNoiseMiddleware.
[2025-04-29 12:50:34,385] WARNING django.request Not Found: /ws/comments/
[2025-04-29 12:50:36,495] WARNING django.request Not Found: /ws/comments/
[2025-04-29 12:50:38,607] WARNING django.request Not Found: /ws/comments/
[2025-04-29 12:51:52,164] DEBUG django.request Asynchronous handler adapted for middleware whitenoise.middleware.WhiteNoiseMiddleware.
[2025-04-29 12:53:33,462] WARNING django.request Not Found: /ws/comments/
[2025-04-29 12:53:35,460] WARNING django.request Not Found: /ws/comments/
[2025-04-29 12:53:50,899] ERROR django.request Internal Server Error: /api/v1/comments/comments/
Traceback (most recent call last):
  File "/usr/local/lib/python3.11/site-packages/kombu/utils/functional.py", line 32, in __call__
    return self.__value__
           ^^^^^^^^^^^^^^
AttributeError: 'ChannelPromise' object has no attribute '__value__'

During handling of the above exception, another exception occurred:

Traceback (most recent call last):
  File "/usr/local/lib/python3.11/site-packages/kombu/transport/virtual/base.py", line 951, in create_channel
    return self._avail_channels.pop()
           ^^^^^^^^^^^^^^^^^^^^^^^^^^
IndexError: pop from empty list

During handling of the above exception, another exception occurred:

Traceback (most recent call last):
  File "/usr/local/lib/python3.11/site-packages/redis/connection.py", line 357, in connect
    sock = self.retry.call_with_retry(
           ^^^^^^^^^^^^^^^^^^^^^^^^^^^
  File "/usr/local/lib/python3.11/site-packages/redis/retry.py", line 62, in call_with_retry
    return do()
           ^^^^
  File "/usr/local/lib/python3.11/site-packages/redis/connection.py", line 358, in <lambda>
    lambda: self._connect(), lambda error: self.disconnect(error)
            ^^^^^^^^^^^^^^^
  File "/usr/local/lib/python3.11/site-packages/redis/connection.py", line 730, in _connect
    raise err
  File "/usr/local/lib/python3.11/site-packages/redis/connection.py", line 718, in _connect
    sock.connect(socket_address)
ConnectionRefusedError: [Errno 111] Connection refused

During handling of the above exception, another exception occurred:

Traceback (most recent call last):
  File "/usr/local/lib/python3.11/site-packages/kombu/connection.py", line 472, in _reraise_as_library_errors
    yield
  File "/usr/local/lib/python3.11/site-packages/kombu/connection.py", line 459, in _ensure_connection
    return retry_over_time(
           ^^^^^^^^^^^^^^^^
  File "/usr/local/lib/python3.11/site-packages/kombu/utils/functional.py", line 318, in retry_over_time
    return fun(*args, **kwargs)
           ^^^^^^^^^^^^^^^^^^^^
  File "/usr/local/lib/python3.11/site-packages/kombu/connection.py", line 938, in _connection_factory
    self._connection = self._establish_connection()
                       ^^^^^^^^^^^^^^^^^^^^^^^^^^^^
  File "/usr/local/lib/python3.11/site-packages/kombu/connection.py", line 860, in _establish_connection
    conn = self.transport.establish_connection()
           ^^^^^^^^^^^^^^^^^^^^^^^^^^^^^^^^^^^^^
  File "/usr/local/lib/python3.11/site-packages/kombu/transport/virtual/base.py", line 975, in establish_connection
    self._avail_channels.append(self.create_channel(self))
                                ^^^^^^^^^^^^^^^^^^^^^^^^^
  File "/usr/local/lib/python3.11/site-packages/kombu/transport/virtual/base.py", line 953, in create_channel
    channel = self.Channel(connection)
              ^^^^^^^^^^^^^^^^^^^^^^^^
  File "/usr/local/lib/python3.11/site-packages/kombu/transport/redis.py", line 744, in __init__
    self.client.ping()
  File "/usr/local/lib/python3.11/site-packages/redis/commands/core.py", line 1212, in ping
    return self.execute_command("PING", **kwargs)
           ^^^^^^^^^^^^^^^^^^^^^^^^^^^^^^^^^^^^^^
  File "/usr/local/lib/python3.11/site-packages/redis/client.py", line 559, in execute_command
    return self._execute_command(*args, **options)
           ^^^^^^^^^^^^^^^^^^^^^^^^^^^^^^^^^^^^^^^
  File "/usr/local/lib/python3.11/site-packages/redis/client.py", line 565, in _execute_command
    conn = self.connection or pool.get_connection(command_name, **options)
                              ^^^^^^^^^^^^^^^^^^^^^^^^^^^^^^^^^^^^^^^^^^^^
  File "/usr/local/lib/python3.11/site-packages/redis/connection.py", line 1422, in get_connection
    connection.connect()
  File "/usr/local/lib/python3.11/site-packages/redis/connection.py", line 363, in connect
    raise ConnectionError(self._error_message(e))
redis.exceptions.ConnectionError: Error 111 connecting to localhost:6379. Connection refused.

The above exception was the direct cause of the following exception:

Traceback (most recent call last):
  File "/usr/local/lib/python3.11/site-packages/asgiref/sync.py", line 518, in thread_handler
    raise exc_info[1]
  File "/usr/local/lib/python3.11/site-packages/django/core/handlers/exception.py", line 42, in inner
    response = await get_response(request)
               ^^^^^^^^^^^^^^^^^^^^^^^^^^^
  File "/usr/local/lib/python3.11/site-packages/asgiref/sync.py", line 518, in thread_handler
    raise exc_info[1]
  File "/usr/local/lib/python3.11/site-packages/django/core/handlers/base.py", line 253, in _get_response_async
    response = await wrapped_callback(
               ^^^^^^^^^^^^^^^^^^^^^^^
  File "/usr/local/lib/python3.11/site-packages/asgiref/sync.py", line 468, in __call__
    ret = await asyncio.shield(exec_coro)
          ^^^^^^^^^^^^^^^^^^^^^^^^^^^^^^^
  File "/usr/local/lib/python3.11/site-packages/asgiref/current_thread_executor.py", line 40, in run
    result = self.fn(*self.args, **self.kwargs)
             ^^^^^^^^^^^^^^^^^^^^^^^^^^^^^^^^^^
  File "/usr/local/lib/python3.11/site-packages/asgiref/sync.py", line 522, in thread_handler
    return func(*args, **kwargs)
           ^^^^^^^^^^^^^^^^^^^^^
  File "/usr/local/lib/python3.11/site-packages/django/views/decorators/csrf.py", line 65, in _view_wrapper
    return view_func(request, *args, **kwargs)
           ^^^^^^^^^^^^^^^^^^^^^^^^^^^^^^^^^^^
  File "/usr/local/lib/python3.11/site-packages/rest_framework/viewsets.py", line 125, in view
    return self.dispatch(request, *args, **kwargs)
           ^^^^^^^^^^^^^^^^^^^^^^^^^^^^^^^^^^^^^^^
  File "/usr/local/lib/python3.11/site-packages/rest_framework/views.py", line 515, in dispatch
    response = self.handle_exception(exc)
               ^^^^^^^^^^^^^^^^^^^^^^^^^^
  File "/usr/local/lib/python3.11/site-packages/rest_framework/views.py", line 475, in handle_exception
    self.raise_uncaught_exception(exc)
  File "/usr/local/lib/python3.11/site-packages/rest_framework/views.py", line 486, in raise_uncaught_exception
    raise exc
  File "/usr/local/lib/python3.11/site-packages/rest_framework/views.py", line 512, in dispatch
    response = handler(request, *args, **kwargs)
               ^^^^^^^^^^^^^^^^^^^^^^^^^^^^^^^^^
  File "/usr/local/lib/python3.11/site-packages/rest_framework/mixins.py", line 19, in create
    self.perform_create(serializer)
  File "/usr/local/lib/python3.11/site-packages/rest_framework/mixins.py", line 24, in perform_create
    serializer.save()
  File "/usr/local/lib/python3.11/site-packages/rest_framework/serializers.py", line 210, in save
    self.instance = self.create(validated_data)
                    ^^^^^^^^^^^^^^^^^^^^^^^^^^^
  File "/usr/local/lib/python3.11/site-packages/rest_framework/serializers.py", line 991, in create
    instance = ModelClass._default_manager.create(**validated_data)
               ^^^^^^^^^^^^^^^^^^^^^^^^^^^^^^^^^^^^^^^^^^^^^^^^^^^^
  File "/usr/local/lib/python3.11/site-packages/django/db/models/manager.py", line 87, in manager_method
    return getattr(self.get_queryset(), name)(*args, **kwargs)
           ^^^^^^^^^^^^^^^^^^^^^^^^^^^^^^^^^^^^^^^^^^^^^^^^^^^
  File "/usr/local/lib/python3.11/site-packages/django/db/models/query.py", line 663, in create
    obj.save(force_insert=True, using=self.db)
  File "/app/base/model.py", line 16, in save
    send_comment_updates.delay()
  File "/usr/local/lib/python3.11/site-packages/celery/app/task.py", line 444, in delay
    return self.apply_async(args, kwargs)
           ^^^^^^^^^^^^^^^^^^^^^^^^^^^^^^
  File "/usr/local/lib/python3.11/site-packages/celery/app/task.py", line 601, in apply_async
    return app.send_task(
           ^^^^^^^^^^^^^^
  File "/usr/local/lib/python3.11/site-packages/celery/app/base.py", line 922, in send_task
    amqp.send_task_message(P, name, message, **options)
  File "/usr/local/lib/python3.11/site-packages/celery/app/amqp.py", line 523, in send_task_message
    ret = producer.publish(
          ^^^^^^^^^^^^^^^^^
  File "/usr/local/lib/python3.11/site-packages/kombu/messaging.py", line 190, in publish
    return _publish(
           ^^^^^^^^^
  File "/usr/local/lib/python3.11/site-packages/kombu/connection.py", line 556, in _ensured
    return fun(*args, **kwargs)
           ^^^^^^^^^^^^^^^^^^^^
  File "/usr/local/lib/python3.11/site-packages/kombu/messaging.py", line 200, in _publish
    channel = self.channel
              ^^^^^^^^^^^^
  File "/usr/local/lib/python3.11/site-packages/kombu/messaging.py", line 224, in _get_channel
    channel = self._channel = channel()
                              ^^^^^^^^^
  File "/usr/local/lib/python3.11/site-packages/kombu/utils/functional.py", line 34, in __call__
    value = self.__value__ = self.__contract__()
                             ^^^^^^^^^^^^^^^^^^^
  File "/usr/local/lib/python3.11/site-packages/kombu/messaging.py", line 240, in <lambda>
    channel = ChannelPromise(lambda: connection.default_channel)
                                     ^^^^^^^^^^^^^^^^^^^^^^^^^^
  File "/usr/local/lib/python3.11/site-packages/kombu/connection.py", line 957, in default_channel
    self._ensure_connection(**conn_opts)
  File "/usr/local/lib/python3.11/site-packages/kombu/connection.py", line 458, in _ensure_connection
    with ctx():
  File "/usr/local/lib/python3.11/contextlib.py", line 158, in __exit__
    self.gen.throw(typ, value, traceback)
  File "/usr/local/lib/python3.11/site-packages/kombu/connection.py", line 476, in _reraise_as_library_errors
    raise ConnectionError(str(exc)) from exc
kombu.exceptions.OperationalError: Error 111 connecting to localhost:6379. Connection refused.
[2025-04-29 13:06:36,976] DEBUG django.request Asynchronous handler adapted for middleware whitenoise.middleware.WhiteNoiseMiddleware.
[2025-04-29 13:07:54,791] WARNING django.request Not Found: /favicon.ico
[2025-04-29 13:09:17,011] DEBUG django.request Asynchronous handler adapted for middleware whitenoise.middleware.WhiteNoiseMiddleware.
[2025-04-29 13:09:37,326] DEBUG django.request Asynchronous handler adapted for middleware whitenoise.middleware.WhiteNoiseMiddleware.
[2025-04-29 13:14:30,335] DEBUG django.request Asynchronous handler adapted for middleware whitenoise.middleware.WhiteNoiseMiddleware.
[2025-04-29 13:17:07,295] DEBUG django.request Asynchronous handler adapted for middleware whitenoise.middleware.WhiteNoiseMiddleware.
[2025-04-29 13:28:18,073] DEBUG django.request Asynchronous handler adapted for middleware whitenoise.middleware.WhiteNoiseMiddleware.
[2025-04-29 13:30:09,764] DEBUG django.request Asynchronous handler adapted for middleware whitenoise.middleware.WhiteNoiseMiddleware.
[2025-04-29 13:36:16,549] DEBUG django.request Asynchronous handler adapted for middleware whitenoise.middleware.WhiteNoiseMiddleware.
[2025-04-29 13:41:21,275] DEBUG django.request Asynchronous handler adapted for middleware whitenoise.middleware.WhiteNoiseMiddleware.
[2025-04-29 13:48:22,132] DEBUG django.request Asynchronous handler adapted for middleware whitenoise.middleware.WhiteNoiseMiddleware.
[2025-04-29 13:53:39,759] DEBUG django.request Asynchronous handler adapted for middleware whitenoise.middleware.WhiteNoiseMiddleware.
[2025-04-29 13:55:13,683] DEBUG django.request Asynchronous handler adapted for middleware whitenoise.middleware.WhiteNoiseMiddleware.
[2025-04-29 14:00:46,009] DEBUG django.request Asynchronous handler adapted for middleware whitenoise.middleware.WhiteNoiseMiddleware.
[2025-04-29 14:08:07,752] DEBUG django.request Asynchronous handler adapted for middleware whitenoise.middleware.WhiteNoiseMiddleware.
[2025-04-29 14:08:20,394] WARNING django.request Not Found: /ws/comments/
[2025-04-29 14:08:22,780] WARNING django.request Not Found: /ws/comments/
[2025-04-29 14:08:32,441] WARNING django.request Not Found: /ws/comments/
[2025-04-29 14:09:01,571] WARNING django.request Not Found: /ws/comments/
[2025-04-29 14:09:08,480] WARNING django.request Not Found: /ws/comments/
[2025-04-29 14:09:50,740] DEBUG django.request Asynchronous handler adapted for middleware whitenoise.middleware.WhiteNoiseMiddleware.
[2025-04-29 14:09:54,495] WARNING django.request Not Found: /ws/comments/
[2025-04-29 14:12:39,853] DEBUG django.request Asynchronous handler adapted for middleware whitenoise.middleware.WhiteNoiseMiddleware.
[2025-04-29 14:12:41,181] WARNING django.request Not Found: /ws/comments/
[2025-04-29 14:19:05,093] DEBUG django.request Asynchronous handler adapted for middleware whitenoise.middleware.WhiteNoiseMiddleware.
[2025-04-29 14:30:46,850] WARNING django.request Not Found: /api/v1/
[2025-04-29 14:30:55,418] WARNING django.request Unauthorized: /api/v1/comments/
[2025-04-29 14:31:14,099] WARNING django.request Not Found: /api/v1login/
[2025-04-29 14:31:20,963] WARNING django.request Not Found: /api/v1/login/
[2025-04-29 14:31:32,260] WARNING django.request Method Not Allowed: /api/v1/auth/login/
[2025-04-29 14:31:41,858] ERROR django.request Internal Server Error: /api/v1/auth/login/
Traceback (most recent call last):
  File "/Users/mutafvladimir/Documents/IT/dZENcode/.venv/lib/python3.12/site-packages/django/db/backends/base/base.py", line 279, in ensure_connection
    self.connect()
  File "/Users/mutafvladimir/Documents/IT/dZENcode/.venv/lib/python3.12/site-packages/django/utils/asyncio.py", line 26, in inner
    return func(*args, **kwargs)
           ^^^^^^^^^^^^^^^^^^^^^
  File "/Users/mutafvladimir/Documents/IT/dZENcode/.venv/lib/python3.12/site-packages/django/db/backends/base/base.py", line 256, in connect
    self.connection = self.get_new_connection(conn_params)
                      ^^^^^^^^^^^^^^^^^^^^^^^^^^^^^^^^^^^^
  File "/Users/mutafvladimir/Documents/IT/dZENcode/.venv/lib/python3.12/site-packages/django/utils/asyncio.py", line 26, in inner
    return func(*args, **kwargs)
           ^^^^^^^^^^^^^^^^^^^^^
  File "/Users/mutafvladimir/Documents/IT/dZENcode/.venv/lib/python3.12/site-packages/django/db/backends/mysql/base.py", line 256, in get_new_connection
    connection = Database.connect(**conn_params)
                 ^^^^^^^^^^^^^^^^^^^^^^^^^^^^^^^
  File "/Users/mutafvladimir/Documents/IT/dZENcode/.venv/lib/python3.12/site-packages/MySQLdb/__init__.py", line 121, in Connect
    return Connection(*args, **kwargs)
           ^^^^^^^^^^^^^^^^^^^^^^^^^^^
  File "/Users/mutafvladimir/Documents/IT/dZENcode/.venv/lib/python3.12/site-packages/MySQLdb/connections.py", line 200, in __init__
    super().__init__(*args, **kwargs2)
MySQLdb.OperationalError: (2005, "Unknown MySQL server host 'mysql-db' (8)")

The above exception was the direct cause of the following exception:

Traceback (most recent call last):
  File "/Users/mutafvladimir/Documents/IT/dZENcode/.venv/lib/python3.12/site-packages/asgiref/sync.py", line 518, in thread_handler
    raise exc_info[1]
  File "/Users/mutafvladimir/Documents/IT/dZENcode/.venv/lib/python3.12/site-packages/django/core/handlers/exception.py", line 42, in inner
    response = await get_response(request)
               ^^^^^^^^^^^^^^^^^^^^^^^^^^^
  File "/Users/mutafvladimir/Documents/IT/dZENcode/.venv/lib/python3.12/site-packages/asgiref/sync.py", line 518, in thread_handler
    raise exc_info[1]
  File "/Users/mutafvladimir/Documents/IT/dZENcode/.venv/lib/python3.12/site-packages/django/core/handlers/base.py", line 253, in _get_response_async
    response = await wrapped_callback(
               ^^^^^^^^^^^^^^^^^^^^^^^
  File "/Users/mutafvladimir/Documents/IT/dZENcode/.venv/lib/python3.12/site-packages/asgiref/sync.py", line 468, in __call__
    ret = await asyncio.shield(exec_coro)
          ^^^^^^^^^^^^^^^^^^^^^^^^^^^^^^^
  File "/Users/mutafvladimir/Documents/IT/dZENcode/.venv/lib/python3.12/site-packages/asgiref/current_thread_executor.py", line 40, in run
    result = self.fn(*self.args, **self.kwargs)
             ^^^^^^^^^^^^^^^^^^^^^^^^^^^^^^^^^^
  File "/Users/mutafvladimir/Documents/IT/dZENcode/.venv/lib/python3.12/site-packages/asgiref/sync.py", line 522, in thread_handler
    return func(*args, **kwargs)
           ^^^^^^^^^^^^^^^^^^^^^
  File "/Users/mutafvladimir/Documents/IT/dZENcode/.venv/lib/python3.12/site-packages/django/views/decorators/csrf.py", line 65, in _view_wrapper
    return view_func(request, *args, **kwargs)
           ^^^^^^^^^^^^^^^^^^^^^^^^^^^^^^^^^^^
  File "/Users/mutafvladimir/Documents/IT/dZENcode/.venv/lib/python3.12/site-packages/django/views/generic/base.py", line 104, in view
    return self.dispatch(request, *args, **kwargs)
           ^^^^^^^^^^^^^^^^^^^^^^^^^^^^^^^^^^^^^^^
  File "/Users/mutafvladimir/Documents/IT/dZENcode/.venv/lib/python3.12/site-packages/rest_framework/views.py", line 515, in dispatch
    response = self.handle_exception(exc)
               ^^^^^^^^^^^^^^^^^^^^^^^^^^
  File "/Users/mutafvladimir/Documents/IT/dZENcode/.venv/lib/python3.12/site-packages/rest_framework/views.py", line 475, in handle_exception
    self.raise_uncaught_exception(exc)
  File "/Users/mutafvladimir/Documents/IT/dZENcode/.venv/lib/python3.12/site-packages/rest_framework/views.py", line 486, in raise_uncaught_exception
    raise exc
  File "/Users/mutafvladimir/Documents/IT/dZENcode/.venv/lib/python3.12/site-packages/rest_framework/views.py", line 512, in dispatch
    response = handler(request, *args, **kwargs)
               ^^^^^^^^^^^^^^^^^^^^^^^^^^^^^^^^^
  File "/Users/mutafvladimir/Documents/IT/dZENcode/.venv/lib/python3.12/site-packages/rest_framework/generics.py", line 194, in post
    return self.create(request, *args, **kwargs)
           ^^^^^^^^^^^^^^^^^^^^^^^^^^^^^^^^^^^^^
  File "/Users/mutafvladimir/Documents/IT/dZENcode/comments/api/auth/view.py", line 50, in create
    user = authenticate(request, username=username, password=password)
           ^^^^^^^^^^^^^^^^^^^^^^^^^^^^^^^^^^^^^^^^^^^^^^^^^^^^^^^^^^^
  File "/Users/mutafvladimir/Documents/IT/dZENcode/.venv/lib/python3.12/site-packages/django/views/decorators/debug.py", line 75, in sensitive_variables_wrapper
    return func(*func_args, **func_kwargs)
           ^^^^^^^^^^^^^^^^^^^^^^^^^^^^^^^
  File "/Users/mutafvladimir/Documents/IT/dZENcode/.venv/lib/python3.12/site-packages/django/contrib/auth/__init__.py", line 114, in authenticate
    user = backend.authenticate(request, **credentials)
           ^^^^^^^^^^^^^^^^^^^^^^^^^^^^^^^^^^^^^^^^^^^^
  File "/Users/mutafvladimir/Documents/IT/dZENcode/.venv/lib/python3.12/site-packages/django/contrib/auth/backends.py", line 65, in authenticate
    user = UserModel._default_manager.get_by_natural_key(username)
           ^^^^^^^^^^^^^^^^^^^^^^^^^^^^^^^^^^^^^^^^^^^^^^^^^^^^^^^
  File "/Users/mutafvladimir/Documents/IT/dZENcode/.venv/lib/python3.12/site-packages/django/contrib/auth/base_user.py", line 37, in get_by_natural_key
    return self.get(**{self.model.USERNAME_FIELD: username})
           ^^^^^^^^^^^^^^^^^^^^^^^^^^^^^^^^^^^^^^^^^^^^^^^^^
  File "/Users/mutafvladimir/Documents/IT/dZENcode/.venv/lib/python3.12/site-packages/django/db/models/manager.py", line 87, in manager_method
    return getattr(self.get_queryset(), name)(*args, **kwargs)
           ^^^^^^^^^^^^^^^^^^^^^^^^^^^^^^^^^^^^^^^^^^^^^^^^^^^
  File "/Users/mutafvladimir/Documents/IT/dZENcode/.venv/lib/python3.12/site-packages/django/db/models/query.py", line 629, in get
    num = len(clone)
          ^^^^^^^^^^
  File "/Users/mutafvladimir/Documents/IT/dZENcode/.venv/lib/python3.12/site-packages/django/db/models/query.py", line 366, in __len__
    self._fetch_all()
  File "/Users/mutafvladimir/Documents/IT/dZENcode/.venv/lib/python3.12/site-packages/django/db/models/query.py", line 1935, in _fetch_all
    self._result_cache = list(self._iterable_class(self))
                         ^^^^^^^^^^^^^^^^^^^^^^^^^^^^^^^^
  File "/Users/mutafvladimir/Documents/IT/dZENcode/.venv/lib/python3.12/site-packages/django/db/models/query.py", line 91, in __iter__
    results = compiler.execute_sql(
              ^^^^^^^^^^^^^^^^^^^^^
  File "/Users/mutafvladimir/Documents/IT/dZENcode/.venv/lib/python3.12/site-packages/django/db/models/sql/compiler.py", line 1620, in execute_sql
    cursor = self.connection.cursor()
             ^^^^^^^^^^^^^^^^^^^^^^^^
  File "/Users/mutafvladimir/Documents/IT/dZENcode/.venv/lib/python3.12/site-packages/django/utils/asyncio.py", line 26, in inner
    return func(*args, **kwargs)
           ^^^^^^^^^^^^^^^^^^^^^
  File "/Users/mutafvladimir/Documents/IT/dZENcode/.venv/lib/python3.12/site-packages/django/db/backends/base/base.py", line 320, in cursor
    return self._cursor()
           ^^^^^^^^^^^^^^
  File "/Users/mutafvladimir/Documents/IT/dZENcode/.venv/lib/python3.12/site-packages/django/db/backends/base/base.py", line 296, in _cursor
    self.ensure_connection()
  File "/Users/mutafvladimir/Documents/IT/dZENcode/.venv/lib/python3.12/site-packages/django/utils/asyncio.py", line 26, in inner
    return func(*args, **kwargs)
           ^^^^^^^^^^^^^^^^^^^^^
  File "/Users/mutafvladimir/Documents/IT/dZENcode/.venv/lib/python3.12/site-packages/django/db/backends/base/base.py", line 278, in ensure_connection
    with self.wrap_database_errors:
         ^^^^^^^^^^^^^^^^^^^^^^^^^
  File "/Users/mutafvladimir/Documents/IT/dZENcode/.venv/lib/python3.12/site-packages/django/db/utils.py", line 91, in __exit__
    raise dj_exc_value.with_traceback(traceback) from exc_value
  File "/Users/mutafvladimir/Documents/IT/dZENcode/.venv/lib/python3.12/site-packages/django/db/backends/base/base.py", line 279, in ensure_connection
    self.connect()
  File "/Users/mutafvladimir/Documents/IT/dZENcode/.venv/lib/python3.12/site-packages/django/utils/asyncio.py", line 26, in inner
    return func(*args, **kwargs)
           ^^^^^^^^^^^^^^^^^^^^^
  File "/Users/mutafvladimir/Documents/IT/dZENcode/.venv/lib/python3.12/site-packages/django/db/backends/base/base.py", line 256, in connect
    self.connection = self.get_new_connection(conn_params)
                      ^^^^^^^^^^^^^^^^^^^^^^^^^^^^^^^^^^^^
  File "/Users/mutafvladimir/Documents/IT/dZENcode/.venv/lib/python3.12/site-packages/django/utils/asyncio.py", line 26, in inner
    return func(*args, **kwargs)
           ^^^^^^^^^^^^^^^^^^^^^
  File "/Users/mutafvladimir/Documents/IT/dZENcode/.venv/lib/python3.12/site-packages/django/db/backends/mysql/base.py", line 256, in get_new_connection
    connection = Database.connect(**conn_params)
                 ^^^^^^^^^^^^^^^^^^^^^^^^^^^^^^^
  File "/Users/mutafvladimir/Documents/IT/dZENcode/.venv/lib/python3.12/site-packages/MySQLdb/__init__.py", line 121, in Connect
    return Connection(*args, **kwargs)
           ^^^^^^^^^^^^^^^^^^^^^^^^^^^
  File "/Users/mutafvladimir/Documents/IT/dZENcode/.venv/lib/python3.12/site-packages/MySQLdb/connections.py", line 200, in __init__
    super().__init__(*args, **kwargs2)
django.db.utils.OperationalError: (2005, "Unknown MySQL server host 'mysql-db' (8)")
[2025-04-29 14:33:07,504] DEBUG django.request Asynchronous handler adapted for middleware whitenoise.middleware.WhiteNoiseMiddleware.
[2025-04-29 14:33:41,727] WARNING django.request Not Found: /ws/comments/
[2025-04-29 14:34:07,100] WARNING django.request Not Found: /ws/comments/
[2025-04-29 14:40:20,272] WARNING django.request Not Found: /ws/comments/
[2025-04-29 14:41:50,159] WARNING django.request Not Found: /ws/comments/
[2025-04-29 14:42:16,155] WARNING django.request Not Found: /ws/comments/
[2025-04-29 14:42:18,810] WARNING django.request Not Found: /api/v1/commitment/commitment/
[2025-04-29 14:42:26,528] WARNING django.request Not Found: /api/v1/comment
[2025-04-29 14:42:33,524] WARNING django.request Unauthorized: /api/v1/comments/
[2025-04-29 14:43:22,090] WARNING django.request Unauthorized: /api/v1/comments/
[2025-04-29 14:43:24,661] WARNING django.request Unauthorized: /api/v1/comments/
[2025-04-29 14:43:57,804] WARNING django.request Unauthorized: /api/v1/comments/
[2025-04-29 14:44:04,563] WARNING django.request Not Found: /api/v1/commitment/commitment/
[2025-04-29 14:44:05,288] WARNING django.request Not Found: /api/v1/applications/grader_name/
[2025-04-29 14:44:11,402] WARNING django.request Method Not Allowed: /api/v1/auth/login/
[2025-04-29 14:46:40,813] DEBUG django.request Asynchronous handler adapted for middleware whitenoise.middleware.WhiteNoiseMiddleware.
[2025-04-29 14:48:04,651] DEBUG django.request Asynchronous handler adapted for middleware whitenoise.middleware.WhiteNoiseMiddleware.
[2025-04-29 14:49:26,700] DEBUG django.request Asynchronous handler adapted for middleware whitenoise.middleware.WhiteNoiseMiddleware.
[2025-04-29 14:55:00,958] DEBUG django.request Asynchronous handler adapted for middleware whitenoise.middleware.WhiteNoiseMiddleware.
[2025-04-29 14:55:05,265] ERROR django.request Internal Server Error: /api/v1/comments/comments/
Traceback (most recent call last):
  File "/Users/mutafvladimir/Documents/IT/dZENcode/.venv/lib/python3.12/site-packages/django/db/backends/base/base.py", line 279, in ensure_connection
    self.connect()
  File "/Users/mutafvladimir/Documents/IT/dZENcode/.venv/lib/python3.12/site-packages/django/utils/asyncio.py", line 26, in inner
    return func(*args, **kwargs)
           ^^^^^^^^^^^^^^^^^^^^^
  File "/Users/mutafvladimir/Documents/IT/dZENcode/.venv/lib/python3.12/site-packages/django/db/backends/base/base.py", line 256, in connect
    self.connection = self.get_new_connection(conn_params)
                      ^^^^^^^^^^^^^^^^^^^^^^^^^^^^^^^^^^^^
  File "/Users/mutafvladimir/Documents/IT/dZENcode/.venv/lib/python3.12/site-packages/django/utils/asyncio.py", line 26, in inner
    return func(*args, **kwargs)
           ^^^^^^^^^^^^^^^^^^^^^
  File "/Users/mutafvladimir/Documents/IT/dZENcode/.venv/lib/python3.12/site-packages/django/db/backends/mysql/base.py", line 256, in get_new_connection
    connection = Database.connect(**conn_params)
                 ^^^^^^^^^^^^^^^^^^^^^^^^^^^^^^^
  File "/Users/mutafvladimir/Documents/IT/dZENcode/.venv/lib/python3.12/site-packages/MySQLdb/__init__.py", line 121, in Connect
    return Connection(*args, **kwargs)
           ^^^^^^^^^^^^^^^^^^^^^^^^^^^
  File "/Users/mutafvladimir/Documents/IT/dZENcode/.venv/lib/python3.12/site-packages/MySQLdb/connections.py", line 200, in __init__
    super().__init__(*args, **kwargs2)
MySQLdb.OperationalError: (2002, "Can't connect to local MySQL server through socket '/tmp/mysql.sock' (2)")

The above exception was the direct cause of the following exception:

Traceback (most recent call last):
  File "/Users/mutafvladimir/Documents/IT/dZENcode/.venv/lib/python3.12/site-packages/asgiref/sync.py", line 518, in thread_handler
    raise exc_info[1]
  File "/Users/mutafvladimir/Documents/IT/dZENcode/.venv/lib/python3.12/site-packages/django/core/handlers/exception.py", line 42, in inner
    response = await get_response(request)
               ^^^^^^^^^^^^^^^^^^^^^^^^^^^
  File "/Users/mutafvladimir/Documents/IT/dZENcode/.venv/lib/python3.12/site-packages/asgiref/sync.py", line 518, in thread_handler
    raise exc_info[1]
  File "/Users/mutafvladimir/Documents/IT/dZENcode/.venv/lib/python3.12/site-packages/django/core/handlers/base.py", line 253, in _get_response_async
    response = await wrapped_callback(
               ^^^^^^^^^^^^^^^^^^^^^^^
  File "/Users/mutafvladimir/Documents/IT/dZENcode/.venv/lib/python3.12/site-packages/asgiref/sync.py", line 468, in __call__
    ret = await asyncio.shield(exec_coro)
          ^^^^^^^^^^^^^^^^^^^^^^^^^^^^^^^
  File "/Users/mutafvladimir/Documents/IT/dZENcode/.venv/lib/python3.12/site-packages/asgiref/current_thread_executor.py", line 40, in run
    result = self.fn(*self.args, **self.kwargs)
             ^^^^^^^^^^^^^^^^^^^^^^^^^^^^^^^^^^
  File "/Users/mutafvladimir/Documents/IT/dZENcode/.venv/lib/python3.12/site-packages/asgiref/sync.py", line 522, in thread_handler
    return func(*args, **kwargs)
           ^^^^^^^^^^^^^^^^^^^^^
  File "/Users/mutafvladimir/Documents/IT/dZENcode/.venv/lib/python3.12/site-packages/django/views/decorators/csrf.py", line 65, in _view_wrapper
    return view_func(request, *args, **kwargs)
           ^^^^^^^^^^^^^^^^^^^^^^^^^^^^^^^^^^^
  File "/Users/mutafvladimir/Documents/IT/dZENcode/.venv/lib/python3.12/site-packages/rest_framework/viewsets.py", line 125, in view
    return self.dispatch(request, *args, **kwargs)
           ^^^^^^^^^^^^^^^^^^^^^^^^^^^^^^^^^^^^^^^
  File "/Users/mutafvladimir/Documents/IT/dZENcode/.venv/lib/python3.12/site-packages/rest_framework/views.py", line 515, in dispatch
    response = self.handle_exception(exc)
               ^^^^^^^^^^^^^^^^^^^^^^^^^^
  File "/Users/mutafvladimir/Documents/IT/dZENcode/.venv/lib/python3.12/site-packages/rest_framework/views.py", line 475, in handle_exception
    self.raise_uncaught_exception(exc)
  File "/Users/mutafvladimir/Documents/IT/dZENcode/.venv/lib/python3.12/site-packages/rest_framework/views.py", line 486, in raise_uncaught_exception
    raise exc
  File "/Users/mutafvladimir/Documents/IT/dZENcode/.venv/lib/python3.12/site-packages/rest_framework/views.py", line 512, in dispatch
    response = handler(request, *args, **kwargs)
               ^^^^^^^^^^^^^^^^^^^^^^^^^^^^^^^^^
  File "/Users/mutafvladimir/Documents/IT/dZENcode/.venv/lib/python3.12/site-packages/rest_framework/mixins.py", line 40, in list
    page = self.paginate_queryset(queryset)
           ^^^^^^^^^^^^^^^^^^^^^^^^^^^^^^^^
  File "/Users/mutafvladimir/Documents/IT/dZENcode/.venv/lib/python3.12/site-packages/rest_framework/generics.py", line 175, in paginate_queryset
    return self.paginator.paginate_queryset(queryset, self.request, view=self)
           ^^^^^^^^^^^^^^^^^^^^^^^^^^^^^^^^^^^^^^^^^^^^^^^^^^^^^^^^^^^^^^^^^^^
  File "/Users/mutafvladimir/Documents/IT/dZENcode/.venv/lib/python3.12/site-packages/rest_framework/pagination.py", line 211, in paginate_queryset
    self.page = paginator.page(page_number)
                ^^^^^^^^^^^^^^^^^^^^^^^^^^^
  File "/Users/mutafvladimir/Documents/IT/dZENcode/.venv/lib/python3.12/site-packages/django/core/paginator.py", line 89, in page
    number = self.validate_number(number)
             ^^^^^^^^^^^^^^^^^^^^^^^^^^^^
  File "/Users/mutafvladimir/Documents/IT/dZENcode/.venv/lib/python3.12/site-packages/django/core/paginator.py", line 70, in validate_number
    if number > self.num_pages:
                ^^^^^^^^^^^^^^
  File "/Users/mutafvladimir/Documents/IT/dZENcode/.venv/lib/python3.12/site-packages/django/utils/functional.py", line 47, in __get__
    res = instance.__dict__[self.name] = self.func(instance)
                                         ^^^^^^^^^^^^^^^^^^^
  File "/Users/mutafvladimir/Documents/IT/dZENcode/.venv/lib/python3.12/site-packages/django/core/paginator.py", line 116, in num_pages
    if self.count == 0 and not self.allow_empty_first_page:
       ^^^^^^^^^^
  File "/Users/mutafvladimir/Documents/IT/dZENcode/.venv/lib/python3.12/site-packages/django/utils/functional.py", line 47, in __get__
    res = instance.__dict__[self.name] = self.func(instance)
                                         ^^^^^^^^^^^^^^^^^^^
  File "/Users/mutafvladimir/Documents/IT/dZENcode/.venv/lib/python3.12/site-packages/django/core/paginator.py", line 110, in count
    return c()
           ^^^
  File "/Users/mutafvladimir/Documents/IT/dZENcode/.venv/lib/python3.12/site-packages/django/db/models/query.py", line 604, in count
    return self.query.get_count(using=self.db)
           ^^^^^^^^^^^^^^^^^^^^^^^^^^^^^^^^^^^
  File "/Users/mutafvladimir/Documents/IT/dZENcode/.venv/lib/python3.12/site-packages/django/db/models/sql/query.py", line 644, in get_count
    return obj.get_aggregation(using, {"__count": Count("*")})["__count"]
           ^^^^^^^^^^^^^^^^^^^^^^^^^^^^^^^^^^^^^^^^^^^^^^^^^^^
  File "/Users/mutafvladimir/Documents/IT/dZENcode/.venv/lib/python3.12/site-packages/django/db/models/sql/query.py", line 626, in get_aggregation
    result = compiler.execute_sql(SINGLE)
             ^^^^^^^^^^^^^^^^^^^^^^^^^^^^
  File "/Users/mutafvladimir/Documents/IT/dZENcode/.venv/lib/python3.12/site-packages/django/db/models/sql/compiler.py", line 1620, in execute_sql
    cursor = self.connection.cursor()
             ^^^^^^^^^^^^^^^^^^^^^^^^
  File "/Users/mutafvladimir/Documents/IT/dZENcode/.venv/lib/python3.12/site-packages/django/utils/asyncio.py", line 26, in inner
    return func(*args, **kwargs)
           ^^^^^^^^^^^^^^^^^^^^^
  File "/Users/mutafvladimir/Documents/IT/dZENcode/.venv/lib/python3.12/site-packages/django/db/backends/base/base.py", line 320, in cursor
    return self._cursor()
           ^^^^^^^^^^^^^^
  File "/Users/mutafvladimir/Documents/IT/dZENcode/.venv/lib/python3.12/site-packages/django/db/backends/base/base.py", line 296, in _cursor
    self.ensure_connection()
  File "/Users/mutafvladimir/Documents/IT/dZENcode/.venv/lib/python3.12/site-packages/django/utils/asyncio.py", line 26, in inner
    return func(*args, **kwargs)
           ^^^^^^^^^^^^^^^^^^^^^
  File "/Users/mutafvladimir/Documents/IT/dZENcode/.venv/lib/python3.12/site-packages/django/db/backends/base/base.py", line 278, in ensure_connection
    with self.wrap_database_errors:
         ^^^^^^^^^^^^^^^^^^^^^^^^^
  File "/Users/mutafvladimir/Documents/IT/dZENcode/.venv/lib/python3.12/site-packages/django/db/utils.py", line 91, in __exit__
    raise dj_exc_value.with_traceback(traceback) from exc_value
  File "/Users/mutafvladimir/Documents/IT/dZENcode/.venv/lib/python3.12/site-packages/django/db/backends/base/base.py", line 279, in ensure_connection
    self.connect()
  File "/Users/mutafvladimir/Documents/IT/dZENcode/.venv/lib/python3.12/site-packages/django/utils/asyncio.py", line 26, in inner
    return func(*args, **kwargs)
           ^^^^^^^^^^^^^^^^^^^^^
  File "/Users/mutafvladimir/Documents/IT/dZENcode/.venv/lib/python3.12/site-packages/django/db/backends/base/base.py", line 256, in connect
    self.connection = self.get_new_connection(conn_params)
                      ^^^^^^^^^^^^^^^^^^^^^^^^^^^^^^^^^^^^
  File "/Users/mutafvladimir/Documents/IT/dZENcode/.venv/lib/python3.12/site-packages/django/utils/asyncio.py", line 26, in inner
    return func(*args, **kwargs)
           ^^^^^^^^^^^^^^^^^^^^^
  File "/Users/mutafvladimir/Documents/IT/dZENcode/.venv/lib/python3.12/site-packages/django/db/backends/mysql/base.py", line 256, in get_new_connection
    connection = Database.connect(**conn_params)
                 ^^^^^^^^^^^^^^^^^^^^^^^^^^^^^^^
  File "/Users/mutafvladimir/Documents/IT/dZENcode/.venv/lib/python3.12/site-packages/MySQLdb/__init__.py", line 121, in Connect
    return Connection(*args, **kwargs)
           ^^^^^^^^^^^^^^^^^^^^^^^^^^^
  File "/Users/mutafvladimir/Documents/IT/dZENcode/.venv/lib/python3.12/site-packages/MySQLdb/connections.py", line 200, in __init__
    super().__init__(*args, **kwargs2)
django.db.utils.OperationalError: (2002, "Can't connect to local MySQL server through socket '/tmp/mysql.sock' (2)")
[2025-04-29 14:57:45,987] ERROR django.request Internal Server Error: /api/v1/comments/comments/
Traceback (most recent call last):
  File "/Users/mutafvladimir/Documents/IT/dZENcode/.venv/lib/python3.12/site-packages/django/db/backends/base/base.py", line 279, in ensure_connection
    self.connect()
  File "/Users/mutafvladimir/Documents/IT/dZENcode/.venv/lib/python3.12/site-packages/django/utils/asyncio.py", line 26, in inner
    return func(*args, **kwargs)
           ^^^^^^^^^^^^^^^^^^^^^
  File "/Users/mutafvladimir/Documents/IT/dZENcode/.venv/lib/python3.12/site-packages/django/db/backends/base/base.py", line 256, in connect
    self.connection = self.get_new_connection(conn_params)
                      ^^^^^^^^^^^^^^^^^^^^^^^^^^^^^^^^^^^^
  File "/Users/mutafvladimir/Documents/IT/dZENcode/.venv/lib/python3.12/site-packages/django/utils/asyncio.py", line 26, in inner
    return func(*args, **kwargs)
           ^^^^^^^^^^^^^^^^^^^^^
  File "/Users/mutafvladimir/Documents/IT/dZENcode/.venv/lib/python3.12/site-packages/django/db/backends/mysql/base.py", line 256, in get_new_connection
    connection = Database.connect(**conn_params)
                 ^^^^^^^^^^^^^^^^^^^^^^^^^^^^^^^
  File "/Users/mutafvladimir/Documents/IT/dZENcode/.venv/lib/python3.12/site-packages/MySQLdb/__init__.py", line 121, in Connect
    return Connection(*args, **kwargs)
           ^^^^^^^^^^^^^^^^^^^^^^^^^^^
  File "/Users/mutafvladimir/Documents/IT/dZENcode/.venv/lib/python3.12/site-packages/MySQLdb/connections.py", line 200, in __init__
    super().__init__(*args, **kwargs2)
MySQLdb.OperationalError: (2002, "Can't connect to local MySQL server through socket '/tmp/mysql.sock' (2)")

The above exception was the direct cause of the following exception:

Traceback (most recent call last):
  File "/Users/mutafvladimir/Documents/IT/dZENcode/.venv/lib/python3.12/site-packages/asgiref/sync.py", line 518, in thread_handler
    raise exc_info[1]
  File "/Users/mutafvladimir/Documents/IT/dZENcode/.venv/lib/python3.12/site-packages/django/core/handlers/exception.py", line 42, in inner
    response = await get_response(request)
               ^^^^^^^^^^^^^^^^^^^^^^^^^^^
  File "/Users/mutafvladimir/Documents/IT/dZENcode/.venv/lib/python3.12/site-packages/asgiref/sync.py", line 518, in thread_handler
    raise exc_info[1]
  File "/Users/mutafvladimir/Documents/IT/dZENcode/.venv/lib/python3.12/site-packages/django/core/handlers/base.py", line 253, in _get_response_async
    response = await wrapped_callback(
               ^^^^^^^^^^^^^^^^^^^^^^^
  File "/Users/mutafvladimir/Documents/IT/dZENcode/.venv/lib/python3.12/site-packages/asgiref/sync.py", line 468, in __call__
    ret = await asyncio.shield(exec_coro)
          ^^^^^^^^^^^^^^^^^^^^^^^^^^^^^^^
  File "/Users/mutafvladimir/Documents/IT/dZENcode/.venv/lib/python3.12/site-packages/asgiref/current_thread_executor.py", line 40, in run
    result = self.fn(*self.args, **self.kwargs)
             ^^^^^^^^^^^^^^^^^^^^^^^^^^^^^^^^^^
  File "/Users/mutafvladimir/Documents/IT/dZENcode/.venv/lib/python3.12/site-packages/asgiref/sync.py", line 522, in thread_handler
    return func(*args, **kwargs)
           ^^^^^^^^^^^^^^^^^^^^^
  File "/Users/mutafvladimir/Documents/IT/dZENcode/.venv/lib/python3.12/site-packages/django/views/decorators/csrf.py", line 65, in _view_wrapper
    return view_func(request, *args, **kwargs)
           ^^^^^^^^^^^^^^^^^^^^^^^^^^^^^^^^^^^
  File "/Users/mutafvladimir/Documents/IT/dZENcode/.venv/lib/python3.12/site-packages/rest_framework/viewsets.py", line 125, in view
    return self.dispatch(request, *args, **kwargs)
           ^^^^^^^^^^^^^^^^^^^^^^^^^^^^^^^^^^^^^^^
  File "/Users/mutafvladimir/Documents/IT/dZENcode/.venv/lib/python3.12/site-packages/rest_framework/views.py", line 515, in dispatch
    response = self.handle_exception(exc)
               ^^^^^^^^^^^^^^^^^^^^^^^^^^
  File "/Users/mutafvladimir/Documents/IT/dZENcode/.venv/lib/python3.12/site-packages/rest_framework/views.py", line 475, in handle_exception
    self.raise_uncaught_exception(exc)
  File "/Users/mutafvladimir/Documents/IT/dZENcode/.venv/lib/python3.12/site-packages/rest_framework/views.py", line 486, in raise_uncaught_exception
    raise exc
  File "/Users/mutafvladimir/Documents/IT/dZENcode/.venv/lib/python3.12/site-packages/rest_framework/views.py", line 503, in dispatch
    self.initial(request, *args, **kwargs)
  File "/Users/mutafvladimir/Documents/IT/dZENcode/.venv/lib/python3.12/site-packages/rest_framework/views.py", line 420, in initial
    self.perform_authentication(request)
  File "/Users/mutafvladimir/Documents/IT/dZENcode/.venv/lib/python3.12/site-packages/rest_framework/views.py", line 330, in perform_authentication
    request.user
  File "/Users/mutafvladimir/Documents/IT/dZENcode/.venv/lib/python3.12/site-packages/rest_framework/request.py", line 232, in user
    self._authenticate()
  File "/Users/mutafvladimir/Documents/IT/dZENcode/.venv/lib/python3.12/site-packages/rest_framework/request.py", line 385, in _authenticate
    user_auth_tuple = authenticator.authenticate(self)
                      ^^^^^^^^^^^^^^^^^^^^^^^^^^^^^^^^
  File "/Users/mutafvladimir/Documents/IT/dZENcode/.venv/lib/python3.12/site-packages/rest_framework_simplejwt/authentication.py", line 51, in authenticate
    return self.get_user(validated_token), validated_token
           ^^^^^^^^^^^^^^^^^^^^^^^^^^^^^^
  File "/Users/mutafvladimir/Documents/IT/dZENcode/.venv/lib/python3.12/site-packages/rest_framework_simplejwt/authentication.py", line 130, in get_user
    user = self.user_model.objects.get(**{api_settings.USER_ID_FIELD: user_id})
           ^^^^^^^^^^^^^^^^^^^^^^^^^^^^^^^^^^^^^^^^^^^^^^^^^^^^^^^^^^^^^^^^^^^^
  File "/Users/mutafvladimir/Documents/IT/dZENcode/.venv/lib/python3.12/site-packages/django/db/models/manager.py", line 87, in manager_method
    return getattr(self.get_queryset(), name)(*args, **kwargs)
           ^^^^^^^^^^^^^^^^^^^^^^^^^^^^^^^^^^^^^^^^^^^^^^^^^^^
  File "/Users/mutafvladimir/Documents/IT/dZENcode/.venv/lib/python3.12/site-packages/django/db/models/query.py", line 629, in get
    num = len(clone)
          ^^^^^^^^^^
  File "/Users/mutafvladimir/Documents/IT/dZENcode/.venv/lib/python3.12/site-packages/django/db/models/query.py", line 366, in __len__
    self._fetch_all()
  File "/Users/mutafvladimir/Documents/IT/dZENcode/.venv/lib/python3.12/site-packages/django/db/models/query.py", line 1935, in _fetch_all
    self._result_cache = list(self._iterable_class(self))
                         ^^^^^^^^^^^^^^^^^^^^^^^^^^^^^^^^
  File "/Users/mutafvladimir/Documents/IT/dZENcode/.venv/lib/python3.12/site-packages/django/db/models/query.py", line 91, in __iter__
    results = compiler.execute_sql(
              ^^^^^^^^^^^^^^^^^^^^^
  File "/Users/mutafvladimir/Documents/IT/dZENcode/.venv/lib/python3.12/site-packages/django/db/models/sql/compiler.py", line 1620, in execute_sql
    cursor = self.connection.cursor()
             ^^^^^^^^^^^^^^^^^^^^^^^^
  File "/Users/mutafvladimir/Documents/IT/dZENcode/.venv/lib/python3.12/site-packages/django/utils/asyncio.py", line 26, in inner
    return func(*args, **kwargs)
           ^^^^^^^^^^^^^^^^^^^^^
  File "/Users/mutafvladimir/Documents/IT/dZENcode/.venv/lib/python3.12/site-packages/django/db/backends/base/base.py", line 320, in cursor
    return self._cursor()
           ^^^^^^^^^^^^^^
  File "/Users/mutafvladimir/Documents/IT/dZENcode/.venv/lib/python3.12/site-packages/django/db/backends/base/base.py", line 296, in _cursor
    self.ensure_connection()
  File "/Users/mutafvladimir/Documents/IT/dZENcode/.venv/lib/python3.12/site-packages/django/utils/asyncio.py", line 26, in inner
    return func(*args, **kwargs)
           ^^^^^^^^^^^^^^^^^^^^^
  File "/Users/mutafvladimir/Documents/IT/dZENcode/.venv/lib/python3.12/site-packages/django/db/backends/base/base.py", line 278, in ensure_connection
    with self.wrap_database_errors:
         ^^^^^^^^^^^^^^^^^^^^^^^^^
  File "/Users/mutafvladimir/Documents/IT/dZENcode/.venv/lib/python3.12/site-packages/django/db/utils.py", line 91, in __exit__
    raise dj_exc_value.with_traceback(traceback) from exc_value
  File "/Users/mutafvladimir/Documents/IT/dZENcode/.venv/lib/python3.12/site-packages/django/db/backends/base/base.py", line 279, in ensure_connection
    self.connect()
  File "/Users/mutafvladimir/Documents/IT/dZENcode/.venv/lib/python3.12/site-packages/django/utils/asyncio.py", line 26, in inner
    return func(*args, **kwargs)
           ^^^^^^^^^^^^^^^^^^^^^
  File "/Users/mutafvladimir/Documents/IT/dZENcode/.venv/lib/python3.12/site-packages/django/db/backends/base/base.py", line 256, in connect
    self.connection = self.get_new_connection(conn_params)
                      ^^^^^^^^^^^^^^^^^^^^^^^^^^^^^^^^^^^^
  File "/Users/mutafvladimir/Documents/IT/dZENcode/.venv/lib/python3.12/site-packages/django/utils/asyncio.py", line 26, in inner
    return func(*args, **kwargs)
           ^^^^^^^^^^^^^^^^^^^^^
  File "/Users/mutafvladimir/Documents/IT/dZENcode/.venv/lib/python3.12/site-packages/django/db/backends/mysql/base.py", line 256, in get_new_connection
    connection = Database.connect(**conn_params)
                 ^^^^^^^^^^^^^^^^^^^^^^^^^^^^^^^
  File "/Users/mutafvladimir/Documents/IT/dZENcode/.venv/lib/python3.12/site-packages/MySQLdb/__init__.py", line 121, in Connect
    return Connection(*args, **kwargs)
           ^^^^^^^^^^^^^^^^^^^^^^^^^^^
  File "/Users/mutafvladimir/Documents/IT/dZENcode/.venv/lib/python3.12/site-packages/MySQLdb/connections.py", line 200, in __init__
    super().__init__(*args, **kwargs2)
django.db.utils.OperationalError: (2002, "Can't connect to local MySQL server through socket '/tmp/mysql.sock' (2)")
[2025-04-29 14:59:05,750] WARNING django.request Not Found: /ws/comments/
d for middleware whitenoise.middleware.WhiteNoiseMiddleware.
[2025-04-29 14:59:48,934] WARNING django.request Not Found: /ws/comments/
d for middleware whitenoise.middleware.WhiteNoiseMiddleware.
[2025-04-29 15:00:30,774] DEBUG django.request Asynchronous handler adapted for middleware whitenoise.middleware.WhiteNoiseMiddleware.
[2025-04-29 15:00:44,285] ERROR django.request Internal Server Error: /api/v1/comments/comments/
Traceback (most recent call last):
  File "/Users/mutafvladimir/Documents/IT/dZENcode/.venv/lib/python3.12/site-packages/django/db/backends/base/base.py", line 279, in ensure_connection
    self.connect()
  File "/Users/mutafvladimir/Documents/IT/dZENcode/.venv/lib/python3.12/site-packages/django/utils/asyncio.py", line 26, in inner
    return func(*args, **kwargs)
           ^^^^^^^^^^^^^^^^^^^^^
  File "/Users/mutafvladimir/Documents/IT/dZENcode/.venv/lib/python3.12/site-packages/django/db/backends/base/base.py", line 256, in connect
    self.connection = self.get_new_connection(conn_params)
                      ^^^^^^^^^^^^^^^^^^^^^^^^^^^^^^^^^^^^
  File "/Users/mutafvladimir/Documents/IT/dZENcode/.venv/lib/python3.12/site-packages/django/utils/asyncio.py", line 26, in inner
    return func(*args, **kwargs)
           ^^^^^^^^^^^^^^^^^^^^^
  File "/Users/mutafvladimir/Documents/IT/dZENcode/.venv/lib/python3.12/site-packages/django/db/backends/mysql/base.py", line 256, in get_new_connection
    connection = Database.connect(**conn_params)
                 ^^^^^^^^^^^^^^^^^^^^^^^^^^^^^^^
  File "/Users/mutafvladimir/Documents/IT/dZENcode/.venv/lib/python3.12/site-packages/MySQLdb/__init__.py", line 121, in Connect
    return Connection(*args, **kwargs)
           ^^^^^^^^^^^^^^^^^^^^^^^^^^^
  File "/Users/mutafvladimir/Documents/IT/dZENcode/.venv/lib/python3.12/site-packages/MySQLdb/connections.py", line 200, in __init__
    super().__init__(*args, **kwargs2)
MySQLdb.OperationalError: (2002, "Can't connect to local MySQL server through socket '/tmp/mysql.sock' (2)")

The above exception was the direct cause of the following exception:

Traceback (most recent call last):
  File "/Users/mutafvladimir/Documents/IT/dZENcode/.venv/lib/python3.12/site-packages/asgiref/sync.py", line 518, in thread_handler
    raise exc_info[1]
  File "/Users/mutafvladimir/Documents/IT/dZENcode/.venv/lib/python3.12/site-packages/django/core/handlers/exception.py", line 42, in inner
    response = await get_response(request)
               ^^^^^^^^^^^^^^^^^^^^^^^^^^^
  File "/Users/mutafvladimir/Documents/IT/dZENcode/.venv/lib/python3.12/site-packages/asgiref/sync.py", line 518, in thread_handler
    raise exc_info[1]
  File "/Users/mutafvladimir/Documents/IT/dZENcode/.venv/lib/python3.12/site-packages/django/core/handlers/base.py", line 253, in _get_response_async
    response = await wrapped_callback(
               ^^^^^^^^^^^^^^^^^^^^^^^
  File "/Users/mutafvladimir/Documents/IT/dZENcode/.venv/lib/python3.12/site-packages/asgiref/sync.py", line 468, in __call__
    ret = await asyncio.shield(exec_coro)
          ^^^^^^^^^^^^^^^^^^^^^^^^^^^^^^^
  File "/Users/mutafvladimir/Documents/IT/dZENcode/.venv/lib/python3.12/site-packages/asgiref/current_thread_executor.py", line 40, in run
    result = self.fn(*self.args, **self.kwargs)
             ^^^^^^^^^^^^^^^^^^^^^^^^^^^^^^^^^^
  File "/Users/mutafvladimir/Documents/IT/dZENcode/.venv/lib/python3.12/site-packages/asgiref/sync.py", line 522, in thread_handler
    return func(*args, **kwargs)
           ^^^^^^^^^^^^^^^^^^^^^
  File "/Users/mutafvladimir/Documents/IT/dZENcode/.venv/lib/python3.12/site-packages/django/views/decorators/csrf.py", line 65, in _view_wrapper
    return view_func(request, *args, **kwargs)
           ^^^^^^^^^^^^^^^^^^^^^^^^^^^^^^^^^^^
  File "/Users/mutafvladimir/Documents/IT/dZENcode/.venv/lib/python3.12/site-packages/rest_framework/viewsets.py", line 125, in view
    return self.dispatch(request, *args, **kwargs)
           ^^^^^^^^^^^^^^^^^^^^^^^^^^^^^^^^^^^^^^^
  File "/Users/mutafvladimir/Documents/IT/dZENcode/.venv/lib/python3.12/site-packages/rest_framework/views.py", line 515, in dispatch
    response = self.handle_exception(exc)
               ^^^^^^^^^^^^^^^^^^^^^^^^^^
  File "/Users/mutafvladimir/Documents/IT/dZENcode/.venv/lib/python3.12/site-packages/rest_framework/views.py", line 475, in handle_exception
    self.raise_uncaught_exception(exc)
  File "/Users/mutafvladimir/Documents/IT/dZENcode/.venv/lib/python3.12/site-packages/rest_framework/views.py", line 486, in raise_uncaught_exception
    raise exc
  File "/Users/mutafvladimir/Documents/IT/dZENcode/.venv/lib/python3.12/site-packages/rest_framework/views.py", line 512, in dispatch
    response = handler(request, *args, **kwargs)
               ^^^^^^^^^^^^^^^^^^^^^^^^^^^^^^^^^
  File "/Users/mutafvladimir/Documents/IT/dZENcode/.venv/lib/python3.12/site-packages/rest_framework/mixins.py", line 40, in list
    page = self.paginate_queryset(queryset)
           ^^^^^^^^^^^^^^^^^^^^^^^^^^^^^^^^
  File "/Users/mutafvladimir/Documents/IT/dZENcode/.venv/lib/python3.12/site-packages/rest_framework/generics.py", line 175, in paginate_queryset
    return self.paginator.paginate_queryset(queryset, self.request, view=self)
           ^^^^^^^^^^^^^^^^^^^^^^^^^^^^^^^^^^^^^^^^^^^^^^^^^^^^^^^^^^^^^^^^^^^
  File "/Users/mutafvladimir/Documents/IT/dZENcode/.venv/lib/python3.12/site-packages/rest_framework/pagination.py", line 211, in paginate_queryset
    self.page = paginator.page(page_number)
                ^^^^^^^^^^^^^^^^^^^^^^^^^^^
  File "/Users/mutafvladimir/Documents/IT/dZENcode/.venv/lib/python3.12/site-packages/django/core/paginator.py", line 89, in page
    number = self.validate_number(number)
             ^^^^^^^^^^^^^^^^^^^^^^^^^^^^
  File "/Users/mutafvladimir/Documents/IT/dZENcode/.venv/lib/python3.12/site-packages/django/core/paginator.py", line 70, in validate_number
    if number > self.num_pages:
                ^^^^^^^^^^^^^^
  File "/Users/mutafvladimir/Documents/IT/dZENcode/.venv/lib/python3.12/site-packages/django/utils/functional.py", line 47, in __get__
    res = instance.__dict__[self.name] = self.func(instance)
                                         ^^^^^^^^^^^^^^^^^^^
  File "/Users/mutafvladimir/Documents/IT/dZENcode/.venv/lib/python3.12/site-packages/django/core/paginator.py", line 116, in num_pages
    if self.count == 0 and not self.allow_empty_first_page:
       ^^^^^^^^^^
  File "/Users/mutafvladimir/Documents/IT/dZENcode/.venv/lib/python3.12/site-packages/django/utils/functional.py", line 47, in __get__
    res = instance.__dict__[self.name] = self.func(instance)
                                         ^^^^^^^^^^^^^^^^^^^
  File "/Users/mutafvladimir/Documents/IT/dZENcode/.venv/lib/python3.12/site-packages/django/core/paginator.py", line 110, in count
    return c()
           ^^^
  File "/Users/mutafvladimir/Documents/IT/dZENcode/.venv/lib/python3.12/site-packages/django/db/models/query.py", line 604, in count
    return self.query.get_count(using=self.db)
           ^^^^^^^^^^^^^^^^^^^^^^^^^^^^^^^^^^^
  File "/Users/mutafvladimir/Documents/IT/dZENcode/.venv/lib/python3.12/site-packages/django/db/models/sql/query.py", line 644, in get_count
    return obj.get_aggregation(using, {"__count": Count("*")})["__count"]
           ^^^^^^^^^^^^^^^^^^^^^^^^^^^^^^^^^^^^^^^^^^^^^^^^^^^
  File "/Users/mutafvladimir/Documents/IT/dZENcode/.venv/lib/python3.12/site-packages/django/db/models/sql/query.py", line 626, in get_aggregation
    result = compiler.execute_sql(SINGLE)
             ^^^^^^^^^^^^^^^^^^^^^^^^^^^^
  File "/Users/mutafvladimir/Documents/IT/dZENcode/.venv/lib/python3.12/site-packages/django/db/models/sql/compiler.py", line 1620, in execute_sql
    cursor = self.connection.cursor()
             ^^^^^^^^^^^^^^^^^^^^^^^^
  File "/Users/mutafvladimir/Documents/IT/dZENcode/.venv/lib/python3.12/site-packages/django/utils/asyncio.py", line 26, in inner
    return func(*args, **kwargs)
           ^^^^^^^^^^^^^^^^^^^^^
  File "/Users/mutafvladimir/Documents/IT/dZENcode/.venv/lib/python3.12/site-packages/django/db/backends/base/base.py", line 320, in cursor
    return self._cursor()
           ^^^^^^^^^^^^^^
  File "/Users/mutafvladimir/Documents/IT/dZENcode/.venv/lib/python3.12/site-packages/django/db/backends/base/base.py", line 296, in _cursor
    self.ensure_connection()
  File "/Users/mutafvladimir/Documents/IT/dZENcode/.venv/lib/python3.12/site-packages/django/utils/asyncio.py", line 26, in inner
    return func(*args, **kwargs)
           ^^^^^^^^^^^^^^^^^^^^^
  File "/Users/mutafvladimir/Documents/IT/dZENcode/.venv/lib/python3.12/site-packages/django/db/backends/base/base.py", line 278, in ensure_connection
    with self.wrap_database_errors:
         ^^^^^^^^^^^^^^^^^^^^^^^^^
  File "/Users/mutafvladimir/Documents/IT/dZENcode/.venv/lib/python3.12/site-packages/django/db/utils.py", line 91, in __exit__
    raise dj_exc_value.with_traceback(traceback) from exc_value
  File "/Users/mutafvladimir/Documents/IT/dZENcode/.venv/lib/python3.12/site-packages/django/db/backends/base/base.py", line 279, in ensure_connection
    self.connect()
  File "/Users/mutafvladimir/Documents/IT/dZENcode/.venv/lib/python3.12/site-packages/django/utils/asyncio.py", line 26, in inner
    return func(*args, **kwargs)
           ^^^^^^^^^^^^^^^^^^^^^
  File "/Users/mutafvladimir/Documents/IT/dZENcode/.venv/lib/python3.12/site-packages/django/db/backends/base/base.py", line 256, in connect
    self.connection = self.get_new_connection(conn_params)
                      ^^^^^^^^^^^^^^^^^^^^^^^^^^^^^^^^^^^^
  File "/Users/mutafvladimir/Documents/IT/dZENcode/.venv/lib/python3.12/site-packages/django/utils/asyncio.py", line 26, in inner
    return func(*args, **kwargs)
           ^^^^^^^^^^^^^^^^^^^^^
  File "/Users/mutafvladimir/Documents/IT/dZENcode/.venv/lib/python3.12/site-packages/django/db/backends/mysql/base.py", line 256, in get_new_connection
    connection = Database.connect(**conn_params)
                 ^^^^^^^^^^^^^^^^^^^^^^^^^^^^^^^
  File "/Users/mutafvladimir/Documents/IT/dZENcode/.venv/lib/python3.12/site-packages/MySQLdb/__init__.py", line 121, in Connect
    return Connection(*args, **kwargs)
           ^^^^^^^^^^^^^^^^^^^^^^^^^^^
  File "/Users/mutafvladimir/Documents/IT/dZENcode/.venv/lib/python3.12/site-packages/MySQLdb/connections.py", line 200, in __init__
    super().__init__(*args, **kwargs2)
django.db.utils.OperationalError: (2002, "Can't connect to local MySQL server through socket '/tmp/mysql.sock' (2)")
[2025-04-29 15:01:00,681] DEBUG django.request Asynchronous handler adapted for middleware whitenoise.middleware.WhiteNoiseMiddleware.
[2025-04-29 15:01:27,745] ERROR django.request Internal Server Error: /api/v1/comments/comments/
Traceback (most recent call last):
  File "/Users/mutafvladimir/Documents/IT/dZENcode/.venv/lib/python3.12/site-packages/django/db/backends/base/base.py", line 279, in ensure_connection
    self.connect()
  File "/Users/mutafvladimir/Documents/IT/dZENcode/.venv/lib/python3.12/site-packages/django/utils/asyncio.py", line 26, in inner
    return func(*args, **kwargs)
           ^^^^^^^^^^^^^^^^^^^^^
  File "/Users/mutafvladimir/Documents/IT/dZENcode/.venv/lib/python3.12/site-packages/django/db/backends/base/base.py", line 256, in connect
    self.connection = self.get_new_connection(conn_params)
                      ^^^^^^^^^^^^^^^^^^^^^^^^^^^^^^^^^^^^
  File "/Users/mutafvladimir/Documents/IT/dZENcode/.venv/lib/python3.12/site-packages/django/utils/asyncio.py", line 26, in inner
    return func(*args, **kwargs)
           ^^^^^^^^^^^^^^^^^^^^^
  File "/Users/mutafvladimir/Documents/IT/dZENcode/.venv/lib/python3.12/site-packages/django/db/backends/mysql/base.py", line 256, in get_new_connection
    connection = Database.connect(**conn_params)
                 ^^^^^^^^^^^^^^^^^^^^^^^^^^^^^^^
  File "/Users/mutafvladimir/Documents/IT/dZENcode/.venv/lib/python3.12/site-packages/MySQLdb/__init__.py", line 121, in Connect
    return Connection(*args, **kwargs)
           ^^^^^^^^^^^^^^^^^^^^^^^^^^^
  File "/Users/mutafvladimir/Documents/IT/dZENcode/.venv/lib/python3.12/site-packages/MySQLdb/connections.py", line 200, in __init__
    super().__init__(*args, **kwargs2)
MySQLdb.OperationalError: (2002, "Can't connect to local MySQL server through socket '/tmp/mysql.sock' (2)")

The above exception was the direct cause of the following exception:

Traceback (most recent call last):
  File "/Users/mutafvladimir/Documents/IT/dZENcode/.venv/lib/python3.12/site-packages/asgiref/sync.py", line 518, in thread_handler
    raise exc_info[1]
  File "/Users/mutafvladimir/Documents/IT/dZENcode/.venv/lib/python3.12/site-packages/django/core/handlers/exception.py", line 42, in inner
    response = await get_response(request)
               ^^^^^^^^^^^^^^^^^^^^^^^^^^^
  File "/Users/mutafvladimir/Documents/IT/dZENcode/.venv/lib/python3.12/site-packages/asgiref/sync.py", line 518, in thread_handler
    raise exc_info[1]
  File "/Users/mutafvladimir/Documents/IT/dZENcode/.venv/lib/python3.12/site-packages/django/core/handlers/base.py", line 253, in _get_response_async
    response = await wrapped_callback(
               ^^^^^^^^^^^^^^^^^^^^^^^
  File "/Users/mutafvladimir/Documents/IT/dZENcode/.venv/lib/python3.12/site-packages/asgiref/sync.py", line 468, in __call__
    ret = await asyncio.shield(exec_coro)
          ^^^^^^^^^^^^^^^^^^^^^^^^^^^^^^^
  File "/Users/mutafvladimir/Documents/IT/dZENcode/.venv/lib/python3.12/site-packages/asgiref/current_thread_executor.py", line 40, in run
    result = self.fn(*self.args, **self.kwargs)
             ^^^^^^^^^^^^^^^^^^^^^^^^^^^^^^^^^^
  File "/Users/mutafvladimir/Documents/IT/dZENcode/.venv/lib/python3.12/site-packages/asgiref/sync.py", line 522, in thread_handler
    return func(*args, **kwargs)
           ^^^^^^^^^^^^^^^^^^^^^
  File "/Users/mutafvladimir/Documents/IT/dZENcode/.venv/lib/python3.12/site-packages/django/views/decorators/csrf.py", line 65, in _view_wrapper
    return view_func(request, *args, **kwargs)
           ^^^^^^^^^^^^^^^^^^^^^^^^^^^^^^^^^^^
  File "/Users/mutafvladimir/Documents/IT/dZENcode/.venv/lib/python3.12/site-packages/rest_framework/viewsets.py", line 125, in view
    return self.dispatch(request, *args, **kwargs)
           ^^^^^^^^^^^^^^^^^^^^^^^^^^^^^^^^^^^^^^^
  File "/Users/mutafvladimir/Documents/IT/dZENcode/.venv/lib/python3.12/site-packages/rest_framework/views.py", line 515, in dispatch
    response = self.handle_exception(exc)
               ^^^^^^^^^^^^^^^^^^^^^^^^^^
  File "/Users/mutafvladimir/Documents/IT/dZENcode/.venv/lib/python3.12/site-packages/rest_framework/views.py", line 475, in handle_exception
    self.raise_uncaught_exception(exc)
  File "/Users/mutafvladimir/Documents/IT/dZENcode/.venv/lib/python3.12/site-packages/rest_framework/views.py", line 486, in raise_uncaught_exception
    raise exc
  File "/Users/mutafvladimir/Documents/IT/dZENcode/.venv/lib/python3.12/site-packages/rest_framework/views.py", line 503, in dispatch
    self.initial(request, *args, **kwargs)
  File "/Users/mutafvladimir/Documents/IT/dZENcode/.venv/lib/python3.12/site-packages/rest_framework/views.py", line 420, in initial
    self.perform_authentication(request)
  File "/Users/mutafvladimir/Documents/IT/dZENcode/.venv/lib/python3.12/site-packages/rest_framework/views.py", line 330, in perform_authentication
    request.user
  File "/Users/mutafvladimir/Documents/IT/dZENcode/.venv/lib/python3.12/site-packages/rest_framework/request.py", line 232, in user
    self._authenticate()
  File "/Users/mutafvladimir/Documents/IT/dZENcode/.venv/lib/python3.12/site-packages/rest_framework/request.py", line 385, in _authenticate
    user_auth_tuple = authenticator.authenticate(self)
                      ^^^^^^^^^^^^^^^^^^^^^^^^^^^^^^^^
  File "/Users/mutafvladimir/Documents/IT/dZENcode/.venv/lib/python3.12/site-packages/rest_framework_simplejwt/authentication.py", line 51, in authenticate
    return self.get_user(validated_token), validated_token
           ^^^^^^^^^^^^^^^^^^^^^^^^^^^^^^
  File "/Users/mutafvladimir/Documents/IT/dZENcode/.venv/lib/python3.12/site-packages/rest_framework_simplejwt/authentication.py", line 130, in get_user
    user = self.user_model.objects.get(**{api_settings.USER_ID_FIELD: user_id})
           ^^^^^^^^^^^^^^^^^^^^^^^^^^^^^^^^^^^^^^^^^^^^^^^^^^^^^^^^^^^^^^^^^^^^
  File "/Users/mutafvladimir/Documents/IT/dZENcode/.venv/lib/python3.12/site-packages/django/db/models/manager.py", line 87, in manager_method
    return getattr(self.get_queryset(), name)(*args, **kwargs)
           ^^^^^^^^^^^^^^^^^^^^^^^^^^^^^^^^^^^^^^^^^^^^^^^^^^^
  File "/Users/mutafvladimir/Documents/IT/dZENcode/.venv/lib/python3.12/site-packages/django/db/models/query.py", line 629, in get
    num = len(clone)
          ^^^^^^^^^^
  File "/Users/mutafvladimir/Documents/IT/dZENcode/.venv/lib/python3.12/site-packages/django/db/models/query.py", line 366, in __len__
    self._fetch_all()
  File "/Users/mutafvladimir/Documents/IT/dZENcode/.venv/lib/python3.12/site-packages/django/db/models/query.py", line 1935, in _fetch_all
    self._result_cache = list(self._iterable_class(self))
                         ^^^^^^^^^^^^^^^^^^^^^^^^^^^^^^^^
  File "/Users/mutafvladimir/Documents/IT/dZENcode/.venv/lib/python3.12/site-packages/django/db/models/query.py", line 91, in __iter__
    results = compiler.execute_sql(
              ^^^^^^^^^^^^^^^^^^^^^
  File "/Users/mutafvladimir/Documents/IT/dZENcode/.venv/lib/python3.12/site-packages/django/db/models/sql/compiler.py", line 1620, in execute_sql
    cursor = self.connection.cursor()
             ^^^^^^^^^^^^^^^^^^^^^^^^
  File "/Users/mutafvladimir/Documents/IT/dZENcode/.venv/lib/python3.12/site-packages/django/utils/asyncio.py", line 26, in inner
    return func(*args, **kwargs)
           ^^^^^^^^^^^^^^^^^^^^^
  File "/Users/mutafvladimir/Documents/IT/dZENcode/.venv/lib/python3.12/site-packages/django/db/backends/base/base.py", line 320, in cursor
    return self._cursor()
           ^^^^^^^^^^^^^^
  File "/Users/mutafvladimir/Documents/IT/dZENcode/.venv/lib/python3.12/site-packages/django/db/backends/base/base.py", line 296, in _cursor
    self.ensure_connection()
  File "/Users/mutafvladimir/Documents/IT/dZENcode/.venv/lib/python3.12/site-packages/django/utils/asyncio.py", line 26, in inner
    return func(*args, **kwargs)
           ^^^^^^^^^^^^^^^^^^^^^
  File "/Users/mutafvladimir/Documents/IT/dZENcode/.venv/lib/python3.12/site-packages/django/db/backends/base/base.py", line 278, in ensure_connection
    with self.wrap_database_errors:
         ^^^^^^^^^^^^^^^^^^^^^^^^^
  File "/Users/mutafvladimir/Documents/IT/dZENcode/.venv/lib/python3.12/site-packages/django/db/utils.py", line 91, in __exit__
    raise dj_exc_value.with_traceback(traceback) from exc_value
  File "/Users/mutafvladimir/Documents/IT/dZENcode/.venv/lib/python3.12/site-packages/django/db/backends/base/base.py", line 279, in ensure_connection
    self.connect()
  File "/Users/mutafvladimir/Documents/IT/dZENcode/.venv/lib/python3.12/site-packages/django/utils/asyncio.py", line 26, in inner
    return func(*args, **kwargs)
           ^^^^^^^^^^^^^^^^^^^^^
  File "/Users/mutafvladimir/Documents/IT/dZENcode/.venv/lib/python3.12/site-packages/django/db/backends/base/base.py", line 256, in connect
    self.connection = self.get_new_connection(conn_params)
                      ^^^^^^^^^^^^^^^^^^^^^^^^^^^^^^^^^^^^
  File "/Users/mutafvladimir/Documents/IT/dZENcode/.venv/lib/python3.12/site-packages/django/utils/asyncio.py", line 26, in inner
    return func(*args, **kwargs)
           ^^^^^^^^^^^^^^^^^^^^^
  File "/Users/mutafvladimir/Documents/IT/dZENcode/.venv/lib/python3.12/site-packages/django/db/backends/mysql/base.py", line 256, in get_new_connection
    connection = Database.connect(**conn_params)
                 ^^^^^^^^^^^^^^^^^^^^^^^^^^^^^^^
  File "/Users/mutafvladimir/Documents/IT/dZENcode/.venv/lib/python3.12/site-packages/MySQLdb/__init__.py", line 121, in Connect
    return Connection(*args, **kwargs)
           ^^^^^^^^^^^^^^^^^^^^^^^^^^^
  File "/Users/mutafvladimir/Documents/IT/dZENcode/.venv/lib/python3.12/site-packages/MySQLdb/connections.py", line 200, in __init__
    super().__init__(*args, **kwargs2)
django.db.utils.OperationalError: (2002, "Can't connect to local MySQL server through socket '/tmp/mysql.sock' (2)")
[2025-04-29 15:04:20,447] ERROR django.request Internal Server Error: /api/v1/comments/comments/
Traceback (most recent call last):
  File "/Users/mutafvladimir/Documents/IT/dZENcode/.venv/lib/python3.12/site-packages/django/db/backends/base/base.py", line 279, in ensure_connection
    self.connect()
  File "/Users/mutafvladimir/Documents/IT/dZENcode/.venv/lib/python3.12/site-packages/django/utils/asyncio.py", line 26, in inner
    return func(*args, **kwargs)
           ^^^^^^^^^^^^^^^^^^^^^
  File "/Users/mutafvladimir/Documents/IT/dZENcode/.venv/lib/python3.12/site-packages/django/db/backends/base/base.py", line 256, in connect
    self.connection = self.get_new_connection(conn_params)
                      ^^^^^^^^^^^^^^^^^^^^^^^^^^^^^^^^^^^^
  File "/Users/mutafvladimir/Documents/IT/dZENcode/.venv/lib/python3.12/site-packages/django/utils/asyncio.py", line 26, in inner
    return func(*args, **kwargs)
           ^^^^^^^^^^^^^^^^^^^^^
  File "/Users/mutafvladimir/Documents/IT/dZENcode/.venv/lib/python3.12/site-packages/django/db/backends/mysql/base.py", line 256, in get_new_connection
    connection = Database.connect(**conn_params)
                 ^^^^^^^^^^^^^^^^^^^^^^^^^^^^^^^
  File "/Users/mutafvladimir/Documents/IT/dZENcode/.venv/lib/python3.12/site-packages/MySQLdb/__init__.py", line 121, in Connect
    return Connection(*args, **kwargs)
           ^^^^^^^^^^^^^^^^^^^^^^^^^^^
  File "/Users/mutafvladimir/Documents/IT/dZENcode/.venv/lib/python3.12/site-packages/MySQLdb/connections.py", line 200, in __init__
    super().__init__(*args, **kwargs2)
MySQLdb.OperationalError: (2002, "Can't connect to local MySQL server through socket '/tmp/mysql.sock' (2)")

The above exception was the direct cause of the following exception:

Traceback (most recent call last):
  File "/Users/mutafvladimir/Documents/IT/dZENcode/.venv/lib/python3.12/site-packages/asgiref/sync.py", line 518, in thread_handler
    raise exc_info[1]
  File "/Users/mutafvladimir/Documents/IT/dZENcode/.venv/lib/python3.12/site-packages/django/core/handlers/exception.py", line 42, in inner
    response = await get_response(request)
               ^^^^^^^^^^^^^^^^^^^^^^^^^^^
  File "/Users/mutafvladimir/Documents/IT/dZENcode/.venv/lib/python3.12/site-packages/asgiref/sync.py", line 518, in thread_handler
    raise exc_info[1]
  File "/Users/mutafvladimir/Documents/IT/dZENcode/.venv/lib/python3.12/site-packages/django/core/handlers/base.py", line 253, in _get_response_async
    response = await wrapped_callback(
               ^^^^^^^^^^^^^^^^^^^^^^^
  File "/Users/mutafvladimir/Documents/IT/dZENcode/.venv/lib/python3.12/site-packages/asgiref/sync.py", line 468, in __call__
    ret = await asyncio.shield(exec_coro)
          ^^^^^^^^^^^^^^^^^^^^^^^^^^^^^^^
  File "/Users/mutafvladimir/Documents/IT/dZENcode/.venv/lib/python3.12/site-packages/asgiref/current_thread_executor.py", line 40, in run
    result = self.fn(*self.args, **self.kwargs)
             ^^^^^^^^^^^^^^^^^^^^^^^^^^^^^^^^^^
  File "/Users/mutafvladimir/Documents/IT/dZENcode/.venv/lib/python3.12/site-packages/asgiref/sync.py", line 522, in thread_handler
    return func(*args, **kwargs)
           ^^^^^^^^^^^^^^^^^^^^^
  File "/Users/mutafvladimir/Documents/IT/dZENcode/.venv/lib/python3.12/site-packages/django/views/decorators/csrf.py", line 65, in _view_wrapper
    return view_func(request, *args, **kwargs)
           ^^^^^^^^^^^^^^^^^^^^^^^^^^^^^^^^^^^
  File "/Users/mutafvladimir/Documents/IT/dZENcode/.venv/lib/python3.12/site-packages/rest_framework/viewsets.py", line 125, in view
    return self.dispatch(request, *args, **kwargs)
           ^^^^^^^^^^^^^^^^^^^^^^^^^^^^^^^^^^^^^^^
  File "/Users/mutafvladimir/Documents/IT/dZENcode/.venv/lib/python3.12/site-packages/rest_framework/views.py", line 515, in dispatch
    response = self.handle_exception(exc)
               ^^^^^^^^^^^^^^^^^^^^^^^^^^
  File "/Users/mutafvladimir/Documents/IT/dZENcode/.venv/lib/python3.12/site-packages/rest_framework/views.py", line 475, in handle_exception
    self.raise_uncaught_exception(exc)
  File "/Users/mutafvladimir/Documents/IT/dZENcode/.venv/lib/python3.12/site-packages/rest_framework/views.py", line 486, in raise_uncaught_exception
    raise exc
  File "/Users/mutafvladimir/Documents/IT/dZENcode/.venv/lib/python3.12/site-packages/rest_framework/views.py", line 503, in dispatch
    self.initial(request, *args, **kwargs)
  File "/Users/mutafvladimir/Documents/IT/dZENcode/.venv/lib/python3.12/site-packages/rest_framework/views.py", line 420, in initial
    self.perform_authentication(request)
  File "/Users/mutafvladimir/Documents/IT/dZENcode/.venv/lib/python3.12/site-packages/rest_framework/views.py", line 330, in perform_authentication
    request.user
  File "/Users/mutafvladimir/Documents/IT/dZENcode/.venv/lib/python3.12/site-packages/rest_framework/request.py", line 232, in user
    self._authenticate()
  File "/Users/mutafvladimir/Documents/IT/dZENcode/.venv/lib/python3.12/site-packages/rest_framework/request.py", line 385, in _authenticate
    user_auth_tuple = authenticator.authenticate(self)
                      ^^^^^^^^^^^^^^^^^^^^^^^^^^^^^^^^
  File "/Users/mutafvladimir/Documents/IT/dZENcode/.venv/lib/python3.12/site-packages/rest_framework_simplejwt/authentication.py", line 51, in authenticate
    return self.get_user(validated_token), validated_token
           ^^^^^^^^^^^^^^^^^^^^^^^^^^^^^^
  File "/Users/mutafvladimir/Documents/IT/dZENcode/.venv/lib/python3.12/site-packages/rest_framework_simplejwt/authentication.py", line 130, in get_user
    user = self.user_model.objects.get(**{api_settings.USER_ID_FIELD: user_id})
           ^^^^^^^^^^^^^^^^^^^^^^^^^^^^^^^^^^^^^^^^^^^^^^^^^^^^^^^^^^^^^^^^^^^^
  File "/Users/mutafvladimir/Documents/IT/dZENcode/.venv/lib/python3.12/site-packages/django/db/models/manager.py", line 87, in manager_method
    return getattr(self.get_queryset(), name)(*args, **kwargs)
           ^^^^^^^^^^^^^^^^^^^^^^^^^^^^^^^^^^^^^^^^^^^^^^^^^^^
  File "/Users/mutafvladimir/Documents/IT/dZENcode/.venv/lib/python3.12/site-packages/django/db/models/query.py", line 629, in get
    num = len(clone)
          ^^^^^^^^^^
  File "/Users/mutafvladimir/Documents/IT/dZENcode/.venv/lib/python3.12/site-packages/django/db/models/query.py", line 366, in __len__
    self._fetch_all()
  File "/Users/mutafvladimir/Documents/IT/dZENcode/.venv/lib/python3.12/site-packages/django/db/models/query.py", line 1935, in _fetch_all
    self._result_cache = list(self._iterable_class(self))
                         ^^^^^^^^^^^^^^^^^^^^^^^^^^^^^^^^
  File "/Users/mutafvladimir/Documents/IT/dZENcode/.venv/lib/python3.12/site-packages/django/db/models/query.py", line 91, in __iter__
    results = compiler.execute_sql(
              ^^^^^^^^^^^^^^^^^^^^^
  File "/Users/mutafvladimir/Documents/IT/dZENcode/.venv/lib/python3.12/site-packages/django/db/models/sql/compiler.py", line 1620, in execute_sql
    cursor = self.connection.cursor()
             ^^^^^^^^^^^^^^^^^^^^^^^^
  File "/Users/mutafvladimir/Documents/IT/dZENcode/.venv/lib/python3.12/site-packages/django/utils/asyncio.py", line 26, in inner
    return func(*args, **kwargs)
           ^^^^^^^^^^^^^^^^^^^^^
  File "/Users/mutafvladimir/Documents/IT/dZENcode/.venv/lib/python3.12/site-packages/django/db/backends/base/base.py", line 320, in cursor
    return self._cursor()
           ^^^^^^^^^^^^^^
  File "/Users/mutafvladimir/Documents/IT/dZENcode/.venv/lib/python3.12/site-packages/django/db/backends/base/base.py", line 296, in _cursor
    self.ensure_connection()
  File "/Users/mutafvladimir/Documents/IT/dZENcode/.venv/lib/python3.12/site-packages/django/utils/asyncio.py", line 26, in inner
    return func(*args, **kwargs)
           ^^^^^^^^^^^^^^^^^^^^^
  File "/Users/mutafvladimir/Documents/IT/dZENcode/.venv/lib/python3.12/site-packages/django/db/backends/base/base.py", line 278, in ensure_connection
    with self.wrap_database_errors:
         ^^^^^^^^^^^^^^^^^^^^^^^^^
  File "/Users/mutafvladimir/Documents/IT/dZENcode/.venv/lib/python3.12/site-packages/django/db/utils.py", line 91, in __exit__
    raise dj_exc_value.with_traceback(traceback) from exc_value
  File "/Users/mutafvladimir/Documents/IT/dZENcode/.venv/lib/python3.12/site-packages/django/db/backends/base/base.py", line 279, in ensure_connection
    self.connect()
  File "/Users/mutafvladimir/Documents/IT/dZENcode/.venv/lib/python3.12/site-packages/django/utils/asyncio.py", line 26, in inner
    return func(*args, **kwargs)
           ^^^^^^^^^^^^^^^^^^^^^
  File "/Users/mutafvladimir/Documents/IT/dZENcode/.venv/lib/python3.12/site-packages/django/db/backends/base/base.py", line 256, in connect
    self.connection = self.get_new_connection(conn_params)
                      ^^^^^^^^^^^^^^^^^^^^^^^^^^^^^^^^^^^^
  File "/Users/mutafvladimir/Documents/IT/dZENcode/.venv/lib/python3.12/site-packages/django/utils/asyncio.py", line 26, in inner
    return func(*args, **kwargs)
           ^^^^^^^^^^^^^^^^^^^^^
  File "/Users/mutafvladimir/Documents/IT/dZENcode/.venv/lib/python3.12/site-packages/django/db/backends/mysql/base.py", line 256, in get_new_connection
    connection = Database.connect(**conn_params)
                 ^^^^^^^^^^^^^^^^^^^^^^^^^^^^^^^
  File "/Users/mutafvladimir/Documents/IT/dZENcode/.venv/lib/python3.12/site-packages/MySQLdb/__init__.py", line 121, in Connect
    return Connection(*args, **kwargs)
           ^^^^^^^^^^^^^^^^^^^^^^^^^^^
  File "/Users/mutafvladimir/Documents/IT/dZENcode/.venv/lib/python3.12/site-packages/MySQLdb/connections.py", line 200, in __init__
    super().__init__(*args, **kwargs2)
django.db.utils.OperationalError: (2002, "Can't connect to local MySQL server through socket '/tmp/mysql.sock' (2)")
[2025-04-29 15:05:57,502] ERROR django.request Internal Server Error: /api/v1/comments/comments/1/
Traceback (most recent call last):
  File "/Users/mutafvladimir/Documents/IT/dZENcode/.venv/lib/python3.12/site-packages/django/db/backends/base/base.py", line 279, in ensure_connection
    self.connect()
  File "/Users/mutafvladimir/Documents/IT/dZENcode/.venv/lib/python3.12/site-packages/django/utils/asyncio.py", line 26, in inner
    return func(*args, **kwargs)
           ^^^^^^^^^^^^^^^^^^^^^
  File "/Users/mutafvladimir/Documents/IT/dZENcode/.venv/lib/python3.12/site-packages/django/db/backends/base/base.py", line 256, in connect
    self.connection = self.get_new_connection(conn_params)
                      ^^^^^^^^^^^^^^^^^^^^^^^^^^^^^^^^^^^^
  File "/Users/mutafvladimir/Documents/IT/dZENcode/.venv/lib/python3.12/site-packages/django/utils/asyncio.py", line 26, in inner
    return func(*args, **kwargs)
           ^^^^^^^^^^^^^^^^^^^^^
  File "/Users/mutafvladimir/Documents/IT/dZENcode/.venv/lib/python3.12/site-packages/django/db/backends/mysql/base.py", line 256, in get_new_connection
    connection = Database.connect(**conn_params)
                 ^^^^^^^^^^^^^^^^^^^^^^^^^^^^^^^
  File "/Users/mutafvladimir/Documents/IT/dZENcode/.venv/lib/python3.12/site-packages/MySQLdb/__init__.py", line 121, in Connect
    return Connection(*args, **kwargs)
           ^^^^^^^^^^^^^^^^^^^^^^^^^^^
  File "/Users/mutafvladimir/Documents/IT/dZENcode/.venv/lib/python3.12/site-packages/MySQLdb/connections.py", line 200, in __init__
    super().__init__(*args, **kwargs2)
MySQLdb.OperationalError: (2002, "Can't connect to local MySQL server through socket '/tmp/mysql.sock' (2)")

The above exception was the direct cause of the following exception:

Traceback (most recent call last):
  File "/Users/mutafvladimir/Documents/IT/dZENcode/.venv/lib/python3.12/site-packages/asgiref/sync.py", line 518, in thread_handler
    raise exc_info[1]
  File "/Users/mutafvladimir/Documents/IT/dZENcode/.venv/lib/python3.12/site-packages/django/core/handlers/exception.py", line 42, in inner
    response = await get_response(request)
               ^^^^^^^^^^^^^^^^^^^^^^^^^^^
  File "/Users/mutafvladimir/Documents/IT/dZENcode/.venv/lib/python3.12/site-packages/asgiref/sync.py", line 518, in thread_handler
    raise exc_info[1]
  File "/Users/mutafvladimir/Documents/IT/dZENcode/.venv/lib/python3.12/site-packages/django/core/handlers/base.py", line 253, in _get_response_async
    response = await wrapped_callback(
               ^^^^^^^^^^^^^^^^^^^^^^^
  File "/Users/mutafvladimir/Documents/IT/dZENcode/.venv/lib/python3.12/site-packages/asgiref/sync.py", line 468, in __call__
    ret = await asyncio.shield(exec_coro)
          ^^^^^^^^^^^^^^^^^^^^^^^^^^^^^^^
  File "/Users/mutafvladimir/Documents/IT/dZENcode/.venv/lib/python3.12/site-packages/asgiref/current_thread_executor.py", line 40, in run
    result = self.fn(*self.args, **self.kwargs)
             ^^^^^^^^^^^^^^^^^^^^^^^^^^^^^^^^^^
  File "/Users/mutafvladimir/Documents/IT/dZENcode/.venv/lib/python3.12/site-packages/asgiref/sync.py", line 522, in thread_handler
    return func(*args, **kwargs)
           ^^^^^^^^^^^^^^^^^^^^^
  File "/Users/mutafvladimir/Documents/IT/dZENcode/.venv/lib/python3.12/site-packages/django/views/decorators/csrf.py", line 65, in _view_wrapper
    return view_func(request, *args, **kwargs)
           ^^^^^^^^^^^^^^^^^^^^^^^^^^^^^^^^^^^
  File "/Users/mutafvladimir/Documents/IT/dZENcode/.venv/lib/python3.12/site-packages/rest_framework/viewsets.py", line 125, in view
    return self.dispatch(request, *args, **kwargs)
           ^^^^^^^^^^^^^^^^^^^^^^^^^^^^^^^^^^^^^^^
  File "/Users/mutafvladimir/Documents/IT/dZENcode/.venv/lib/python3.12/site-packages/rest_framework/views.py", line 515, in dispatch
    response = self.handle_exception(exc)
               ^^^^^^^^^^^^^^^^^^^^^^^^^^
  File "/Users/mutafvladimir/Documents/IT/dZENcode/.venv/lib/python3.12/site-packages/rest_framework/views.py", line 475, in handle_exception
    self.raise_uncaught_exception(exc)
  File "/Users/mutafvladimir/Documents/IT/dZENcode/.venv/lib/python3.12/site-packages/rest_framework/views.py", line 486, in raise_uncaught_exception
    raise exc
  File "/Users/mutafvladimir/Documents/IT/dZENcode/.venv/lib/python3.12/site-packages/rest_framework/views.py", line 503, in dispatch
    self.initial(request, *args, **kwargs)
  File "/Users/mutafvladimir/Documents/IT/dZENcode/.venv/lib/python3.12/site-packages/rest_framework/views.py", line 420, in initial
    self.perform_authentication(request)
  File "/Users/mutafvladimir/Documents/IT/dZENcode/.venv/lib/python3.12/site-packages/rest_framework/views.py", line 330, in perform_authentication
    request.user
  File "/Users/mutafvladimir/Documents/IT/dZENcode/.venv/lib/python3.12/site-packages/rest_framework/request.py", line 232, in user
    self._authenticate()
  File "/Users/mutafvladimir/Documents/IT/dZENcode/.venv/lib/python3.12/site-packages/rest_framework/request.py", line 385, in _authenticate
    user_auth_tuple = authenticator.authenticate(self)
                      ^^^^^^^^^^^^^^^^^^^^^^^^^^^^^^^^
  File "/Users/mutafvladimir/Documents/IT/dZENcode/.venv/lib/python3.12/site-packages/rest_framework_simplejwt/authentication.py", line 51, in authenticate
    return self.get_user(validated_token), validated_token
           ^^^^^^^^^^^^^^^^^^^^^^^^^^^^^^
  File "/Users/mutafvladimir/Documents/IT/dZENcode/.venv/lib/python3.12/site-packages/rest_framework_simplejwt/authentication.py", line 130, in get_user
    user = self.user_model.objects.get(**{api_settings.USER_ID_FIELD: user_id})
           ^^^^^^^^^^^^^^^^^^^^^^^^^^^^^^^^^^^^^^^^^^^^^^^^^^^^^^^^^^^^^^^^^^^^
  File "/Users/mutafvladimir/Documents/IT/dZENcode/.venv/lib/python3.12/site-packages/django/db/models/manager.py", line 87, in manager_method
    return getattr(self.get_queryset(), name)(*args, **kwargs)
           ^^^^^^^^^^^^^^^^^^^^^^^^^^^^^^^^^^^^^^^^^^^^^^^^^^^
  File "/Users/mutafvladimir/Documents/IT/dZENcode/.venv/lib/python3.12/site-packages/django/db/models/query.py", line 629, in get
    num = len(clone)
          ^^^^^^^^^^
  File "/Users/mutafvladimir/Documents/IT/dZENcode/.venv/lib/python3.12/site-packages/django/db/models/query.py", line 366, in __len__
    self._fetch_all()
  File "/Users/mutafvladimir/Documents/IT/dZENcode/.venv/lib/python3.12/site-packages/django/db/models/query.py", line 1935, in _fetch_all
    self._result_cache = list(self._iterable_class(self))
                         ^^^^^^^^^^^^^^^^^^^^^^^^^^^^^^^^
  File "/Users/mutafvladimir/Documents/IT/dZENcode/.venv/lib/python3.12/site-packages/django/db/models/query.py", line 91, in __iter__
    results = compiler.execute_sql(
              ^^^^^^^^^^^^^^^^^^^^^
  File "/Users/mutafvladimir/Documents/IT/dZENcode/.venv/lib/python3.12/site-packages/django/db/models/sql/compiler.py", line 1620, in execute_sql
    cursor = self.connection.cursor()
             ^^^^^^^^^^^^^^^^^^^^^^^^
  File "/Users/mutafvladimir/Documents/IT/dZENcode/.venv/lib/python3.12/site-packages/django/utils/asyncio.py", line 26, in inner
    return func(*args, **kwargs)
           ^^^^^^^^^^^^^^^^^^^^^
  File "/Users/mutafvladimir/Documents/IT/dZENcode/.venv/lib/python3.12/site-packages/django/db/backends/base/base.py", line 320, in cursor
    return self._cursor()
           ^^^^^^^^^^^^^^
  File "/Users/mutafvladimir/Documents/IT/dZENcode/.venv/lib/python3.12/site-packages/django/db/backends/base/base.py", line 296, in _cursor
    self.ensure_connection()
  File "/Users/mutafvladimir/Documents/IT/dZENcode/.venv/lib/python3.12/site-packages/django/utils/asyncio.py", line 26, in inner
    return func(*args, **kwargs)
           ^^^^^^^^^^^^^^^^^^^^^
  File "/Users/mutafvladimir/Documents/IT/dZENcode/.venv/lib/python3.12/site-packages/django/db/backends/base/base.py", line 278, in ensure_connection
    with self.wrap_database_errors:
         ^^^^^^^^^^^^^^^^^^^^^^^^^
  File "/Users/mutafvladimir/Documents/IT/dZENcode/.venv/lib/python3.12/site-packages/django/db/utils.py", line 91, in __exit__
    raise dj_exc_value.with_traceback(traceback) from exc_value
  File "/Users/mutafvladimir/Documents/IT/dZENcode/.venv/lib/python3.12/site-packages/django/db/backends/base/base.py", line 279, in ensure_connection
    self.connect()
  File "/Users/mutafvladimir/Documents/IT/dZENcode/.venv/lib/python3.12/site-packages/django/utils/asyncio.py", line 26, in inner
    return func(*args, **kwargs)
           ^^^^^^^^^^^^^^^^^^^^^
  File "/Users/mutafvladimir/Documents/IT/dZENcode/.venv/lib/python3.12/site-packages/django/db/backends/base/base.py", line 256, in connect
    self.connection = self.get_new_connection(conn_params)
                      ^^^^^^^^^^^^^^^^^^^^^^^^^^^^^^^^^^^^
  File "/Users/mutafvladimir/Documents/IT/dZENcode/.venv/lib/python3.12/site-packages/django/utils/asyncio.py", line 26, in inner
    return func(*args, **kwargs)
           ^^^^^^^^^^^^^^^^^^^^^
  File "/Users/mutafvladimir/Documents/IT/dZENcode/.venv/lib/python3.12/site-packages/django/db/backends/mysql/base.py", line 256, in get_new_connection
    connection = Database.connect(**conn_params)
                 ^^^^^^^^^^^^^^^^^^^^^^^^^^^^^^^
  File "/Users/mutafvladimir/Documents/IT/dZENcode/.venv/lib/python3.12/site-packages/MySQLdb/__init__.py", line 121, in Connect
    return Connection(*args, **kwargs)
           ^^^^^^^^^^^^^^^^^^^^^^^^^^^
  File "/Users/mutafvladimir/Documents/IT/dZENcode/.venv/lib/python3.12/site-packages/MySQLdb/connections.py", line 200, in __init__
    super().__init__(*args, **kwargs2)
django.db.utils.OperationalError: (2002, "Can't connect to local MySQL server through socket '/tmp/mysql.sock' (2)")
[2025-04-29 15:06:02,571] ERROR django.request Internal Server Error: /api/v1/comments/comments/
Traceback (most recent call last):
  File "/Users/mutafvladimir/Documents/IT/dZENcode/.venv/lib/python3.12/site-packages/django/db/backends/base/base.py", line 279, in ensure_connection
    self.connect()
  File "/Users/mutafvladimir/Documents/IT/dZENcode/.venv/lib/python3.12/site-packages/django/utils/asyncio.py", line 26, in inner
    return func(*args, **kwargs)
           ^^^^^^^^^^^^^^^^^^^^^
  File "/Users/mutafvladimir/Documents/IT/dZENcode/.venv/lib/python3.12/site-packages/django/db/backends/base/base.py", line 256, in connect
    self.connection = self.get_new_connection(conn_params)
                      ^^^^^^^^^^^^^^^^^^^^^^^^^^^^^^^^^^^^
  File "/Users/mutafvladimir/Documents/IT/dZENcode/.venv/lib/python3.12/site-packages/django/utils/asyncio.py", line 26, in inner
    return func(*args, **kwargs)
           ^^^^^^^^^^^^^^^^^^^^^
  File "/Users/mutafvladimir/Documents/IT/dZENcode/.venv/lib/python3.12/site-packages/django/db/backends/mysql/base.py", line 256, in get_new_connection
    connection = Database.connect(**conn_params)
                 ^^^^^^^^^^^^^^^^^^^^^^^^^^^^^^^
  File "/Users/mutafvladimir/Documents/IT/dZENcode/.venv/lib/python3.12/site-packages/MySQLdb/__init__.py", line 121, in Connect
    return Connection(*args, **kwargs)
           ^^^^^^^^^^^^^^^^^^^^^^^^^^^
  File "/Users/mutafvladimir/Documents/IT/dZENcode/.venv/lib/python3.12/site-packages/MySQLdb/connections.py", line 200, in __init__
    super().__init__(*args, **kwargs2)
MySQLdb.OperationalError: (2002, "Can't connect to local MySQL server through socket '/tmp/mysql.sock' (2)")

The above exception was the direct cause of the following exception:

Traceback (most recent call last):
  File "/Users/mutafvladimir/Documents/IT/dZENcode/.venv/lib/python3.12/site-packages/asgiref/sync.py", line 518, in thread_handler
    raise exc_info[1]
  File "/Users/mutafvladimir/Documents/IT/dZENcode/.venv/lib/python3.12/site-packages/django/core/handlers/exception.py", line 42, in inner
    response = await get_response(request)
               ^^^^^^^^^^^^^^^^^^^^^^^^^^^
  File "/Users/mutafvladimir/Documents/IT/dZENcode/.venv/lib/python3.12/site-packages/asgiref/sync.py", line 518, in thread_handler
    raise exc_info[1]
  File "/Users/mutafvladimir/Documents/IT/dZENcode/.venv/lib/python3.12/site-packages/django/core/handlers/base.py", line 253, in _get_response_async
    response = await wrapped_callback(
               ^^^^^^^^^^^^^^^^^^^^^^^
  File "/Users/mutafvladimir/Documents/IT/dZENcode/.venv/lib/python3.12/site-packages/asgiref/sync.py", line 468, in __call__
    ret = await asyncio.shield(exec_coro)
          ^^^^^^^^^^^^^^^^^^^^^^^^^^^^^^^
  File "/Users/mutafvladimir/Documents/IT/dZENcode/.venv/lib/python3.12/site-packages/asgiref/current_thread_executor.py", line 40, in run
    result = self.fn(*self.args, **self.kwargs)
             ^^^^^^^^^^^^^^^^^^^^^^^^^^^^^^^^^^
  File "/Users/mutafvladimir/Documents/IT/dZENcode/.venv/lib/python3.12/site-packages/asgiref/sync.py", line 522, in thread_handler
    return func(*args, **kwargs)
           ^^^^^^^^^^^^^^^^^^^^^
  File "/Users/mutafvladimir/Documents/IT/dZENcode/.venv/lib/python3.12/site-packages/django/views/decorators/csrf.py", line 65, in _view_wrapper
    return view_func(request, *args, **kwargs)
           ^^^^^^^^^^^^^^^^^^^^^^^^^^^^^^^^^^^
  File "/Users/mutafvladimir/Documents/IT/dZENcode/.venv/lib/python3.12/site-packages/rest_framework/viewsets.py", line 125, in view
    return self.dispatch(request, *args, **kwargs)
           ^^^^^^^^^^^^^^^^^^^^^^^^^^^^^^^^^^^^^^^
  File "/Users/mutafvladimir/Documents/IT/dZENcode/.venv/lib/python3.12/site-packages/rest_framework/views.py", line 515, in dispatch
    response = self.handle_exception(exc)
               ^^^^^^^^^^^^^^^^^^^^^^^^^^
  File "/Users/mutafvladimir/Documents/IT/dZENcode/.venv/lib/python3.12/site-packages/rest_framework/views.py", line 475, in handle_exception
    self.raise_uncaught_exception(exc)
  File "/Users/mutafvladimir/Documents/IT/dZENcode/.venv/lib/python3.12/site-packages/rest_framework/views.py", line 486, in raise_uncaught_exception
    raise exc
  File "/Users/mutafvladimir/Documents/IT/dZENcode/.venv/lib/python3.12/site-packages/rest_framework/views.py", line 503, in dispatch
    self.initial(request, *args, **kwargs)
  File "/Users/mutafvladimir/Documents/IT/dZENcode/.venv/lib/python3.12/site-packages/rest_framework/views.py", line 420, in initial
    self.perform_authentication(request)
  File "/Users/mutafvladimir/Documents/IT/dZENcode/.venv/lib/python3.12/site-packages/rest_framework/views.py", line 330, in perform_authentication
    request.user
  File "/Users/mutafvladimir/Documents/IT/dZENcode/.venv/lib/python3.12/site-packages/rest_framework/request.py", line 232, in user
    self._authenticate()
  File "/Users/mutafvladimir/Documents/IT/dZENcode/.venv/lib/python3.12/site-packages/rest_framework/request.py", line 385, in _authenticate
    user_auth_tuple = authenticator.authenticate(self)
                      ^^^^^^^^^^^^^^^^^^^^^^^^^^^^^^^^
  File "/Users/mutafvladimir/Documents/IT/dZENcode/.venv/lib/python3.12/site-packages/rest_framework_simplejwt/authentication.py", line 51, in authenticate
    return self.get_user(validated_token), validated_token
           ^^^^^^^^^^^^^^^^^^^^^^^^^^^^^^
  File "/Users/mutafvladimir/Documents/IT/dZENcode/.venv/lib/python3.12/site-packages/rest_framework_simplejwt/authentication.py", line 130, in get_user
    user = self.user_model.objects.get(**{api_settings.USER_ID_FIELD: user_id})
           ^^^^^^^^^^^^^^^^^^^^^^^^^^^^^^^^^^^^^^^^^^^^^^^^^^^^^^^^^^^^^^^^^^^^
  File "/Users/mutafvladimir/Documents/IT/dZENcode/.venv/lib/python3.12/site-packages/django/db/models/manager.py", line 87, in manager_method
    return getattr(self.get_queryset(), name)(*args, **kwargs)
           ^^^^^^^^^^^^^^^^^^^^^^^^^^^^^^^^^^^^^^^^^^^^^^^^^^^
  File "/Users/mutafvladimir/Documents/IT/dZENcode/.venv/lib/python3.12/site-packages/django/db/models/query.py", line 629, in get
    num = len(clone)
          ^^^^^^^^^^
  File "/Users/mutafvladimir/Documents/IT/dZENcode/.venv/lib/python3.12/site-packages/django/db/models/query.py", line 366, in __len__
    self._fetch_all()
  File "/Users/mutafvladimir/Documents/IT/dZENcode/.venv/lib/python3.12/site-packages/django/db/models/query.py", line 1935, in _fetch_all
    self._result_cache = list(self._iterable_class(self))
                         ^^^^^^^^^^^^^^^^^^^^^^^^^^^^^^^^
  File "/Users/mutafvladimir/Documents/IT/dZENcode/.venv/lib/python3.12/site-packages/django/db/models/query.py", line 91, in __iter__
    results = compiler.execute_sql(
              ^^^^^^^^^^^^^^^^^^^^^
  File "/Users/mutafvladimir/Documents/IT/dZENcode/.venv/lib/python3.12/site-packages/django/db/models/sql/compiler.py", line 1620, in execute_sql
    cursor = self.connection.cursor()
             ^^^^^^^^^^^^^^^^^^^^^^^^
  File "/Users/mutafvladimir/Documents/IT/dZENcode/.venv/lib/python3.12/site-packages/django/utils/asyncio.py", line 26, in inner
    return func(*args, **kwargs)
           ^^^^^^^^^^^^^^^^^^^^^
  File "/Users/mutafvladimir/Documents/IT/dZENcode/.venv/lib/python3.12/site-packages/django/db/backends/base/base.py", line 320, in cursor
    return self._cursor()
           ^^^^^^^^^^^^^^
  File "/Users/mutafvladimir/Documents/IT/dZENcode/.venv/lib/python3.12/site-packages/django/db/backends/base/base.py", line 296, in _cursor
    self.ensure_connection()
  File "/Users/mutafvladimir/Documents/IT/dZENcode/.venv/lib/python3.12/site-packages/django/utils/asyncio.py", line 26, in inner
    return func(*args, **kwargs)
           ^^^^^^^^^^^^^^^^^^^^^
  File "/Users/mutafvladimir/Documents/IT/dZENcode/.venv/lib/python3.12/site-packages/django/db/backends/base/base.py", line 278, in ensure_connection
    with self.wrap_database_errors:
         ^^^^^^^^^^^^^^^^^^^^^^^^^
  File "/Users/mutafvladimir/Documents/IT/dZENcode/.venv/lib/python3.12/site-packages/django/db/utils.py", line 91, in __exit__
    raise dj_exc_value.with_traceback(traceback) from exc_value
  File "/Users/mutafvladimir/Documents/IT/dZENcode/.venv/lib/python3.12/site-packages/django/db/backends/base/base.py", line 279, in ensure_connection
    self.connect()
  File "/Users/mutafvladimir/Documents/IT/dZENcode/.venv/lib/python3.12/site-packages/django/utils/asyncio.py", line 26, in inner
    return func(*args, **kwargs)
           ^^^^^^^^^^^^^^^^^^^^^
  File "/Users/mutafvladimir/Documents/IT/dZENcode/.venv/lib/python3.12/site-packages/django/db/backends/base/base.py", line 256, in connect
    self.connection = self.get_new_connection(conn_params)
                      ^^^^^^^^^^^^^^^^^^^^^^^^^^^^^^^^^^^^
  File "/Users/mutafvladimir/Documents/IT/dZENcode/.venv/lib/python3.12/site-packages/django/utils/asyncio.py", line 26, in inner
    return func(*args, **kwargs)
           ^^^^^^^^^^^^^^^^^^^^^
  File "/Users/mutafvladimir/Documents/IT/dZENcode/.venv/lib/python3.12/site-packages/django/db/backends/mysql/base.py", line 256, in get_new_connection
    connection = Database.connect(**conn_params)
                 ^^^^^^^^^^^^^^^^^^^^^^^^^^^^^^^
  File "/Users/mutafvladimir/Documents/IT/dZENcode/.venv/lib/python3.12/site-packages/MySQLdb/__init__.py", line 121, in Connect
    return Connection(*args, **kwargs)
           ^^^^^^^^^^^^^^^^^^^^^^^^^^^
  File "/Users/mutafvladimir/Documents/IT/dZENcode/.venv/lib/python3.12/site-packages/MySQLdb/connections.py", line 200, in __init__
    super().__init__(*args, **kwargs2)
django.db.utils.OperationalError: (2002, "Can't connect to local MySQL server through socket '/tmp/mysql.sock' (2)")
[2025-04-29 15:07:36,787] DEBUG django.request Asynchronous handler adapted for middleware whitenoise.middleware.WhiteNoiseMiddleware.
[2025-04-29 15:09:02,996] DEBUG django.request Asynchronous handler adapted for middleware whitenoise.middleware.WhiteNoiseMiddleware.
[2025-04-29 15:11:10,891] DEBUG django.request Asynchronous handler adapted for middleware whitenoise.middleware.WhiteNoiseMiddleware.
[2025-04-29 15:15:16,279] DEBUG django.request Asynchronous handler adapted for middleware whitenoise.middleware.WhiteNoiseMiddleware.
[2025-04-29 15:29:54,595] DEBUG django.request Asynchronous handler adapted for middleware whitenoise.middleware.WhiteNoiseMiddleware.
[2025-04-29 15:30:11,391] WARNING django.request Bad Request: /api/v1/comments/comments/
[2025-04-29 15:31:15,541] DEBUG django.request Asynchronous handler adapted for middleware whitenoise.middleware.WhiteNoiseMiddleware.
[2025-04-29 15:34:34,292] DEBUG django.request Asynchronous handler adapted for middleware whitenoise.middleware.WhiteNoiseMiddleware.
[2025-04-29 15:42:21,398] DEBUG django.request Asynchronous handler adapted for middleware whitenoise.middleware.WhiteNoiseMiddleware.
[2025-04-29 15:42:33,549] WARNING django.request Bad Request: /api/v1/comments/comments/
[2025-04-29 15:43:41,275] DEBUG django.request Asynchronous handler adapted for middleware whitenoise.middleware.WhiteNoiseMiddleware.
[2025-04-29 15:45:03,522] DEBUG django.request Asynchronous handler adapted for middleware whitenoise.middleware.WhiteNoiseMiddleware.
[2025-04-29 15:45:05,166] WARNING django.request Bad Request: /api/v1/comments/comments/
[2025-04-29 15:48:16,985] DEBUG django.request Asynchronous handler adapted for middleware whitenoise.middleware.WhiteNoiseMiddleware.
[2025-04-29 15:48:21,428] WARNING django.request Bad Request: /api/v1/comments/comments/
[2025-04-29 15:49:34,191] DEBUG django.request Asynchronous handler adapted for middleware whitenoise.middleware.WhiteNoiseMiddleware.
[2025-04-29 15:49:38,557] WARNING django.request Bad Request: /
[2025-04-29 15:50:39,892] DEBUG django.request Asynchronous handler adapted for middleware whitenoise.middleware.WhiteNoiseMiddleware.
